Workbook

Sheet HUONG_DAN
B1: HƯỚNG DẪN SỬ DỤNG
B2: Header xanh dương = cột nhập tay. Header xanh lá = cột công thức tự động, KHÔNG nhập/ghi đè.
B3: Ô vàng chữ xanh dương ở DANH_MUC = cấu hình, sửa được (KPI, link form, điều kiện bắt buộc).
B4: Thêm nguồn mới: thêm 1 dòng ở MASTER_SOURCE TRƯỚC khi phát link/QR. Link tự sinh ở cột Link/QR.
B5: Đăng ký không có REF: chọn NHS-UNKNOWN. Không gán vào một Nữ hộ sinh cụ thể.
B6: Đơn hàng: mỗi đơn 1 dòng ở ORDERS. Cột SĐT đăng ký là bắt buộc; SĐT nhận hàng được phép khác.
B7: Dữ liệu gốc vẫn là Pancake CRM. File này kéo từ CRM, giữ cột ID Pancake CRM để đối chiếu ngược.
B8: File chứa họ tên + SĐT của mẹ: chỉ chia sẻ cho người cần, không để "ai có link cũng xem".
B9: Đã chuẩn bị sẵn công thức cho 5.000 dòng. Dán dữ liệu bằng Paste Values để không mất định dạng/validation.
B11: THAY ĐỔI SO VỚI BẢN TRƯỚC
B12: MASTER_SOURCE: chuẩn hóa Team về 2 giá trị ZM / CDB (trước có ZMOMS, ZM, CỘNG ĐỒNG BẦU, CDB).
B13: MASTER_SOURCE: Ngày tạo chuyển từ chữ sang kiểu ngày; thêm NHS-UNKNOWN; Link/QR tự sinh; thêm cột kiểm tra mã trùng và đếm đăng ký / hợp lệ / đơn theo nguồn.
... B26: 6. NHS-UNKNOWN để Team "Chưa xác định" – đổi sang ZM nếu team thống nhất tính về Z-Moms.

Sheet TONG_QUAN
A1: TỔNG QUAN DATA – Z-MOMS x APTAMIL
A2: Mọi số liệu tự tính từ DATA_MASTER / ORDERS. Không nhập tay ở sheet này.
A4: Chỉ số | B4: Giá trị | D4: Team | E4: Đăng ký | F4: Hợp lệ
A5: Tổng đăng ký | B5: =COUNTIF(DATA_MASTER!$D$2:$D$5000,"?*") | D5: ZM | E5: =COUNTIF(DATA_MASTER!$L$2:$L$5000,D5) | F5: =COUNTIFS(DATA_MASTER!$L$2:$L$5000,D5,DATA_MASTER!$T$2:$T$5000,"Có")
A6: Data hợp lệ (tính KPI) | B6: =COUNTIF(DATA_MASTER!$T$2:$T$5000,"Có") | D6: CDB | E6: =COUNTIF(DATA_MASTER!$L$2:$L$5000,D6) | F6: =COUNTIFS(DATA_MASTER!$L$2:$L$5000,D6,DATA_MASTER!$T$2:$T$5000,"Có")
A7: KPI Aptamil | B7: =DANH_MUC!$L$2 | D7: Chưa xác định | E7: =COUNTIF(DATA_MASTER!$L$2:$L$5000,D7) | F7: =COUNTIFS(DATA_MASTER!$L$2:$L$5000,D7,DATA_MASTER!$T$2:$T$5000,"Có")
A8: % hoàn thành KPI | B8: =IF(B7=0,0,B6/B7)
A9: Còn thiếu | B9: =MAX(0,B7-B6)
A10: Không hợp lệ | B10: =COUNTIF(DATA_MASTER!$T$2:$T$5000,"Không") | D10: Loại nguồn | E10: Đăng ký | F10: Hợp lệ
A11: trong đó trùng SĐT | B11: =COUNTIF(DATA_MASTER!$R$2:$R$5000,"Trùng") | D11: NHS | E11: =COUNTIF(DATA_MASTER!$K$2:$K$5000,D11) | F11: =COUNTIFS(DATA_MASTER!$K$2:$K$5000,D11,DATA_MASTER!$T$2:$T$5000,"Có")
A12: Đăng ký chưa xác định nguồn | B12: =COUNTIF(DATA_MASTER!$L$2:$L$5000,"Chưa xác định") | D12: Event | E12: =COUNTIF(DATA_MASTER!$K$2:$K$5000,D12) | F12: =COUNTIFS(DATA_MASTER!$K$2:$K$5000,D12,DATA_MASTER!$T$2:$T$5000,"Có")
A13: % chưa xác định nguồn | B13: =IF(B5=0,0,B12/B5) | D13: Team | E13: =COUNTIF(DATA_MASTER!$K$2:$K$5000,D13) | F13: =COUNTIFS(DATA_MASTER!$K$2:$K$5000,D13,DATA_MASTER!$T$2:$T$5000,"Có")
A14: Số mẹ đã mua (đơn đã CK) | B14: =COUNTIFS(DATA_MASTER!$W$2:$W$5000,">0") | D14: Khác | E14: =COUNTIF(DATA_MASTER!$K$2:$K$5000,D14) | F14: =COUNTIFS(DATA_MASTER!$K$2:$K$5000,D14,DATA_MASTER!$T$2:$T$5000,"Có")
A15: Tỷ lệ mua / data hợp lệ | B15: =IF(B6=0,0,B14/B6) | D15: Seeding | E15: =COUNTIF(DATA_MASTER!$K$2:$K$5000,D15) | F15: =COUNTIFS(DATA_MASTER!$K$2:$K$5000,D15,DATA_MASTER!$T$2:$T$5000,"Có")
A16: Doanh thu đã CK (VNĐ) | B16: =SUMIFS(ORDERS!$J$2:$J$4995,ORDERS!$L$2:$L$4995,"Đã chuyển khoản") | D16: Sales | E16: =COUNTIF(DATA_MASTER!$K$2:$K$5000,D16) | F16: =COUNTIFS(DATA_MASTER!$K$2:$K$5000,D16,DATA_MASTER!$T$2:$T$5000,"Có")
A18: Tuần bắt đầu (thứ 2) | B18: Đăng ký mới | C18: Hợp lệ | D18: KPI tuần | E18: Đạt?
A19: 46293 | B19: =COUNTIF(DATA_MASTER!$H$2:$H$5000,A19) | C19: =COUNTIFS(DATA_MASTER!$H$2:$H$5000,A19,DATA_MASTER!$T$2:$T$5000,"Có") | D19: =DANH_MUC!$L$3 | E19: =IF(A19>TODAY(),"",IF(C19>=D19,"Đạt","Chưa đạt"))
A20: =A19+7 | B20: =COUNTIF(DATA_MASTER!$H$2:$H$5000,A20) | C20: =COUNTIFS(DATA_MASTER!$H$2:$H$5000,A20,DATA_MASTER!$T$2:$T$5000,"Có") | D20: =DANH_MUC!$L$3 | E20: =IF(A20>TODAY(),"",IF(C20>=D20,"Đạt","Chưa đạt"))
A21: =A20+7 | B21: =COUNTIF(DATA_MASTER!$H$2:$H$5000,A21) | C21: =COUNTIFS(DATA_MASTER!$H$2:$H$5000,A21,DATA_MASTER!$T$2:$T$5000,"Có") | D21: =DANH_MUC!$L$3 | E21: =IF(A21>TODAY(),"",IF(C21>=D21,"Đạt","Chưa đạt"))
A22: =A21+7 | B22: =COUNTIF(DATA_MASTER!$H$2:$H$5000,A22) | C22: =COUNTIFS(DATA_MASTER!$H$2:$H$5000,A22,DATA_MASTER!$T$2:$T$5000,"Có") | D22: =DANH_MUC!$L$3 | E22: =IF(A22>TODAY(),"",IF(C22>=D22,"Đạt","Chưa đạt"))
A23: =A22+7 | B23: =COUNTIF(DATA_MASTER!$H$2:$H$5000,A23) | C23: =COUNTIFS(DATA_MASTER!$H$2:$H$5000,A23,DATA_MASTER!$T$2:$T$5000,"Có") | D23: =DANH_MUC!$L$3 | E23: =IF(A23>TODAY(),"",IF(C23>=D23,"Đạt","Chưa đạt"))
A24: =A23+7 | B24: =COUNTIF(DATA_MASTER!$H$2:$H$5000,A24) | C24: =COUNTIFS(DATA_MASTER!$H$2:$H$5000,A24,DATA_MASTER!$T$2:$T$5000,"Có") | D24: =DANH_MUC!$L$3 | E24: =IF(A24>TODAY(),"",IF(C24>=D24,"Đạt","Chưa đạt"))
A25: =A24+7 | B25: =COUNTIF(DATA_MASTER!$H$2:$H$5000,A25) | C25: =COUNTIFS(DATA_MASTER!$H$2:$H$5000,A25,DATA_MASTER!$T$2:$T$5000,"Có") | D25: =DANH_MUC!$L$3 | E25: =IF(A25>TODAY(),"",IF(C25>=D25,"Đạt","Chưa đạt"))
A26: =A25+7 | B26: =COUNTIF(DATA_MASTER!$H$2:$H$5000,A26) | C26: =COUNTIFS(DATA_MASTER!$H$2:$H$5000,A26,DATA_MASTER!$T$2:$T$5000,"Có") | D26: =DANH_MUC!$L$3 | E26: =IF(A26>TODAY(),"",IF(C26>=D26,"Đạt","Chưa đạt"))
A27: =A26+7 | B27: =COUNTIF(DATA_MASTER!$H$2:$H$5000,A27) | C27: =COUNTIFS(DATA_MASTER!$H$2:$H$5000,A27,DATA_MASTER!$T$2:$T$5000,"Có") | D27: =DANH_MUC!$L$3 | E27: =IF(A27>TODAY(),"",IF(C27>=D27,"Đạt","Chưa đạt"))
A28: =A27+7 | B28: =COUNTIF(DATA_MASTER!$H$2:$H$5000,A28) | C28: =COUNTIFS(DATA_MASTER!$H$2:$H$5000,A28,DATA_MASTER!$T$2:$T$5000,"Có") | D28: =DANH_MUC!$L$3 | E28: =IF(A28>TODAY(),"",IF(C28>=D28,"Đạt","Chưa đạt"))
A29: =A28+7 | B29: =COUNTIF(DATA_MASTER!$H$2:$H$5000,A29) | C29: =COUNTIFS(DATA_MASTER!$H$2:$H$5000,A29,DATA_MASTER!$T$2:$T$5000,"Có") | D29: =DANH_MUC!$L$3 | E29: =IF(A29>TODAY(),"",IF(C29>=D29,"Đạt","Chưa đạt"))
A30: =A29+7 | B30: =COUNTIF(DATA_MASTER!$H$2:$H$5000,A30) | C30: =COUNTIFS(DATA_MASTER!$H$2:$H$5000,A30,DATA_MASTER!$T$2:$T$5000,"Có") | D30: =DANH_MUC!$L$3 | E30: =IF(A30>TODAY(),"",IF(C30>=D30,"Đạt","Chưa đạt"))
A31: =A30+7 | B31: =COUNTIF(DATA_MASTER!$H$2:$H$5000,A31) | C31: =COUNTIFS(DATA_MASTER!$H$2:$H$5000,A31,DATA_MASTER!$T$2:$T$5000,"Có") | D31: =DANH_MUC!$L$3 | E31: =IF(A31>TODAY(),"",IF(C31>=D31,"Đạt","Chưa đạt"))
... A44: =A43+7 | B44: =COUNTIF(DATA_MASTER!$H$2:$H$5000,A44) | C44: =COUNTIFS(DATA_MASTER!$H$2:$H$5000,A44,DATA_MASTER!$T$2:$T$5000,"Có") | D44: =DANH_MUC!$L$3 | E44: =IF(A44>TODAY(),"",IF(C44>=D44,"Đạt","Chưa đạt"))

Sheet DATA_MASTER
A1: ID Pancake CRM | B1: Thời gian đăng ký | C1: Họ và tên | D1: Số điện thoại đăng ký | E1: Ngày dự sinh / ngày sinh của bé | F1: Tình trạng mẹ | G1: Tỉnh/Thành phố | H1: Tuần đăng ký (thứ 2) | I1: Mã REF | J1: Nguồn | K1: Loại nguồn | L1: Activation Team | M1: Đồng ý đăng ký hội viên | N1: Đã đọc chính sách Aptamil | O1: Đồng ý nhận thông báo | P1: Đồng ý chia sẻ để đăng ký Aptaclub | Q1: Đủ điều kiện gửi CRM Danone | R1: Trùng SĐT? | S1: SĐT đúng định dạng? | T1: Hợp lệ (tính KPI) | U1: Lý do không hợp lệ | V1: Đã mua? | W1: Số đơn đã CK | X1: Tổng tiền đã CK (VNĐ) | Y1: Ghi chú
A2: e0aab3d1-323e-4c63-ac93-fa4bc0dcd6c2 | B2: 46286.756 | C2: Lương Thị Hương Liên | D2: 0399222285 | E2: 46327 | F2: Đang mang thai | G2: Hồ Chí Minh | H2: =IF(ISNUMBER($B2),INT($B2)-WEEKDAY($B2,2)+1,"") | I2: Z-GREEN | J2: {=IF($D2="","",IF($I2="","(trống REF)",IFERROR(INDEX(MASTER_SOURCE!$B$2:$B$495,MATCH($I2,MASTER_SOURCE!$A$2:$A$495,0)),"(REF không có trong MASTER_SOURCE)")))} | K2: {=IF($D2="","",IFERROR(INDEX(MASTER_SOURCE!$C$2:$C$495,MATCH($I2,MASTER_SOURCE!$A$2:$A$495,0)),""))} | L2: {=IF($D2="","",IFERROR(INDEX(MASTER_SOURCE!$D$2:$D$495,MATCH($I2,MASTER_SOURCE!$A$2:$A$495,0)),""))} | M2: Có | N2: Có | O2: Có | P2: Có | Q2: =IF($D2="","",IF(AND(OR(DANH_MUC!$L$5<>"Có",M2="Có"),OR(DANH_MUC!$L$6<>"Có",N2="Có"),OR(DANH_MUC!$L$7<>"Có",O2="Có"),OR(DANH_MUC!$L$8<>"Có",P2="Có")),"Có","Không")) | R2: =IF($D2="","",IF(COUNTIF($D$2:$D2,$D2)>1,"Trùng","")) | S2: =IF($D2="","",IF(AND(LEN($D2)=10,LEFT($D2,1)="0",ISNUMBER(--$D2)),"Có","Không")) | T2: =IF($D2="","",IF(AND($C2<>"",$Q2="Có",$R2="",$S2="Có",AND($L2<>"",OR($L2<>"Chưa xác định",DANH_MUC!$L$9="Có"))),"Có","Không")) | U2: =IF(OR($D2="",$T2="Có"),"",IF($C2="","Thiếu họ tên; ","")&IF($S2<>"Có","SĐT sai định dạng; ","")&IF($R2="Trùng","Trùng SĐT; ","")&IF($Q2<>"Có","Thiếu đồng ý bắt buộc; ","")&IF($L2="","Thiếu/sai Mã REF; ",IF(AND($L2="Chưa xác định",DANH_MUC!$L$9<>"Có"),"Nguồn chưa xác định; ",""))) | V2: =IF(OR($D2="",$R2="Trùng"),"",IF(COUNTIF(ORDERS!$C$2:$C$4995,$D2)>0,"Có","Không")) | W2: =IF(OR($D2="",$R2="Trùng"),"",COUNTIFS(ORDERS!$C$2:$C$4995,$D2,ORDERS!$L$2:$L$4995,"Đã chuyển khoản")) | X2: =IF(OR($D2="",$R2="Trùng"),"",SUMIFS(ORDERS!$J$2:$J$4995,ORDERS!$C$2:$C$4995,$D2,ORDERS!$L$2:$L$4995,"Đã chuyển khoản"))
A3: eca8b050-6e7d-4df9-90bd-1c140161b9b2 | B3: 46286.899 | C3: ĐỖ THỊ NHÃ LINH | D3: 0971259214 | E3: 46237 | F3: Đã sinh | G3: Hồ Chí Minh | H3: =IF(ISNUMBER($B3),INT($B3)-WEEKDAY($B3,2)+1,"") | I3: Z-CIH | J3: {=IF($D3="","",IF($I3="","(trống REF)",IFERROR(INDEX(MASTER_SOURCE!$B$2:$B$495,MATCH($I3,MASTER_SOURCE!$A$2:$A$495,0)),"(REF không có trong MASTER_SOURCE)")))} | K3: {=IF($D3="","",IFERROR(INDEX(MASTER_SOURCE!$C$2:$C$495,MATCH($I3,MASTER_SOURCE!$A$2:$A$495,0)),""))} | L3: {=IF($D3="","",IFERROR(INDEX(MASTER_SOURCE!$D$2:$D$495,MATCH($I3,MASTER_SOURCE!$A$2:$A$495,0)),""))} | M3: Có | N3: Có | O3: Có | P3: Có | Q3: =IF($D3="","",IF(AND(OR(DANH_MUC!$L$5<>"Có",M3="Có"),OR(DANH_MUC!$L$6<>"Có",N3="Có"),OR(DANH_MUC!$L$7<>"Có",O3="Có"),OR(DANH_MUC!$L$8<>"Có",P3="Có")),"Có","Không")) | R3: =IF($D3="","",IF(COUNTIF($D$2:$D3,$D3)>1,"Trùng","")) | S3: =IF($D3="","",IF(AND(LEN($D3)=10,LEFT($D3,1)="0",ISNUMBER(--$D3)),"Có","Không")) | T3: =IF($D3="","",IF(AND($C3<>"",$Q3="Có",$R3="",$S3="Có",AND($L3<>"",OR($L3<>"Chưa xác định",DANH_MUC!$L$9="Có"))),"Có","Không")) | U3: =IF(OR($D3="",$T3="Có"),"",IF($C3="","Thiếu họ tên; ","")&IF($S3<>"Có","SĐT sai định dạng; ","")&IF($R3="Trùng","Trùng SĐT; ","")&IF($Q3<>"Có","Thiếu đồng ý bắt buộc; ","")&IF($L3="","Thiếu/sai Mã REF; ",IF(AND($L3="Chưa xác định",DANH_MUC!$L$9<>"Có"),"Nguồn chưa xác định; ",""))) | V3: =IF(OR($D3="",$R3="Trùng"),"",IF(COUNTIF(ORDERS!$C$2:$C$4995,$D3)>0,"Có","Không")) | W3: =IF(OR($D3="",$R3="Trùng"),"",COUNTIFS(ORDERS!$C$2:$C$4995,$D3,ORDERS!$L$2:$L$4995,"Đã chuyển khoản")) | X3: =IF(OR($D3="",$R3="Trùng"),"",SUMIFS(ORDERS!$J$2:$J$4995,ORDERS!$C$2:$C$4995,$D3,ORDERS!$L$2:$L$4995,"Đã chuyển khoản"))
A4: caf11a33-ef88-46cb-91bf-c9a2ff486a87 | B4: 46286.916 | C4: Lương Diệu Hiền | D4: 0924734621 | E4: 46174 | F4: Đã sinh | G4: Hồ Chí Minh | H4: =IF(ISNUMBER($B4),INT($B4)-WEEKDAY($B4,2)+1,"") | I4: Z-00 | J4: {=IF($D4="","",IF($I4="","(trống REF)",IFERROR(INDEX(MASTER_SOURCE!$B$2:$B$495,MATCH($I4,MASTER_SOURCE!$A$2:$A$495,0)),"(REF không có trong MASTER_SOURCE)")))} | K4: {=IF($D4="","",IFERROR(INDEX(MASTER_SOURCE!$C$2:$C$495,MATCH($I4,MASTER_SOURCE!$A$2:$A$495,0)),""))} | L4: {=IF($D4="","",IFERROR(INDEX(MASTER_SOURCE!$D$2:$D$495,MATCH($I4,MASTER_SOURCE!$A$2:$A$495,0)),""))} | M4: Có | N4: Có | O4: Có | P4: Có | Q4: =IF($D4="","",IF(AND(OR(DANH_MUC!$L$5<>"Có",M4="Có"),OR(DANH_MUC!$L$6<>"Có",N4="Có"),OR(DANH_MUC!$L$7<>"Có",O4="Có"),OR(DANH_MUC!$L$8<>"Có",P4="Có")),"Có","Không")) | R4: =IF($D4="","",IF(COUNTIF($D$2:$D4,$D4)>1,"Trùng","")) | S4: =IF($D4="","",IF(AND(LEN($D4)=10,LEFT($D4,1)="0",ISNUMBER(--$D4)),"Có","Không")) | T4: =IF($D4="","",IF(AND($C4<>"",$Q4="Có",$R4="",$S4="Có",AND($L4<>"",OR($L4<>"Chưa xác định",DANH_MUC!$L$9="Có"))),"Có","Không")) | U4: =IF(OR($D4="",$T4="Có"),"",IF($C4="","Thiếu họ tên; ","")&IF($S4<>"Có","SĐT sai định dạng; ","")&IF($R4="Trùng","Trùng SĐT; ","")&IF($Q4<>"Có","Thiếu đồng ý bắt buộc; ","")&IF($L4="","Thiếu/sai Mã REF; ",IF(AND($L4="Chưa xác định",DANH_MUC!$L$9<>"Có"),"Nguồn chưa xác định; ",""))) | V4: =IF(OR($D4="",$R4="Trùng"),"",IF(COUNTIF(ORDERS!$C$2:$C$4995,$D4)>0,"Có","Không")) | W4: =IF(OR($D4="",$R4="Trùng"),"",COUNTIFS(ORDERS!$C$2:$C$4995,$D4,ORDERS!$L$2:$L$4995,"Đã chuyển khoản")) | X4: =IF(OR($D4="",$R4="Trùng"),"",SUMIFS(ORDERS!$J$2:$J$4995,ORDERS!$C$2:$C$4995,$D4,ORDERS!$L$2:$L$4995,"Đã chuyển khoản"))
A5: 904a3428-7455-4fd8-a08f-ab3bcf722b40 | B5: 46287.503 | C5: Lê Thị Hoa | D5: 0979103592 | E5: 46028 | F5: Đã sinh | G5: Hồ Chí Minh | H5: =IF(ISNUMBER($B5),INT($B5)-WEEKDAY($B5,2)+1,"") | I5: Z-00 | J5: {=IF($D5="","",IF($I5="","(trống REF)",IFERROR(INDEX(MASTER_SOURCE!$B$2:$B$495,MATCH($I5,MASTER_SOURCE!$A$2:$A$495,0)),"(REF không có trong MASTER_SOURCE)")))} | K5: {=IF($D5="","",IFERROR(INDEX(MASTER_SOURCE!$C$2:$C$495,MATCH($I5,MASTER_SOURCE!$A$2:$A$495,0)),""))} | L5: {=IF($D5="","",IFERROR(INDEX(MASTER_SOURCE!$D$2:$D$495,MATCH($I5,MASTER_SOURCE!$A$2:$A$495,0)),""))} | M5: Có | N5: Có | O5: Có | P5: Có | Q5: =IF($D5="","",IF(AND(OR(DANH_MUC!$L$5<>"Có",M5="Có"),OR(DANH_MUC!$L$6<>"Có",N5="Có"),OR(DANH_MUC!$L$7<>"Có",O5="Có"),OR(DANH_MUC!$L$8<>"Có",P5="Có")),"Có","Không")) | R5: =IF($D5="","",IF(COUNTIF($D$2:$D5,$D5)>1,"Trùng","")) | S5: =IF($D5="","",IF(AND(LEN($D5)=10,LEFT($D5,1)="0",ISNUMBER(--$D5)),"Có","Không")) | T5: =IF($D5="","",IF(AND($C5<>"",$Q5="Có",$R5="",$S5="Có",AND($L5<>"",OR($L5<>"Chưa xác định",DANH_MUC!$L$9="Có"))),"Có","Không")) | U5: =IF(OR($D5="",$T5="Có"),"",IF($C5="","Thiếu họ tên; ","")&IF($S5<>"Có","SĐT sai định dạng; ","")&IF($R5="Trùng","Trùng SĐT; ","")&IF($Q5<>"Có","Thiếu đồng ý bắt buộc; ","")&IF($L5="","Thiếu/sai Mã REF; ",IF(AND($L5="Chưa xác định",DANH_MUC!$L$9<>"Có"),"Nguồn chưa xác định; ",""))) | V5: =IF(OR($D5="",$R5="Trùng"),"",IF(COUNTIF(ORDERS!$C$2:$C$4995,$D5)>0,"Có","Không")) | W5: =IF(OR($D5="",$R5="Trùng"),"",COUNTIFS(ORDERS!$C$2:$C$4995,$D5,ORDERS!$L$2:$L$4995,"Đã chuyển khoản")) | X5: =IF(OR($D5="",$R5="Trùng"),"",SUMIFS(ORDERS!$J$2:$J$4995,ORDERS!$C$2:$C$4995,$D5,ORDERS!$L$2:$L$4995,"Đã chuyển khoản"))
A6: 08ce8ee5-79db-413c-9226-9d5a90f5091c | B6: 46287.504 | C6: Bùi Thị Lan Anh | D6: 0921247456 | E6: 46268 | F6: Đã sinh | G6: Nghệ An | H6: =IF(ISNUMBER($B6),INT($B6)-WEEKDAY($B6,2)+1,"") | I6: Z-00 | J6: {=IF($D6="","",IF($I6="","(trống REF)",IFERROR(INDEX(MASTER_SOURCE!$B$2:$B$495,MATCH($I6,MASTER_SOURCE!$A$2:$A$495,0)),"(REF không có trong MASTER_SOURCE)")))} | K6: {=IF($D6="","",IFERROR(INDEX(MASTER_SOURCE!$C$2:$C$495,MATCH($I6,MASTER_SOURCE!$A$2:$A$495,0)),""))} | L6: {=IF($D6="","",IFERROR(INDEX(MASTER_SOURCE!$D$2:$D$495,MATCH($I6,MASTER_SOURCE!$A$2:$A$495,0)),""))} | M6: Có | N6: Có | O6: Có | P6: Có | Q6: =IF($D6="","",IF(AND(OR(DANH_MUC!$L$5<>"Có",M6="Có"),OR(DANH_MUC!$L$6<>"Có",N6="Có"),OR(DANH_MUC!$L$7<>"Có",O6="Có"),OR(DANH_MUC!$L$8<>"Có",P6="Có")),"Có","Không")) | R6: =IF($D6="","",IF(COUNTIF($D$2:$D6,$D6)>1,"Trùng","")) | S6: =IF($D6="","",IF(AND(LEN($D6)=10,LEFT($D6,1)="0",ISNUMBER(--$D6)),"Có","Không")) | T6: =IF($D6="","",IF(AND($C6<>"",$Q6="Có",$R6="",$S6="Có",AND($L6<>"",OR($L6<>"Chưa xác định",DANH_MUC!$L$9="Có"))),"Có","Không")) | U6: =IF(OR($D6="",$T6="Có"),"",IF($C6="","Thiếu họ tên; ","")&IF($S6<>"Có","SĐT sai định dạng; ","")&IF($R6="Trùng","Trùng SĐT; ","")&IF($Q6<>"Có","Thiếu đồng ý bắt buộc; ","")&IF($L6="","Thiếu/sai Mã REF; ",IF(AND($L6="Chưa xác định",DANH_MUC!$L$9<>"Có"),"Nguồn chưa xác định; ",""))) | V6: =IF(OR($D6="",$R6="Trùng"),"",IF(COUNTIF(ORDERS!$C$2:$C$4995,$D6)>0,"Có","Không")) | W6: =IF(OR($D6="",$R6="Trùng"),"",COUNTIFS(ORDERS!$C$2:$C$4995,$D6,ORDERS!$L$2:$L$4995,"Đã chuyển khoản")) | X6: =IF(OR($D6="",$R6="Trùng"),"",SUMIFS(ORDERS!$J$2:$J$4995,ORDERS!$C$2:$C$4995,$D6,ORDERS!$L$2:$L$4995,"Đã chuyển khoản"))
A7: 559520a4-df2e-4c80-91ca-8d624e0aa2f5 | B7: 46287.506 | C7: Nguyễn Thị Phương Dung | D7: 0342794617 | E7: 46083 | F7: Đã sinh | G7: Đồng Nai | H7: =IF(ISNUMBER($B7),INT($B7)-WEEKDAY($B7,2)+1,"") | I7: Z-00 | J7: {=IF($D7="","",IF($I7="","(trống REF)",IFERROR(INDEX(MASTER_SOURCE!$B$2:$B$495,MATCH($I7,MASTER_SOURCE!$A$2:$A$495,0)),"(REF không có trong MASTER_SOURCE)")))} | K7: {=IF($D7="","",IFERROR(INDEX(MASTER_SOURCE!$C$2:$C$495,MATCH($I7,MASTER_SOURCE!$A$2:$A$495,0)),""))} | L7: {=IF($D7="","",IFERROR(INDEX(MASTER_SOURCE!$D$2:$D$495,MATCH($I7,MASTER_SOURCE!$A$2:$A$495,0)),""))} | M7: Có | N7: Có | O7: Có | P7: Có | Q7: =IF($D7="","",IF(AND(OR(DANH_MUC!$L$5<>"Có",M7="Có"),OR(DANH_MUC!$L$6<>"Có",N7="Có"),OR(DANH_MUC!$L$7<>"Có",O7="Có"),OR(DANH_MUC!$L$8<>"Có",P7="Có")),"Có","Không")) | R7: =IF($D7="","",IF(COUNTIF($D$2:$D7,$D7)>1,"Trùng","")) | S7: =IF($D7="","",IF(AND(LEN($D7)=10,LEFT($D7,1)="0",ISNUMBER(--$D7)),"Có","Không")) | T7: =IF($D7="","",IF(AND($C7<>"",$Q7="Có",$R7="",$S7="Có",AND($L7<>"",OR($L7<>"Chưa xác định",DANH_MUC!$L$9="Có"))),"Có","Không")) | U7: =IF(OR($D7="",$T7="Có"),"",IF($C7="","Thiếu họ tên; ","")&IF($S7<>"Có","SĐT sai định dạng; ","")&IF($R7="Trùng","Trùng SĐT; ","")&IF($Q7<>"Có","Thiếu đồng ý bắt buộc; ","")&IF($L7="","Thiếu/sai Mã REF; ",IF(AND($L7="Chưa xác định",DANH_MUC!$L$9<>"Có"),"Nguồn chưa xác định; ",""))) | V7: =IF(OR($D7="",$R7="Trùng"),"",IF(COUNTIF(ORDERS!$C$2:$C$4995,$D7)>0,"Có","Không")) | W7: =IF(OR($D7="",$R7="Trùng"),"",COUNTIFS(ORDERS!$C$2:$C$4995,$D7,ORDERS!$L$2:$L$4995,"Đã chuyển khoản")) | X7: =IF(OR($D7="",$R7="Trùng"),"",SUMIFS(ORDERS!$J$2:$J$4995,ORDERS!$C$2:$C$4995,$D7,ORDERS!$L$2:$L$4995,"Đã chuyển khoản"))
A8: 335e0615-3f89-4566-ac57-a204ad892801 | B8: 46287.51 | C8: Hà Thị Thu Phương | D8: 0393345239 | E8: 46153 | F8: Đã sinh | G8: Hồ Chí Minh | H8: =IF(ISNUMBER($B8),INT($B8)-WEEKDAY($B8,2)+1,"") | I8: Z-00 | J8: {=IF($D8="","",IF($I8="","(trống REF)",IFERROR(INDEX(MASTER_SOURCE!$B$2:$B$495,MATCH($I8,MASTER_SOURCE!$A$2:$A$495,0)),"(REF không có trong MASTER_SOURCE)")))} | K8: {=IF($D8="","",IFERROR(INDEX(MASTER_SOURCE!$C$2:$C$495,MATCH($I8,MASTER_SOURCE!$A$2:$A$495,0)),""))} | L8: {=IF($D8="","",IFERROR(INDEX(MASTER_SOURCE!$D$2:$D$495,MATCH($I8,MASTER_SOURCE!$A$2:$A$495,0)),""))} | M8: Có | N8: Có | O8: Có | P8: Có | Q8: =IF($D8="","",IF(AND(OR(DANH_MUC!$L$5<>"Có",M8="Có"),OR(DANH_MUC!$L$6<>"Có",N8="Có"),OR(DANH_MUC!$L$7<>"Có",O8="Có"),OR(DANH_MUC!$L$8<>"Có",P8="Có")),"Có","Không")) | R8: =IF($D8="","",IF(COUNTIF($D$2:$D8,$D8)>1,"Trùng","")) | S8: =IF($D8="","",IF(AND(LEN($D8)=10,LEFT($D8,1)="0",ISNUMBER(--$D8)),"Có","Không")) | T8: =IF($D8="","",IF(AND($C8<>"",$Q8="Có",$R8="",$S8="Có",AND($L8<>"",OR($L8<>"Chưa xác định",DANH_MUC!$L$9="Có"))),"Có","Không")) | U8: =IF(OR($D8="",$T8="Có"),"",IF($C8="","Thiếu họ tên; ","")&IF($S8<>"Có","SĐT sai định dạng; ","")&IF($R8="Trùng","Trùng SĐT; ","")&IF($Q8<>"Có","Thiếu đồng ý bắt buộc; ","")&IF($L8="","Thiếu/sai Mã REF; ",IF(AND($L8="Chưa xác định",DANH_MUC!$L$9<>"Có"),"Nguồn chưa xác định; ",""))) | V8: =IF(OR($D8="",$R8="Trùng"),"",IF(COUNTIF(ORDERS!$C$2:$C$4995,$D8)>0,"Có","Không")) | W8: =IF(OR($D8="",$R8="Trùng"),"",COUNTIFS(ORDERS!$C$2:$C$4995,$D8,ORDERS!$L$2:$L$4995,"Đã chuyển khoản")) | X8: =IF(OR($D8="",$R8="Trùng"),"",SUMIFS(ORDERS!$J$2:$J$4995,ORDERS!$C$2:$C$4995,$D8,ORDERS!$L$2:$L$4995,"Đã chuyển khoản"))
A9: 840f0fea-7095-4fc2-9875-d459e1a162b3 | B9: 46287.569 | C9: Minh Anh | D9: 0984748123 | E9: 46199 | F9: Đã sinh | G9: Đồng Nai | H9: =IF(ISNUMBER($B9),INT($B9)-WEEKDAY($B9,2)+1,"") | I9: Z-00 | J9: {=IF($D9="","",IF($I9="","(trống REF)",IFERROR(INDEX(MASTER_SOURCE!$B$2:$B$495,MATCH($I9,MASTER_SOURCE!$A$2:$A$495,0)),"(REF không có trong MASTER_SOURCE)")))} | K9: {=IF($D9="","",IFERROR(INDEX(MASTER_SOURCE!$C$2:$C$495,MATCH($I9,MASTER_SOURCE!$A$2:$A$495,0)),""))} | L9: {=IF($D9="","",IFERROR(INDEX(MASTER_SOURCE!$D$2:$D$495,MATCH($I9,MASTER_SOURCE!$A$2:$A$495,0)),""))} | M9: Có | N9: Có | O9: Có | P9: Có | Q9: =IF($D9="","",IF(AND(OR(DANH_MUC!$L$5<>"Có",M9="Có"),OR(DANH_MUC!$L$6<>"Có",N9="Có"),OR(DANH_MUC!$L$7<>"Có",O9="Có"),OR(DANH_MUC!$L$8<>"Có",P9="Có")),"Có","Không")) | R9: =IF($D9="","",IF(COUNTIF($D$2:$D9,$D9)>1,"Trùng","")) | S9: =IF($D9="","",IF(AND(LEN($D9)=10,LEFT($D9,1)="0",ISNUMBER(--$D9)),"Có","Không")) | T9: =IF($D9="","",IF(AND($C9<>"",$Q9="Có",$R9="",$S9="Có",AND($L9<>"",OR($L9<>"Chưa xác định",DANH_MUC!$L$9="Có"))),"Có","Không")) | U9: =IF(OR($D9="",$T9="Có"),"",IF($C9="","Thiếu họ tên; ","")&IF($S9<>"Có","SĐT sai định dạng; ","")&IF($R9="Trùng","Trùng SĐT; ","")&IF($Q9<>"Có","Thiếu đồng ý bắt buộc; ","")&IF($L9="","Thiếu/sai Mã REF; ",IF(AND($L9="Chưa xác định",DANH_MUC!$L$9<>"Có"),"Nguồn chưa xác định; ",""))) | V9: =IF(OR($D9="",$R9="Trùng"),"",IF(COUNTIF(ORDERS!$C$2:$C$4995,$D9)>0,"Có","Không")) | W9: =IF(OR($D9="",$R9="Trùng"),"",COUNTIFS(ORDERS!$C$2:$C$4995,$D9,ORDERS!$L$2:$L$4995,"Đã chuyển khoản")) | X9: =IF(OR($D9="",$R9="Trùng"),"",SUMIFS(ORDERS!$J$2:$J$4995,ORDERS!$C$2:$C$4995,$D9,ORDERS!$L$2:$L$4995,"Đã chuyển khoản"))
A10: 261a8789-c269-441e-b75f-3d40478618de | B10: 46287.581 | C10: Nguyễn Thảo | D10: 0936028702 | E10: 46297 | F10: Đang mang thai | G10: Hồ Chí Minh | H10: =IF(ISNUMBER($B10),INT($B10)-WEEKDAY($B10,2)+1,"") | I10: Z-00 | J10: {=IF($D10="","",IF($I10="","(trống REF)",IFERROR(INDEX(MASTER_SOURCE!$B$2:$B$495,MATCH($I10,MASTER_SOURCE!$A$2:$A$495,0)),"(REF không có trong MASTER_SOURCE)")))} | K10: {=IF($D10="","",IFERROR(INDEX(MASTER_SOURCE!$C$2:$C$495,MATCH($I10,MASTER_SOURCE!$A$2:$A$495,0)),""))} | L10: {=IF($D10="","",IFERROR(INDEX(MASTER_SOURCE!$D$2:$D$495,MATCH($I10,MASTER_SOURCE!$A$2:$A$495,0)),""))} | M10: Có | N10: Có | O10: Có | P10: Có | Q10: =IF($D10="","",IF(AND(OR(DANH_MUC!$L$5<>"Có",M10="Có"),OR(DANH_MUC!$L$6<>"Có",N10="Có"),OR(DANH_MUC!$L$7<>"Có",O10="Có"),OR(DANH_MUC!$L$8<>"Có",P10="Có")),"Có","Không")) | R10: =IF($D10="","",IF(COUNTIF($D$2:$D10,$D10)>1,"Trùng","")) | S10: =IF($D10="","",IF(AND(LEN($D10)=10,LEFT($D10,1)="0",ISNUMBER(--$D10)),"Có","Không")) | T10: =IF($D10="","",IF(AND($C10<>"",$Q10="Có",$R10="",$S10="Có",AND($L10<>"",OR($L10<>"Chưa xác định",DANH_MUC!$L$9="Có"))),"Có","Không")) | U10: =IF(OR($D10="",$T10="Có"),"",IF($C10="","Thiếu họ tên; ","")&IF($S10<>"Có","SĐT sai định dạng; ","")&IF($R10="Trùng","Trùng SĐT; ","")&IF($Q10<>"Có","Thiếu đồng ý bắt buộc; ","")&IF($L10="","Thiếu/sai Mã REF; ",IF(AND($L10="Chưa xác định",DANH_MUC!$L$9<>"Có"),"Nguồn chưa xác định; ",""))) | V10: =IF(OR($D10="",$R10="Trùng"),"",IF(COUNTIF(ORDERS!$C$2:$C$4995,$D10)>0,"Có","Không")) | W10: =IF(OR($D10="",$R10="Trùng"),"",COUNTIFS(ORDERS!$C$2:$C$4995,$D10,ORDERS!$L$2:$L$4995,"Đã chuyển khoản")) | X10: =IF(OR($D10="",$R10="Trùng"),"",SUMIFS(ORDERS!$J$2:$J$4995,ORDERS!$C$2:$C$4995,$D10,ORDERS!$L$2:$L$4995,"Đã chuyển khoản"))
A11: 34f9340d-e395-403a-9a63-de2c771f56b1 | B11: 46287.59 | C11: Nguyễn Thị Việt | D11: 0368435969 | E11: 46315 | F11: Đang mang thai | G11: Hồ Chí Minh | H11: =IF(ISNUMBER($B11),INT($B11)-WEEKDAY($B11,2)+1,"") | I11: Z-00 | J11: {=IF($D11="","",IF($I11="","(trống REF)",IFERROR(INDEX(MASTER_SOURCE!$B$2:$B$495,MATCH($I11,MASTER_SOURCE!$A$2:$A$495,0)),"(REF không có trong MASTER_SOURCE)")))} | K11: {=IF($D11="","",IFERROR(INDEX(MASTER_SOURCE!$C$2:$C$495,MATCH($I11,MASTER_SOURCE!$A$2:$A$495,0)),""))} | L11: {=IF($D11="","",IFERROR(INDEX(MASTER_SOURCE!$D$2:$D$495,MATCH($I11,MASTER_SOURCE!$A$2:$A$495,0)),""))} | M11: Có | N11: Có | O11: Có | P11: Có | Q11: =IF($D11="","",IF(AND(OR(DANH_MUC!$L$5<>"Có",M11="Có"),OR(DANH_MUC!$L$6<>"Có",N11="Có"),OR(DANH_MUC!$L$7<>"Có",O11="Có"),OR(DANH_MUC!$L$8<>"Có",P11="Có")),"Có","Không")) | R11: =IF($D11="","",IF(COUNTIF($D$2:$D11,$D11)>1,"Trùng","")) | S11: =IF($D11="","",IF(AND(LEN($D11)=10,LEFT($D11,1)="0",ISNUMBER(--$D11)),"Có","Không")) | T11: =IF($D11="","",IF(AND($C11<>"",$Q11="Có",$R11="",$S11="Có",AND($L11<>"",OR($L11<>"Chưa xác định",DANH_MUC!$L$9="Có"))),"Có","Không")) | U11: =IF(OR($D11="",$T11="Có"),"",IF($C11="","Thiếu họ tên; ","")&IF($S11<>"Có","SĐT sai định dạng; ","")&IF($R11="Trùng","Trùng SĐT; ","")&IF($Q11<>"Có","Thiếu đồng ý bắt buộc; ","")&IF($L11="","Thiếu/sai Mã REF; ",IF(AND($L11="Chưa xác định",DANH_MUC!$L$9<>"Có"),"Nguồn chưa xác định; ",""))) | V11: =IF(OR($D11="",$R11="Trùng"),"",IF(COUNTIF(ORDERS!$C$2:$C$4995,$D11)>0,"Có","Không")) | W11: =IF(OR($D11="",$R11="Trùng"),"",COUNTIFS(ORDERS!$C$2:$C$4995,$D11,ORDERS!$L$2:$L$4995,"Đã chuyển khoản")) | X11: =IF(OR($D11="",$R11="Trùng"),"",SUMIFS(ORDERS!$J$2:$J$4995,ORDERS!$C$2:$C$4995,$D11,ORDERS!$L$2:$L$4995,"Đã chuyển khoản"))
A12: 5d402db6-b4c4-4c3f-b55d-88cf574a2a2f | B12: 46287.631 | C12: Cao Nguyễn Anh Thư | D12: 0964079475 | E12: 46335 | F12: Đang mang thai | G12: Hồ Chí Minh | H12: =IF(ISNUMBER($B12),INT($B12)-WEEKDAY($B12,2)+1,"") | I12: Z-00 | J12: {=IF($D12="","",IF($I12="","(trống REF)",IFERROR(INDEX(MASTER_SOURCE!$B$2:$B$495,MATCH($I12,MASTER_SOURCE!$A$2:$A$495,0)),"(REF không có trong MASTER_SOURCE)")))} | K12: {=IF($D12="","",IFERROR(INDEX(MASTER_SOURCE!$C$2:$C$495,MATCH($I12,MASTER_SOURCE!$A$2:$A$495,0)),""))} | L12: {=IF($D12="","",IFERROR(INDEX(MASTER_SOURCE!$D$2:$D$495,MATCH($I12,MASTER_SOURCE!$A$2:$A$495,0)),""))} | M12: Có | N12: Có | O12: Có | P12: Có | Q12: =IF($D12="","",IF(AND(OR(DANH_MUC!$L$5<>"Có",M12="Có"),OR(DANH_MUC!$L$6<>"Có",N12="Có"),OR(DANH_MUC!$L$7<>"Có",O12="Có"),OR(DANH_MUC!$L$8<>"Có",P12="Có")),"Có","Không")) | R12: =IF($D12="","",IF(COUNTIF($D$2:$D12,$D12)>1,"Trùng","")) | S12: =IF($D12="","",IF(AND(LEN($D12)=10,LEFT($D12,1)="0",ISNUMBER(--$D12)),"Có","Không")) | T12: =IF($D12="","",IF(AND($C12<>"",$Q12="Có",$R12="",$S12="Có",AND($L12<>"",OR($L12<>"Chưa xác định",DANH_MUC!$L$9="Có"))),"Có","Không")) | U12: =IF(OR($D12="",$T12="Có"),"",IF($C12="","Thiếu họ tên; ","")&IF($S12<>"Có","SĐT sai định dạng; ","")&IF($R12="Trùng","Trùng SĐT; ","")&IF($Q12<>"Có","Thiếu đồng ý bắt buộc; ","")&IF($L12="","Thiếu/sai Mã REF; ",IF(AND($L12="Chưa xác định",DANH_MUC!$L$9<>"Có"),"Nguồn chưa xác định; ",""))) | V12: =IF(OR($D12="",$R12="Trùng"),"",IF(COUNTIF(ORDERS!$C$2:$C$4995,$D12)>0,"Có","Không")) | W12: =IF(OR($D12="",$R12="Trùng"),"",COUNTIFS(ORDERS!$C$2:$C$4995,$D12,ORDERS!$L$2:$L$4995,"Đã chuyển khoản")) | X12: =IF(OR($D12="",$R12="Trùng"),"",SUMIFS(ORDERS!$J$2:$J$4995,ORDERS!$C$2:$C$4995,$D12,ORDERS!$L$2:$L$4995,"Đã chuyển khoản"))
A13: cba10242-654c-422a-bf30-a5239b495974 | B13: 46287.64 | C13: Đào Ngọc | D13: 0933951993 | E13: 46349 | F13: Đang mang thai | G13: Hồ Chí Minh | H13: =IF(ISNUMBER($B13),INT($B13)-WEEKDAY($B13,2)+1,"") | I13: Z-00 | J13: {=IF($D13="","",IF($I13="","(trống REF)",IFERROR(INDEX(MASTER_SOURCE!$B$2:$B$495,MATCH($I13,MASTER_SOURCE!$A$2:$A$495,0)),"(REF không có trong MASTER_SOURCE)")))} | K13: {=IF($D13="","",IFERROR(INDEX(MASTER_SOURCE!$C$2:$C$495,MATCH($I13,MASTER_SOURCE!$A$2:$A$495,0)),""))} | L13: {=IF($D13="","",IFERROR(INDEX(MASTER_SOURCE!$D$2:$D$495,MATCH($I13,MASTER_SOURCE!$A$2:$A$495,0)),""))} | M13: Có | N13: Không | O13: Có | P13: Không | Q13: =IF($D13="","",IF(AND(OR(DANH_MUC!$L$5<>"Có",M13="Có"),OR(DANH_MUC!$L$6<>"Có",N13="Có"),OR(DANH_MUC!$L$7<>"Có",O13="Có"),OR(DANH_MUC!$L$8<>"Có",P13="Có")),"Có","Không")) | R13: =IF($D13="","",IF(COUNTIF($D$2:$D13,$D13)>1,"Trùng","")) | S13: =IF($D13="","",IF(AND(LEN($D13)=10,LEFT($D13,1)="0",ISNUMBER(--$D13)),"Có","Không")) | T13: =IF($D13="","",IF(AND($C13<>"",$Q13="Có",$R13="",$S13="Có",AND($L13<>"",OR($L13<>"Chưa xác định",DANH_MUC!$L$9="Có"))),"Có","Không")) | U13: =IF(OR($D13="",$T13="Có"),"",IF($C13="","Thiếu họ tên; ","")&IF($S13<>"Có","SĐT sai định dạng; ","")&IF($R13="Trùng","Trùng SĐT; ","")&IF($Q13<>"Có","Thiếu đồng ý bắt buộc; ","")&IF($L13="","Thiếu/sai Mã REF; ",IF(AND($L13="Chưa xác định",DANH_MUC!$L$9<>"Có"),"Nguồn chưa xác định; ",""))) | V13: =IF(OR($D13="",$R13="Trùng"),"",IF(COUNTIF(ORDERS!$C$2:$C$4995,$D13)>0,"Có","Không")) | W13: =IF(OR($D13="",$R13="Trùng"),"",COUNTIFS(ORDERS!$C$2:$C$4995,$D13,ORDERS!$L$2:$L$4995,"Đã chuyển khoản")) | X13: =IF(OR($D13="",$R13="Trùng"),"",SUMIFS(ORDERS!$J$2:$J$4995,ORDERS!$C$2:$C$4995,$D13,ORDERS!$L$2:$L$4995,"Đã chuyển khoản"))
... A424: 0fad289e-0f3b-4725-a4d5-a1970e688ac0 | B424: 46297.922 | C424: Lê Thị Phượng | D424: 0354862626 | E424: 46270 | F424: Đã sinh | G424: Hải Phòng | H424: =IF(ISNUMBER($B424),INT($B424)-WEEKDAY($B424,2)+1,"") | I424: Z-YHP | J424: {=IF($D424="","",IF($I424="","(trống REF)",IFERROR(INDEX(MASTER_SOURCE!$B$2:$B$495,MATCH($I424,MASTER_SOURCE!$A$2:$A$495,0)),"(REF không có trong MASTER_SOURCE)")))} | K424: {=IF($D424="","",IFERROR(INDEX(MASTER_SOURCE!$C$2:$C$495,MATCH($I424,MASTER_SOURCE!$A$2:$A$495,0)),""))} | L424: {=IF($D424="","",IFERROR(INDEX(MASTER_SOURCE!$D$2:$D$495,MATCH($I424,MASTER_SOURCE!$A$2:$A$495,0)),""))} | M424: Có | N424: Có | O424: Có | P424: Có | Q424: =IF($D424="","",IF(AND(OR(DANH_MUC!$L$5<>"Có",M424="Có"),OR(DANH_MUC!$L$6<>"Có",N424="Có"),OR(DANH_MUC!$L$7<>"Có",O424="Có"),OR(DANH_MUC!$L$8<>"Có",P424="Có")),"Có","Không")) | R424: =IF($D424="","",IF(COUNTIF($D$2:$D424,$D424)>1,"Trùng","")) | S424: =IF($D424="","",IF(AND(LEN($D424)=10,LEFT($D424,1)="0",ISNUMBER(--$D424)),"Có","Không")) | T424: =IF($D424="","",IF(AND($C424<>"",$Q424="Có",$R424="",$S424="Có",AND($L424<>"",OR($L424<>"Chưa xác định",DANH_MUC!$L$9="Có"))),"Có","Không")) | U424: =IF(OR($D424="",$T424="Có"),"",IF($C424="","Thiếu họ tên; ","")&IF($S424<>"Có","SĐT sai định dạng; ","")&IF($R424="Trùng","Trùng SĐT; ","")&IF($Q424<>"Có","Thiếu đồng ý bắt buộc; ","")&IF($L424="","Thiếu/sai Mã REF; ",IF(AND($L424="Chưa xác định",DANH_MUC!$L$9<>"Có"),"Nguồn chưa xác định; ",""))) | V424: =IF(OR($D424="",$R424="Trùng"),"",IF(COUNTIF(ORDERS!$C$2:$C$4995,$D424)>0,"Có","Không")) | W424: =IF(OR($D424="",$R424="Trùng"),"",COUNTIFS(ORDERS!$C$2:$C$4995,$D424,ORDERS!$L$2:$L$4995,"Đã chuyển khoản")) | X424: =IF(OR($D424="",$R424="Trùng"),"",SUMIFS(ORDERS!$J$2:$J$4995,ORDERS!$C$2:$C$4995,$D424,ORDERS!$L$2:$L$4995,"Đã chuyển khoản"))
H425: =IF(ISNUMBER($B425),INT($B425)-WEEKDAY($B425,2)+1,"") | J425: {=IF($D425="","",IF($I425="","(trống REF)",IFERROR(INDEX(MASTER_SOURCE!$B$2:$B$495,MATCH($I425,MASTER_SOURCE!$A$2:$A$495,0)),"(REF không có trong MASTER_SOURCE)")))} | K425: {=IF($D425="","",IFERROR(INDEX(MASTER_SOURCE!$C$2:$C$495,MATCH($I425,MASTER_SOURCE!$A$2:$A$495,0)),""))} | L425: {=IF($D425="","",IFERROR(INDEX(MASTER_SOURCE!$D$2:$D$495,MATCH($I425,MASTER_SOURCE!$A$2:$A$495,0)),""))} | Q425: =IF($D425="","",IF(AND(OR(DANH_MUC!$L$5<>"Có",M425="Có"),OR(DANH_MUC!$L$6<>"Có",N425="Có"),OR(DANH_MUC!$L$7<>"Có",O425="Có"),OR(DANH_MUC!$L$8<>"Có",P425="Có")),"Có","Không")) | R425: =IF($D425="","",IF(COUNTIF($D$2:$D425,$D425)>1,"Trùng","")) | S425: =IF($D425="","",IF(AND(LEN($D425)=10,LEFT($D425,1)="0",ISNUMBER(--$D425)),"Có","Không")) | T425: =IF($D425="","",IF(AND($C425<>"",$Q425="Có",$R425="",$S425="Có",AND($L425<>"",OR($L425<>"Chưa xác định",DANH_MUC!$L$9="Có"))),"Có","Không")) | U425: =IF(OR($D425="",$T425="Có"),"",IF($C425="","Thiếu họ tên; ","")&IF($S425<>"Có","SĐT sai định dạng; ","")&IF($R425="Trùng","Trùng SĐT; ","")&IF($Q425<>"Có","Thiếu đồng ý bắt buộc; ","")&IF($L425="","Thiếu/sai Mã REF; ",IF(AND($L425="Chưa xác định",DANH_MUC!$L$9<>"Có"),"Nguồn chưa xác định; ",""))) | V425: =IF(OR($D425="",$R425="Trùng"),"",IF(COUNTIF(ORDERS!$C$2:$C$4995,$D425)>0,"Có","Không")) | W425: =IF(OR($D425="",$R425="Trùng"),"",COUNTIFS(ORDERS!$C$2:$C$4995,$D425,ORDERS!$L$2:$L$4995,"Đã chuyển khoản")) | X425: =IF(OR($D425="",$R425="Trùng"),"",SUMIFS(ORDERS!$J$2:$J$4995,ORDERS!$C$2:$C$4995,$D425,ORDERS!$L$2:$L$4995,"Đã chuyển khoản"))
H426: =IF(ISNUMBER($B426),INT($B426)-WEEKDAY($B426,2)+1,"") | J426: {=IF($D426="","",IF($I426="","(trống REF)",IFERROR(INDEX(MASTER_SOURCE!$B$2:$B$495,MATCH($I426,MASTER_SOURCE!$A$2:$A$495,0)),"(REF không có trong MASTER_SOURCE)")))} | K426: {=IF($D426="","",IFERROR(INDEX(MASTER_SOURCE!$C$2:$C$495,MATCH($I426,MASTER_SOURCE!$A$2:$A$495,0)),""))} | L426: {=IF($D426="","",IFERROR(INDEX(MASTER_SOURCE!$D$2:$D$495,MATCH($I426,MASTER_SOURCE!$A$2:$A$495,0)),""))} | Q426: =IF($D426="","",IF(AND(OR(DANH_MUC!$L$5<>"Có",M426="Có"),OR(DANH_MUC!$L$6<>"Có",N426="Có"),OR(DANH_MUC!$L$7<>"Có",O426="Có"),OR(DANH_MUC!$L$8<>"Có",P426="Có")),"Có","Không")) | R426: =IF($D426="","",IF(COUNTIF($D$2:$D426,$D426)>1,"Trùng","")) | S426: =IF($D426="","",IF(AND(LEN($D426)=10,LEFT($D426,1)="0",ISNUMBER(--$D426)),"Có","Không")) | T426: =IF($D426="","",IF(AND($C426<>"",$Q426="Có",$R426="",$S426="Có",AND($L426<>"",OR($L426<>"Chưa xác định",DANH_MUC!$L$9="Có"))),"Có","Không")) | U426: =IF(OR($D426="",$T426="Có"),"",IF($C426="","Thiếu họ tên; ","")&IF($S426<>"Có","SĐT sai định dạng; ","")&IF($R426="Trùng","Trùng SĐT; ","")&IF($Q426<>"Có","Thiếu đồng ý bắt buộc; ","")&IF($L426="","Thiếu/sai Mã REF; ",IF(AND($L426="Chưa xác định",DANH_MUC!$L$9<>"Có"),"Nguồn chưa xác định; ",""))) | V426: =IF(OR($D426="",$R426="Trùng"),"",IF(COUNTIF(ORDERS!$C$2:$C$4995,$D426)>0,"Có","Không")) | W426: =IF(OR($D426="",$R426="Trùng"),"",COUNTIFS(ORDERS!$C$2:$C$4995,$D426,ORDERS!$L$2:$L$4995,"Đã chuyển khoản")) | X426: =IF(OR($D426="",$R426="Trùng"),"",SUMIFS(ORDERS!$J$2:$J$4995,ORDERS!$C$2:$C$4995,$D426,ORDERS!$L$2:$L$4995,"Đã chuyển khoản"))
H427: =IF(ISNUMBER($B427),INT($B427)-WEEKDAY($B427,2)+1,"") | J427: {=IF($D427="","",IF($I427="","(trống REF)",IFERROR(INDEX(MASTER_SOURCE!$B$2:$B$495,MATCH($I427,MASTER_SOURCE!$A$2:$A$495,0)),"(REF không có trong MASTER_SOURCE)")))} | K427: {=IF($D427="","",IFERROR(INDEX(MASTER_SOURCE!$C$2:$C$495,MATCH($I427,MASTER_SOURCE!$A$2:$A$495,0)),""))} | L427: {=IF($D427="","",IFERROR(INDEX(MASTER_SOURCE!$D$2:$D$495,MATCH($I427,MASTER_SOURCE!$A$2:$A$495,0)),""))} | Q427: =IF($D427="","",IF(AND(OR(DANH_MUC!$L$5<>"Có",M427="Có"),OR(DANH_MUC!$L$6<>"Có",N427="Có"),OR(DANH_MUC!$L$7<>"Có",O427="Có"),OR(DANH_MUC!$L$8<>"Có",P427="Có")),"Có","Không")) | R427: =IF($D427="","",IF(COUNTIF($D$2:$D427,$D427)>1,"Trùng","")) | S427: =IF($D427="","",IF(AND(LEN($D427)=10,LEFT($D427,1)="0",ISNUMBER(--$D427)),"Có","Không")) | T427: =IF($D427="","",IF(AND($C427<>"",$Q427="Có",$R427="",$S427="Có",AND($L427<>"",OR($L427<>"Chưa xác định",DANH_MUC!$L$9="Có"))),"Có","Không")) | U427: =IF(OR($D427="",$T427="Có"),"",IF($C427="","Thiếu họ tên; ","")&IF($S427<>"Có","SĐT sai định dạng; ","")&IF($R427="Trùng","Trùng SĐT; ","")&IF($Q427<>"Có","Thiếu đồng ý bắt buộc; ","")&IF($L427="","Thiếu/sai Mã REF; ",IF(AND($L427="Chưa xác định",DANH_MUC!$L$9<>"Có"),"Nguồn chưa xác định; ",""))) | V427: =IF(OR($D427="",$R427="Trùng"),"",IF(COUNTIF(ORDERS!$C$2:$C$4995,$D427)>0,"Có","Không")) | W427: =IF(OR($D427="",$R427="Trùng"),"",COUNTIFS(ORDERS!$C$2:$C$4995,$D427,ORDERS!$L$2:$L$4995,"Đã chuyển khoản")) | X427: =IF(OR($D427="",$R427="Trùng"),"",SUMIFS(ORDERS!$J$2:$J$4995,ORDERS!$C$2:$C$4995,$D427,ORDERS!$L$2:$L$4995,"Đã chuyển khoản"))
H428: =IF(ISNUMBER($B428),INT($B428)-WEEKDAY($B428,2)+1,"") | J428: {=IF($D428="","",IF($I428="","(trống REF)",IFERROR(INDEX(MASTER_SOURCE!$B$2:$B$495,MATCH($I428,MASTER_SOURCE!$A$2:$A$495,0)),"(REF không có trong MASTER_SOURCE)")))} | K428: {=IF($D428="","",IFERROR(INDEX(MASTER_SOURCE!$C$2:$C$495,MATCH($I428,MASTER_SOURCE!$A$2:$A$495,0)),""))} | L428: {=IF($D428="","",IFERROR(INDEX(MASTER_SOURCE!$D$2:$D$495,MATCH($I428,MASTER_SOURCE!$A$2:$A$495,0)),""))} | Q428: =IF($D428="","",IF(AND(OR(DANH_MUC!$L$5<>"Có",M428="Có"),OR(DANH_MUC!$L$6<>"Có",N428="Có"),OR(DANH_MUC!$L$7<>"Có",O428="Có"),OR(DANH_MUC!$L$8<>"Có",P428="Có")),"Có","Không")) | R428: =IF($D428="","",IF(COUNTIF($D$2:$D428,$D428)>1,"Trùng","")) | S428: =IF($D428="","",IF(AND(LEN($D428)=10,LEFT($D428,1)="0",ISNUMBER(--$D428)),"Có","Không")) | T428: =IF($D428="","",IF(AND($C428<>"",$Q428="Có",$R428="",$S428="Có",AND($L428<>"",OR($L428<>"Chưa xác định",DANH_MUC!$L$9="Có"))),"Có","Không")) | U428: =IF(OR($D428="",$T428="Có"),"",IF($C428="","Thiếu họ tên; ","")&IF($S428<>"Có","SĐT sai định dạng; ","")&IF($R428="Trùng","Trùng SĐT; ","")&IF($Q428<>"Có","Thiếu đồng ý bắt buộc; ","")&IF($L428="","Thiếu/sai Mã REF; ",IF(AND($L428="Chưa xác định",DANH_MUC!$L$9<>"Có"),"Nguồn chưa xác định; ",""))) | V428: =IF(OR($D428="",$R428="Trùng"),"",IF(COUNTIF(ORDERS!$C$2:$C$4995,$D428)>0,"Có","Không")) | W428: =IF(OR($D428="",$R428="Trùng"),"",COUNTIFS(ORDERS!$C$2:$C$4995,$D428,ORDERS!$L$2:$L$4995,"Đã chuyển khoản")) | X428: =IF(OR($D428="",$R428="Trùng"),"",SUMIFS(ORDERS!$J$2:$J$4995,ORDERS!$C$2:$C$4995,$D428,ORDERS!$L$2:$L$4995,"Đã chuyển khoản"))
H429: =IF(ISNUMBER($B429),INT($B429)-WEEKDAY($B429,2)+1,"") | J429: {=IF($D429="","",IF($I429="","(trống REF)",IFERROR(INDEX(MASTER_SOURCE!$B$2:$B$495,MATCH($I429,MASTER_SOURCE!$A$2:$A$495,0)),"(REF không có trong MASTER_SOURCE)")))} | K429: {=IF($D429="","",IFERROR(INDEX(MASTER_SOURCE!$C$2:$C$495,MATCH($I429,MASTER_SOURCE!$A$2:$A$495,0)),""))} | L429: {=IF($D429="","",IFERROR(INDEX(MASTER_SOURCE!$D$2:$D$495,MATCH($I429,MASTER_SOURCE!$A$2:$A$495,0)),""))} | Q429: =IF($D429="","",IF(AND(OR(DANH_MUC!$L$5<>"Có",M429="Có"),OR(DANH_MUC!$L$6<>"Có",N429="Có"),OR(DANH_MUC!$L$7<>"Có",O429="Có"),OR(DANH_MUC!$L$8<>"Có",P429="Có")),"Có","Không")) | R429: =IF($D429="","",IF(COUNTIF($D$2:$D429,$D429)>1,"Trùng","")) | S429: =IF($D429="","",IF(AND(LEN($D429)=10,LEFT($D429,1)="0",ISNUMBER(--$D429)),"Có","Không")) | T429: =IF($D429="","",IF(AND($C429<>"",$Q429="Có",$R429="",$S429="Có",AND($L429<>"",OR($L429<>"Chưa xác định",DANH_MUC!$L$9="Có"))),"Có","Không")) | U429: =IF(OR($D429="",$T429="Có"),"",IF($C429="","Thiếu họ tên; ","")&IF($S429<>"Có","SĐT sai định dạng; ","")&IF($R429="Trùng","Trùng SĐT; ","")&IF($Q429<>"Có","Thiếu đồng ý bắt buộc; ","")&IF($L429="","Thiếu/sai Mã REF; ",IF(AND($L429="Chưa xác định",DANH_MUC!$L$9<>"Có"),"Nguồn chưa xác định; ",""))) | V429: =IF(OR($D429="",$R429="Trùng"),"",IF(COUNTIF(ORDERS!$C$2:$C$4995,$D429)>0,"Có","Không")) | W429: =IF(OR($D429="",$R429="Trùng"),"",COUNTIFS(ORDERS!$C$2:$C$4995,$D429,ORDERS!$L$2:$L$4995,"Đã chuyển khoản")) | X429: =IF(OR($D429="",$R429="Trùng"),"",SUMIFS(ORDERS!$J$2:$J$4995,ORDERS!$C$2:$C$4995,$D429,ORDERS!$L$2:$L$4995,"Đã chuyển khoản"))
H430: =IF(ISNUMBER($B430),INT($B430)-WEEKDAY($B430,2)+1,"") | J430: {=IF($D430="","",IF($I430="","(trống REF)",IFERROR(INDEX(MASTER_SOURCE!$B$2:$B$495,MATCH($I430,MASTER_SOURCE!$A$2:$A$495,0)),"(REF không có trong MASTER_SOURCE)")))} | K430: {=IF($D430="","",IFERROR(INDEX(MASTER_SOURCE!$C$2:$C$495,MATCH($I430,MASTER_SOURCE!$A$2:$A$495,0)),""))} | L430: {=IF($D430="","",IFERROR(INDEX(MASTER_SOURCE!$D$2:$D$495,MATCH($I430,MASTER_SOURCE!$A$2:$A$495,0)),""))} | Q430: =IF($D430="","",IF(AND(OR(DANH_MUC!$L$5<>"Có",M430="Có"),OR(DANH_MUC!$L$6<>"Có",N430="Có"),OR(DANH_MUC!$L$7<>"Có",O430="Có"),OR(DANH_MUC!$L$8<>"Có",P430="Có")),"Có","Không")) | R430: =IF($D430="","",IF(COUNTIF($D$2:$D430,$D430)>1,"Trùng","")) | S430: =IF($D430="","",IF(AND(LEN($D430)=10,LEFT($D430,1)="0",ISNUMBER(--$D430)),"Có","Không")) | T430: =IF($D430="","",IF(AND($C430<>"",$Q430="Có",$R430="",$S430="Có",AND($L430<>"",OR($L430<>"Chưa xác định",DANH_MUC!$L$9="Có"))),"Có","Không")) | U430: =IF(OR($D430="",$T430="Có"),"",IF($C430="","Thiếu họ tên; ","")&IF($S430<>"Có","SĐT sai định dạng; ","")&IF($R430="Trùng","Trùng SĐT; ","")&IF($Q430<>"Có","Thiếu đồng ý bắt buộc; ","")&IF($L430="","Thiếu/sai Mã REF; ",IF(AND($L430="Chưa xác định",DANH_MUC!$L$9<>"Có"),"Nguồn chưa xác định; ",""))) | V430: =IF(OR($D430="",$R430="Trùng"),"",IF(COUNTIF(ORDERS!$C$2:$C$4995,$D430)>0,"Có","Không")) | W430: =IF(OR($D430="",$R430="Trùng"),"",COUNTIFS(ORDERS!$C$2:$C$4995,$D430,ORDERS!$L$2:$L$4995,"Đã chuyển khoản")) | X430: =IF(OR($D430="",$R430="Trùng"),"",SUMIFS(ORDERS!$J$2:$J$4995,ORDERS!$C$2:$C$4995,$D430,ORDERS!$L$2:$L$4995,"Đã chuyển khoản"))
H431: =IF(ISNUMBER($B431),INT($B431)-WEEKDAY($B431,2)+1,"") | J431: {=IF($D431="","",IF($I431="","(trống REF)",IFERROR(INDEX(MASTER_SOURCE!$B$2:$B$495,MATCH($I431,MASTER_SOURCE!$A$2:$A$495,0)),"(REF không có trong MASTER_SOURCE)")))} | K431: {=IF($D431="","",IFERROR(INDEX(MASTER_SOURCE!$C$2:$C$495,MATCH($I431,MASTER_SOURCE!$A$2:$A$495,0)),""))} | L431: {=IF($D431="","",IFERROR(INDEX(MASTER_SOURCE!$D$2:$D$495,MATCH($I431,MASTER_SOURCE!$A$2:$A$495,0)),""))} | Q431: =IF($D431="","",IF(AND(OR(DANH_MUC!$L$5<>"Có",M431="Có"),OR(DANH_MUC!$L$6<>"Có",N431="Có"),OR(DANH_MUC!$L$7<>"Có",O431="Có"),OR(DANH_MUC!$L$8<>"Có",P431="Có")),"Có","Không")) | R431: =IF($D431="","",IF(COUNTIF($D$2:$D431,$D431)>1,"Trùng","")) | S431: =IF($D431="","",IF(AND(LEN($D431)=10,LEFT($D431,1)="0",ISNUMBER(--$D431)),"Có","Không")) | T431: =IF($D431="","",IF(AND($C431<>"",$Q431="Có",$R431="",$S431="Có",AND($L431<>"",OR($L431<>"Chưa xác định",DANH_MUC!$L$9="Có"))),"Có","Không")) | U431: =IF(OR($D431="",$T431="Có"),"",IF($C431="","Thiếu họ tên; ","")&IF($S431<>"Có","SĐT sai định dạng; ","")&IF($R431="Trùng","Trùng SĐT; ","")&IF($Q431<>"Có","Thiếu đồng ý bắt buộc; ","")&IF($L431="","Thiếu/sai Mã REF; ",IF(AND($L431="Chưa xác định",DANH_MUC!$L$9<>"Có"),"Nguồn chưa xác định; ",""))) | V431: =IF(OR($D431="",$R431="Trùng"),"",IF(COUNTIF(ORDERS!$C$2:$C$4995,$D431)>0,"Có","Không")) | W431: =IF(OR($D431="",$R431="Trùng"),"",COUNTIFS(ORDERS!$C$2:$C$4995,$D431,ORDERS!$L$2:$L$4995,"Đã chuyển khoản")) | X431: =IF(OR($D431="",$R431="Trùng"),"",SUMIFS(ORDERS!$J$2:$J$4995,ORDERS!$C$2:$C$4995,$D431,ORDERS!$L$2:$L$4995,"Đã chuyển khoản"))
H432: =IF(ISNUMBER($B432),INT($B432)-WEEKDAY($B432,2)+1,"") | J432: {=IF($D432="","",IF($I432="","(trống REF)",IFERROR(INDEX(MASTER_SOURCE!$B$2:$B$495,MATCH($I432,MASTER_SOURCE!$A$2:$A$495,0)),"(REF không có trong MASTER_SOURCE)")))} | K432: {=IF($D432="","",IFERROR(INDEX(MASTER_SOURCE!$C$2:$C$495,MATCH($I432,MASTER_SOURCE!$A$2:$A$495,0)),""))} | L432: {=IF($D432="","",IFERROR(INDEX(MASTER_SOURCE!$D$2:$D$495,MATCH($I432,MASTER_SOURCE!$A$2:$A$495,0)),""))} | Q432: =IF($D432="","",IF(AND(OR(DANH_MUC!$L$5<>"Có",M432="Có"),OR(DANH_MUC!$L$6<>"Có",N432="Có"),OR(DANH_MUC!$L$7<>"Có",O432="Có"),OR(DANH_MUC!$L$8<>"Có",P432="Có")),"Có","Không")) | R432: =IF($D432="","",IF(COUNTIF($D$2:$D432,$D432)>1,"Trùng","")) | S432: =IF($D432="","",IF(AND(LEN($D432)=10,LEFT($D432,1)="0",ISNUMBER(--$D432)),"Có","Không")) | T432: =IF($D432="","",IF(AND($C432<>"",$Q432="Có",$R432="",$S432="Có",AND($L432<>"",OR($L432<>"Chưa xác định",DANH_MUC!$L$9="Có"))),"Có","Không")) | U432: =IF(OR($D432="",$T432="Có"),"",IF($C432="","Thiếu họ tên; ","")&IF($S432<>"Có","SĐT sai định dạng; ","")&IF($R432="Trùng","Trùng SĐT; ","")&IF($Q432<>"Có","Thiếu đồng ý bắt buộc; ","")&IF($L432="","Thiếu/sai Mã REF; ",IF(AND($L432="Chưa xác định",DANH_MUC!$L$9<>"Có"),"Nguồn chưa xác định; ",""))) | V432: =IF(OR($D432="",$R432="Trùng"),"",IF(COUNTIF(ORDERS!$C$2:$C$4995,$D432)>0,"Có","Không")) | W432: =IF(OR($D432="",$R432="Trùng"),"",COUNTIFS(ORDERS!$C$2:$C$4995,$D432,ORDERS!$L$2:$L$4995,"Đã chuyển khoản")) | X432: =IF(OR($D432="",$R432="Trùng"),"",SUMIFS(ORDERS!$J$2:$J$4995,ORDERS!$C$2:$C$4995,$D432,ORDERS!$L$2:$L$4995,"Đã chuyển khoản"))
H433: =IF(ISNUMBER($B433),INT($B433)-WEEKDAY($B433,2)+1,"") | J433: {=IF($D433="","",IF($I433="","(trống REF)",IFERROR(INDEX(MASTER_SOURCE!$B$2:$B$495,MATCH($I433,MASTER_SOURCE!$A$2:$A$495,0)),"(REF không có trong MASTER_SOURCE)")))} | K433: {=IF($D433="","",IFERROR(INDEX(MASTER_SOURCE!$C$2:$C$495,MATCH($I433,MASTER_SOURCE!$A$2:$A$495,0)),""))} | L433: {=IF($D433="","",IFERROR(INDEX(MASTER_SOURCE!$D$2:$D$495,MATCH($I433,MASTER_SOURCE!$A$2:$A$495,0)),""))} | Q433: =IF($D433="","",IF(AND(OR(DANH_MUC!$L$5<>"Có",M433="Có"),OR(DANH_MUC!$L$6<>"Có",N433="Có"),OR(DANH_MUC!$L$7<>"Có",O433="Có"),OR(DANH_MUC!$L$8<>"Có",P433="Có")),"Có","Không")) | R433: =IF($D433="","",IF(COUNTIF($D$2:$D433,$D433)>1,"Trùng","")) | S433: =IF($D433="","",IF(AND(LEN($D433)=10,LEFT($D433,1)="0",ISNUMBER(--$D433)),"Có","Không")) | T433: =IF($D433="","",IF(AND($C433<>"",$Q433="Có",$R433="",$S433="Có",AND($L433<>"",OR($L433<>"Chưa xác định",DANH_MUC!$L$9="Có"))),"Có","Không")) | U433: =IF(OR($D433="",$T433="Có"),"",IF($C433="","Thiếu họ tên; ","")&IF($S433<>"Có","SĐT sai định dạng; ","")&IF($R433="Trùng","Trùng SĐT; ","")&IF($Q433<>"Có","Thiếu đồng ý bắt buộc; ","")&IF($L433="","Thiếu/sai Mã REF; ",IF(AND($L433="Chưa xác định",DANH_MUC!$L$9<>"Có"),"Nguồn chưa xác định; ",""))) | V433: =IF(OR($D433="",$R433="Trùng"),"",IF(COUNTIF(ORDERS!$C$2:$C$4995,$D433)>0,"Có","Không")) | W433: =IF(OR($D433="",$R433="Trùng"),"",COUNTIFS(ORDERS!$C$2:$C$4995,$D433,ORDERS!$L$2:$L$4995,"Đã chuyển khoản")) | X433: =IF(OR($D433="",$R433="Trùng"),"",SUMIFS(ORDERS!$J$2:$J$4995,ORDERS!$C$2:$C$4995,$D433,ORDERS!$L$2:$L$4995,"Đã chuyển khoản"))
H434: =IF(ISNUMBER($B434),INT($B434)-WEEKDAY($B434,2)+1,"") | J434: {=IF($D434="","",IF($I434="","(trống REF)",IFERROR(INDEX(MASTER_SOURCE!$B$2:$B$495,MATCH($I434,MASTER_SOURCE!$A$2:$A$495,0)),"(REF không có trong MASTER_SOURCE)")))} | K434: {=IF($D434="","",IFERROR(INDEX(MASTER_SOURCE!$C$2:$C$495,MATCH($I434,MASTER_SOURCE!$A$2:$A$495,0)),""))} | L434: {=IF($D434="","",IFERROR(INDEX(MASTER_SOURCE!$D$2:$D$495,MATCH($I434,MASTER_SOURCE!$A$2:$A$495,0)),""))} | Q434: =IF($D434="","",IF(AND(OR(DANH_MUC!$L$5<>"Có",M434="Có"),OR(DANH_MUC!$L$6<>"Có",N434="Có"),OR(DANH_MUC!$L$7<>"Có",O434="Có"),OR(DANH_MUC!$L$8<>"Có",P434="Có")),"Có","Không")) | R434: =IF($D434="","",IF(COUNTIF($D$2:$D434,$D434)>1,"Trùng","")) | S434: =IF($D434="","",IF(AND(LEN($D434)=10,LEFT($D434,1)="0",ISNUMBER(--$D434)),"Có","Không")) | T434: =IF($D434="","",IF(AND($C434<>"",$Q434="Có",$R434="",$S434="Có",AND($L434<>"",OR($L434<>"Chưa xác định",DANH_MUC!$L$9="Có"))),"Có","Không")) | U434: =IF(OR($D434="",$T434="Có"),"",IF($C434="","Thiếu họ tên; ","")&IF($S434<>"Có","SĐT sai định dạng; ","")&IF($R434="Trùng","Trùng SĐT; ","")&IF($Q434<>"Có","Thiếu đồng ý bắt buộc; ","")&IF($L434="","Thiếu/sai Mã REF; ",IF(AND($L434="Chưa xác định",DANH_MUC!$L$9<>"Có"),"Nguồn chưa xác định; ",""))) | V434: =IF(OR($D434="",$R434="Trùng"),"",IF(COUNTIF(ORDERS!$C$2:$C$4995,$D434)>0,"Có","Không")) | W434: =IF(OR($D434="",$R434="Trùng"),"",COUNTIFS(ORDERS!$C$2:$C$4995,$D434,ORDERS!$L$2:$L$4995,"Đã chuyển khoản")) | X434: =IF(OR($D434="",$R434="Trùng"),"",SUMIFS(ORDERS!$J$2:$J$4995,ORDERS!$C$2:$C$4995,$D434,ORDERS!$L$2:$L$4995,"Đã chuyển khoản"))
H435: =IF(ISNUMBER($B435),INT($B435)-WEEKDAY($B435,2)+1,"") | J435: {=IF($D435="","",IF($I435="","(trống REF)",IFERROR(INDEX(MASTER_SOURCE!$B$2:$B$495,MATCH($I435,MASTER_SOURCE!$A$2:$A$495,0)),"(REF không có trong MASTER_SOURCE)")))} | K435: {=IF($D435="","",IFERROR(INDEX(MASTER_SOURCE!$C$2:$C$495,MATCH($I435,MASTER_SOURCE!$A$2:$A$495,0)),""))} | L435: {=IF($D435="","",IFERROR(INDEX(MASTER_SOURCE!$D$2:$D$495,MATCH($I435,MASTER_SOURCE!$A$2:$A$495,0)),""))} | Q435: =IF($D435="","",IF(AND(OR(DANH_MUC!$L$5<>"Có",M435="Có"),OR(DANH_MUC!$L$6<>"Có",N435="Có"),OR(DANH_MUC!$L$7<>"Có",O435="Có"),OR(DANH_MUC!$L$8<>"Có",P435="Có")),"Có","Không")) | R435: =IF($D435="","",IF(COUNTIF($D$2:$D435,$D435)>1,"Trùng","")) | S435: =IF($D435="","",IF(AND(LEN($D435)=10,LEFT($D435,1)="0",ISNUMBER(--$D435)),"Có","Không")) | T435: =IF($D435="","",IF(AND($C435<>"",$Q435="Có",$R435="",$S435="Có",AND($L435<>"",OR($L435<>"Chưa xác định",DANH_MUC!$L$9="Có"))),"Có","Không")) | U435: =IF(OR($D435="",$T435="Có"),"",IF($C435="","Thiếu họ tên; ","")&IF($S435<>"Có","SĐT sai định dạng; ","")&IF($R435="Trùng","Trùng SĐT; ","")&IF($Q435<>"Có","Thiếu đồng ý bắt buộc; ","")&IF($L435="","Thiếu/sai Mã REF; ",IF(AND($L435="Chưa xác định",DANH_MUC!$L$9<>"Có"),"Nguồn chưa xác định; ",""))) | V435: =IF(OR($D435="",$R435="Trùng"),"",IF(COUNTIF(ORDERS!$C$2:$C$4995,$D435)>0,"Có","Không")) | W435: =IF(OR($D435="",$R435="Trùng"),"",COUNTIFS(ORDERS!$C$2:$C$4995,$D435,ORDERS!$L$2:$L$4995,"Đã chuyển khoản")) | X435: =IF(OR($D435="",$R435="Trùng"),"",SUMIFS(ORDERS!$J$2:$J$4995,ORDERS!$C$2:$C$4995,$D435,ORDERS!$L$2:$L$4995,"Đã chuyển khoản"))
H436: =IF(ISNUMBER($B436),INT($B436)-WEEKDAY($B436,2)+1,"") | J436: {=IF($D436="","",IF($I436="","(trống REF)",IFERROR(INDEX(MASTER_SOURCE!$B$2:$B$495,MATCH($I436,MASTER_SOURCE!$A$2:$A$495,0)),"(REF không có trong MASTER_SOURCE)")))} | K436: {=IF($D436="","",IFERROR(INDEX(MASTER_SOURCE!$C$2:$C$495,MATCH($I436,MASTER_SOURCE!$A$2:$A$495,0)),""))} | L436: {=IF($D436="","",IFERROR(INDEX(MASTER_SOURCE!$D$2:$D$495,MATCH($I436,MASTER_SOURCE!$A$2:$A$495,0)),""))} | Q436: =IF($D436="","",IF(AND(OR(DANH_MUC!$L$5<>"Có",M436="Có"),OR(DANH_MUC!$L$6<>"Có",N436="Có"),OR(DANH_MUC!$L$7<>"Có",O436="Có"),OR(DANH_MUC!$L$8<>"Có",P436="Có")),"Có","Không")) | R436: =IF($D436="","",IF(COUNTIF($D$2:$D436,$D436)>1,"Trùng","")) | S436: =IF($D436="","",IF(AND(LEN($D436)=10,LEFT($D436,1)="0",ISNUMBER(--$D436)),"Có","Không")) | T436: =IF($D436="","",IF(AND($C436<>"",$Q436="Có",$R436="",$S436="Có",AND($L436<>"",OR($L436<>"Chưa xác định",DANH_MUC!$L$9="Có"))),"Có","Không")) | U436: =IF(OR($D436="",$T436="Có"),"",IF($C436="","Thiếu họ tên; ","")&IF($S436<>"Có","SĐT sai định dạng; ","")&IF($R436="Trùng","Trùng SĐT; ","")&IF($Q436<>"Có","Thiếu đồng ý bắt buộc; ","")&IF($L436="","Thiếu/sai Mã REF; ",IF(AND($L436="Chưa xác định",DANH_MUC!$L$9<>"Có"),"Nguồn chưa xác định; ",""))) | V436: =IF(OR($D436="",$R436="Trùng"),"",IF(COUNTIF(ORDERS!$C$2:$C$4995,$D436)>0,"Có","Không")) | W436: =IF(OR($D436="",$R436="Trùng"),"",COUNTIFS(ORDERS!$C$2:$C$4995,$D436,ORDERS!$L$2:$L$4995,"Đã chuyển khoản")) | X436: =IF(OR($D436="",$R436="Trùng"),"",SUMIFS(ORDERS!$J$2:$J$4995,ORDERS!$C$2:$C$4995,$D436,ORDERS!$L$2:$L$4995,"Đã chuyển khoản"))
... H5000: =IF(ISNUMBER($B5000),INT($B5000)-WEEKDAY($B5000,2)+1,"") | J5000: {=IF($D5000="","",IF($I5000="","(trống REF)",IFERROR(INDEX(MASTER_SOURCE!$B$2:$B$495,MATCH($I5000,MASTER_SOURCE!$A$2:$A$495,0)),"(REF không có trong MASTER_SOURCE)")))} | K5000: {=IF($D5000="","",IFERROR(INDEX(MASTER_SOURCE!$C$2:$C$495,MATCH($I5000,MASTER_SOURCE!$A$2:$A$495,0)),""))} | L5000: {=IF($D5000="","",IFERROR(INDEX(MASTER_SOURCE!$D$2:$D$495,MATCH($I5000,MASTER_SOURCE!$A$2:$A$495,0)),""))} | Q5000: =IF($D5000="","",IF(AND(OR(DANH_MUC!$L$5<>"Có",M5000="Có"),OR(DANH_MUC!$L$6<>"Có",N5000="Có"),OR(DANH_MUC!$L$7<>"Có",O5000="Có"),OR(DANH_MUC!$L$8<>"Có",P5000="Có")),"Có","Không")) | R5000: =IF($D5000="","",IF(COUNTIF($D$2:$D5000,$D5000)>1,"Trùng","")) | S5000: =IF($D5000="","",IF(AND(LEN($D5000)=10,LEFT($D5000,1)="0",ISNUMBER(--$D5000)),"Có","Không")) | T5000: =IF($D5000="","",IF(AND($C5000<>"",$Q5000="Có",$R5000="",$S5000="Có",AND($L5000<>"",OR($L5000<>"Chưa xác định",DANH_MUC!$L$9="Có"))),"Có","Không")) | U5000: =IF(OR($D5000="",$T5000="Có"),"",IF($C5000="","Thiếu họ tên; ","")&IF($S5000<>"Có","SĐT sai định dạng; ","")&IF($R5000="Trùng","Trùng SĐT; ","")&IF($Q5000<>"Có","Thiếu đồng ý bắt buộc; ","")&IF($L5000="","Thiếu/sai Mã REF; ",IF(AND($L5000="Chưa xác định",DANH_MUC!$L$9<>"Có"),"Nguồn chưa xác định; ",""))) | V5000: =IF(OR($D5000="",$R5000="Trùng"),"",IF(COUNTIF(ORDERS!$C$2:$C$4995,$D5000)>0,"Có","Không")) | W5000: =IF(OR($D5000="",$R5000="Trùng"),"",COUNTIFS(ORDERS!$C$2:$C$4995,$D5000,ORDERS!$L$2:$L$4995,"Đã chuyển khoản")) | X5000: =IF(OR($D5000="",$R5000="Trùng"),"",SUMIFS(ORDERS!$J$2:$J$4995,ORDERS!$C$2:$C$4995,$D5000,ORDERS!$L$2:$L$4995,"Đã chuyển khoản"))

Sheet ORDERS
A1: Mã đơn | B1: Ngày đặt | C1: SĐT đăng ký | D1: Họ tên (từ DATA_MASTER) | E1: Mã REF | F1: Team | G1: Combo / sản phẩm | H1: Số lượng | I1: Đơn giá (VNĐ) | J1: Thành tiền (VNĐ) | K1: Hình thức TT | L1: Trạng thái TT | M1: Ngày nhận CK | N1: SĐT nhận hàng | O1: Người nhận | P1: Địa chỉ nhận | Q1: Trạng thái giao | R1: Người bán | S1: Kiểm tra | T1: Ghi chú
A2: 1 | B2: 15/9/2026 | C2: 0988318495 | D2: =IF($C2="","",IFERROR(INDEX(DATA_MASTER!$C$2:$C$5000,MATCH($C2,DATA_MASTER!$D$2:$D$5000,0)),"Châu Mỹ Nhi")) | E2: =IF($C2="","",IFERROR(INDEX(DATA_MASTER!$I$2:$I$5000,MATCH($C2,DATA_MASTER!$D$2:$D$5000,0)),"")) | F2: =IF($C2="","",IFERROR(INDEX(DATA_MASTER!$L$2:$L$5000,MATCH($C2,DATA_MASTER!$D$2:$D$5000,0)),"ZM")) | G2: Sữa Aptamil 380g | H2: 1 | I2: 320000 | J2: =IF(OR($H2="",$I2=""),"",$H2*$I2) | K2: Chuyển khoản QR | L2: Đã chuyển khoản | M2: 15/9/2026 | N2: 0988318495 | O2: Châu Mỹ Nhi | P2: Sảnh B Tháp C1, chung cư Picity High Park, 9A Đường Thạnh Xuân 13, Thạnh Xuân, Quận 12 | Q2: Đã giao | R2: Voi Con | S2: =IF(AND($A2="",$C2=""),"",IF($A2="","Thiếu mã đơn; ","")&IF(COUNTIF($A$2:$A2,$A2)>1,"Trùng mã đơn; ","")&IF(COUNTIF($C$2:$C2,$C2)>1,"Trùng SĐT; ","")&IF(ISNA(MATCH($C2,DATA_MASTER!$D$2:$D$5000,0)),"SĐT chưa đăng ký hội viên; ","")&IF(AND($L2="Đã chuyển khoản",$M2=""),"Thiếu ngày nhận CK; ","")) | T2: ĐVVC: J&T | Mã VĐ: 801113029239 | POD: https://drive.google.com/drive/folders/14YqSb9mohXWUMATpBaLAocW_7uBLVQM8 | Bill: https://drive.google.com/drive/folders/1szwxYRL9ETmCmqj7BvAX8q8voLzWVEdM?usp=drive_link
A3: 2 | B3: 15/9/2026 | C3: 0911122888 | D3: =IF($C3="","",IFERROR(INDEX(DATA_MASTER!$C$2:$C$5000,MATCH($C3,DATA_MASTER!$D$2:$D$5000,0)),"Phạm Thị Ánh Ngọc")) | E3: =IF($C3="","",IFERROR(INDEX(DATA_MASTER!$I$2:$I$5000,MATCH($C3,DATA_MASTER!$D$2:$D$5000,0)),"")) | F3: =IF($C3="","",IFERROR(INDEX(DATA_MASTER!$L$2:$L$5000,MATCH($C3,DATA_MASTER!$D$2:$D$5000,0)),"ZM")) | G3: Sữa Aptamil 380g | H3: 1 | I3: 320000 | J3: =IF(OR($H3="",$I3=""),"",$H3*$I3) | K3: Chuyển khoản QR | L3: Đã chuyển khoản | M3: 15/9/2026 | N3: 0911122888 | O3: Phạm Thị Ánh Ngọc | P3: Lô B chung cư Bộ Công an, đường số 3, phường An Khánh, Quận Thủ Đức | Q3: Đã giao | R3: Voi Con | S3: =IF(AND($A3="",$C3=""),"",IF($A3="","Thiếu mã đơn; ","")&IF(COUNTIF($A$2:$A3,$A3)>1,"Trùng mã đơn; ","")&IF(COUNTIF($C$2:$C3,$C3)>1,"Trùng SĐT; ","")&IF(ISNA(MATCH($C3,DATA_MASTER!$D$2:$D$5000,0)),"SĐT chưa đăng ký hội viên; ","")&IF(AND($L3="Đã chuyển khoản",$M3=""),"Thiếu ngày nhận CK; ","")) | T3: ĐVVC: Ahamove | Mã VĐ: 775818591 | POD: https://drive.google.com/drive/folders/14YqSb9mohXWUMATpBaLAocW_7uBLVQM8 | Bill: Voi Con
A4: 3 | B4: 16/9/2026 | C4: 0776645191 | D4: =IF($C4="","",IFERROR(INDEX(DATA_MASTER!$C$2:$C$5000,MATCH($C4,DATA_MASTER!$D$2:$D$5000,0)),"Chị Nga")) | E4: =IF($C4="","",IFERROR(INDEX(DATA_MASTER!$I$2:$I$5000,MATCH($C4,DATA_MASTER!$D$2:$D$5000,0)),"")) | F4: =IF($C4="","",IFERROR(INDEX(DATA_MASTER!$L$2:$L$5000,MATCH($C4,DATA_MASTER!$D$2:$D$5000,0)),"ZM")) | G4: Sữa Aptamil 380g | H4: 1 | I4: 320000 | J4: =IF(OR($H4="",$I4=""),"",$H4*$I4) | K4: Chuyển khoản QR | L4: Đã chuyển khoản | M4: 16/9/2026 | N4: 0776645191 | O4: Chị Nga | P4: E11/18L ấp 48 Thới Hòa, xã Vĩnh Lộc, HCM, Bình Chánh | Q4: Đã giao | R4: Voi Con | S4: =IF(AND($A4="",$C4=""),"",IF($A4="","Thiếu mã đơn; ","")&IF(COUNTIF($A$2:$A4,$A4)>1,"Trùng mã đơn; ","")&IF(COUNTIF($C$2:$C4,$C4)>1,"Trùng SĐT; ","")&IF(ISNA(MATCH($C4,DATA_MASTER!$D$2:$D$5000,0)),"SĐT chưa đăng ký hội viên; ","")&IF(AND($L4="Đã chuyển khoản",$M4=""),"Thiếu ngày nhận CK; ","")) | T4: ĐVVC: J&T | Mã VĐ: 801113925129 | POD: https://drive.google.com/drive/folders/14YqSb9mohXWUMATpBaLAocW_7uBLVQM8 | Bill: Voi Con
A5: 4 | B5: 16/9/2026 | C5: 0963214847 | D5: =IF($C5="","",IFERROR(INDEX(DATA_MASTER!$C$2:$C$5000,MATCH($C5,DATA_MASTER!$D$2:$D$5000,0)),"Trần Như Quyên")) | E5: =IF($C5="","",IFERROR(INDEX(DATA_MASTER!$I$2:$I$5000,MATCH($C5,DATA_MASTER!$D$2:$D$5000,0)),"")) | F5: =IF($C5="","",IFERROR(INDEX(DATA_MASTER!$L$2:$L$5000,MATCH($C5,DATA_MASTER!$D$2:$D$5000,0)),"ZM")) | G5: Sữa Aptamil 380g | H5: 1 | I5: 320000 | J5: =IF(OR($H5="",$I5=""),"",$H5*$I5) | K5: Chuyển khoản QR | L5: Đã chuyển khoản | M5: 16/9/2026 | N5: 0963214847 | O5: Trần Như Quyên | P5: 66-68 Đường số 37 Phường Bình Trưng, Tp Thủ Đức | Q5: Đã giao | R5: Voi Con | S5: =IF(AND($A5="",$C5=""),"",IF($A5="","Thiếu mã đơn; ","")&IF(COUNTIF($A$2:$A5,$A5)>1,"Trùng mã đơn; ","")&IF(COUNTIF($C$2:$C5,$C5)>1,"Trùng SĐT; ","")&IF(ISNA(MATCH($C5,DATA_MASTER!$D$2:$D$5000,0)),"SĐT chưa đăng ký hội viên; ","")&IF(AND($L5="Đã chuyển khoản",$M5=""),"Thiếu ngày nhận CK; ","")) | T5: ĐVVC: Shipper riêng | Mã VĐ: 353282909 | POD: https://drive.google.com/drive/folders/14YqSb9mohXWUMATpBaLAocW_7uBLVQM8
A6: 5 | B6: 16/9/2026 | C6: 0938921181 | D6: =IF($C6="","",IFERROR(INDEX(DATA_MASTER!$C$2:$C$5000,MATCH($C6,DATA_MASTER!$D$2:$D$5000,0)),"Trần Phan Huyền Trân")) | E6: =IF($C6="","",IFERROR(INDEX(DATA_MASTER!$I$2:$I$5000,MATCH($C6,DATA_MASTER!$D$2:$D$5000,0)),"")) | F6: =IF($C6="","",IFERROR(INDEX(DATA_MASTER!$L$2:$L$5000,MATCH($C6,DATA_MASTER!$D$2:$D$5000,0)),"ZM")) | G6: Sữa Aptamil 380g | H6: 1 | I6: 320000 | J6: =IF(OR($H6="",$I6=""),"",$H6*$I6) | K6: Chuyển khoản QR | L6: Đã chuyển khoản | M6: 16/9/2026 | N6: 0938921181 | O6: Trần Phan Huyền Trân | P6: 199/8 đường 3/2, phường Vườn Lài | Q6: Đã giao | R6: Voi Con | S6: =IF(AND($A6="",$C6=""),"",IF($A6="","Thiếu mã đơn; ","")&IF(COUNTIF($A$2:$A6,$A6)>1,"Trùng mã đơn; ","")&IF(COUNTIF($C$2:$C6,$C6)>1,"Trùng SĐT; ","")&IF(ISNA(MATCH($C6,DATA_MASTER!$D$2:$D$5000,0)),"SĐT chưa đăng ký hội viên; ","")&IF(AND($L6="Đã chuyển khoản",$M6=""),"Thiếu ngày nhận CK; ","")) | T6: ĐVVC: Shipper riêng | Mã VĐ: 353282909 | POD: https://drive.google.com/drive/folders/14YqSb9mohXWUMATpBaLAocW_7uBLVQM8
A7: 6 | B7: 16/9/2026 | C7: 0569795552 | D7: =IF($C7="","",IFERROR(INDEX(DATA_MASTER!$C$2:$C$5000,MATCH($C7,DATA_MASTER!$D$2:$D$5000,0)),"Mỹ Linh")) | E7: =IF($C7="","",IFERROR(INDEX(DATA_MASTER!$I$2:$I$5000,MATCH($C7,DATA_MASTER!$D$2:$D$5000,0)),"")) | F7: =IF($C7="","",IFERROR(INDEX(DATA_MASTER!$L$2:$L$5000,MATCH($C7,DATA_MASTER!$D$2:$D$5000,0)),"ZM")) | G7: Sữa Aptamil 380g | H7: 1 | I7: 320000 | J7: =IF(OR($H7="",$I7=""),"",$H7*$I7) | K7: Chuyển khoản QR | L7: Đã chuyển khoản | M7: 16/9/2026 | N7: 0569795552 | O7: Mỹ Linh | P7: 8/48 đường Tân Hóa, phường 1, Quận 11 | Q7: Đã giao | R7: Voi Con | S7: =IF(AND($A7="",$C7=""),"",IF($A7="","Thiếu mã đơn; ","")&IF(COUNTIF($A$2:$A7,$A7)>1,"Trùng mã đơn; ","")&IF(COUNTIF($C$2:$C7,$C7)>1,"Trùng SĐT; ","")&IF(ISNA(MATCH($C7,DATA_MASTER!$D$2:$D$5000,0)),"SĐT chưa đăng ký hội viên; ","")&IF(AND($L7="Đã chuyển khoản",$M7=""),"Thiếu ngày nhận CK; ","")) | T7: ĐVVC: Shipper riêng | Mã VĐ: 353282909 | POD: https://drive.google.com/drive/folders/14YqSb9mohXWUMATpBaLAocW_7uBLVQM8
A8: 7 | B8: 16/9/2026 | C8: 0965301505 | D8: =IF($C8="","",IFERROR(INDEX(DATA_MASTER!$C$2:$C$5000,MATCH($C8,DATA_MASTER!$D$2:$D$5000,0)),"Trang Thanh")) | E8: =IF($C8="","",IFERROR(INDEX(DATA_MASTER!$I$2:$I$5000,MATCH($C8,DATA_MASTER!$D$2:$D$5000,0)),"")) | F8: =IF($C8="","",IFERROR(INDEX(DATA_MASTER!$L$2:$L$5000,MATCH($C8,DATA_MASTER!$D$2:$D$5000,0)),"ZM")) | G8: Sữa Aptamil 380g | H8: 1 | I8: 320000 | J8: =IF(OR($H8="",$I8=""),"",$H8*$I8) | K8: Chuyển khoản QR | L8: Đã chuyển khoản | M8: 16/9/2026 | N8: 0965301505 | O8: Trang Thanh | P8: 494/39 Phú Định, Phường Phú Định | Q8: Đã giao | R8: Voi Con | S8: =IF(AND($A8="",$C8=""),"",IF($A8="","Thiếu mã đơn; ","")&IF(COUNTIF($A$2:$A8,$A8)>1,"Trùng mã đơn; ","")&IF(COUNTIF($C$2:$C8,$C8)>1,"Trùng SĐT; ","")&IF(ISNA(MATCH($C8,DATA_MASTER!$D$2:$D$5000,0)),"SĐT chưa đăng ký hội viên; ","")&IF(AND($L8="Đã chuyển khoản",$M8=""),"Thiếu ngày nhận CK; ","")) | T8: ĐVVC: Shipper riêng | Mã VĐ: 353282909 | POD: https://drive.google.com/drive/folders/14YqSb9mohXWUMATpBaLAocW_7uBLVQM8
A9: 8 | B9: 16/9/2026 | C9: 0902861292 | D9: =IF($C9="","",IFERROR(INDEX(DATA_MASTER!$C$2:$C$5000,MATCH($C9,DATA_MASTER!$D$2:$D$5000,0)),"Chị Vân")) | E9: =IF($C9="","",IFERROR(INDEX(DATA_MASTER!$I$2:$I$5000,MATCH($C9,DATA_MASTER!$D$2:$D$5000,0)),"")) | F9: =IF($C9="","",IFERROR(INDEX(DATA_MASTER!$L$2:$L$5000,MATCH($C9,DATA_MASTER!$D$2:$D$5000,0)),"ZM")) | G9: Sữa Aptamil 380g | H9: 1 | I9: 320000 | J9: =IF(OR($H9="",$I9=""),"",$H9*$I9) | K9: Chuyển khoản QR | L9: Đã chuyển khoản | M9: 16/9/2026 | N9: 0902861292 | O9: Chị Vân | P9: 157/7/1C Dương Bá Trạc, P. Chánh Hưng | Q9: Đã giao | R9: Voi Con | S9: =IF(AND($A9="",$C9=""),"",IF($A9="","Thiếu mã đơn; ","")&IF(COUNTIF($A$2:$A9,$A9)>1,"Trùng mã đơn; ","")&IF(COUNTIF($C$2:$C9,$C9)>1,"Trùng SĐT; ","")&IF(ISNA(MATCH($C9,DATA_MASTER!$D$2:$D$5000,0)),"SĐT chưa đăng ký hội viên; ","")&IF(AND($L9="Đã chuyển khoản",$M9=""),"Thiếu ngày nhận CK; ","")) | T9: ĐVVC: Shipper riêng | Mã VĐ: 353282909 | POD: https://drive.google.com/drive/folders/14YqSb9mohXWUMATpBaLAocW_7uBLVQM8
