Workbook

Sheet DASHBOARD TỔNG QUAN
A1: TIẾN ĐỘ DỰ ÁN– DANONE x ZMOMS
A2: MỤC TIÊU CHIẾN DỊCH: 10,010 DATA XÁC THỰC | 2,517 NEW USERS (NU COMBO) | LỘ TRÌNH 16 TUẦN (15/09/2026 - 04/01/2027)
A3: Cập nhật tự động 100% thời gian thực • Đồng bộ Lead Co-data, Hoạt động Nữ hộ sinh tại nhà, Dữ liệu thai kỳ & Lớp Online
A4: 🏥 TIẾN TRÌNH SK BỆNH VIỆN | C4: 🎯 LEAD & NU SỰ KIỆN | E4: 👩‍⚕️ NỮ HỘ SINH TƯ VẤN TẠI NHÀ | H4: 🤰 DỮ LIỆU THAI KỲ & COHORT | K4: 💻 LỚP ONLINE | M4: 📝 ACTION ITEMS
A5: 🎯 TIẾN ĐỘ DATA XÁC THỰC | C5: 🛒 TIẾN ĐỘ NU COMBO | E5: ⚡ TỶ LỆ CHUYỂN ĐỔI (CR) | G5: 👩‍⚕️ NỮ HỘ SINH TƯ VẤN TẠI NHÀ | J5: 🤰 THAI KỲ & ĐƠN HÀNG THÀNH CÔNG | M5: 🏥 ĐỐI TÁC BV
A6: 1212 | C6: 322 | E6: =C6/A6 -> 0.26567657 | M6: =SUM(K14:K29) -> 23
A8: ="Target: 10,010 | Đạt: " & TEXT(SUM(D14:D29)/10010, "0.0%") -> Target: 10,010 | Đạt: 11.5% | C8: ="Target: 2,517 | Đạt: " & TEXT(SUM(G14:G29)/2517, "0.0%") -> Target: 2,517 | Đạt: 12.8% | E8: Target chuẩn: 25.14% | G8: ="CR tư vấn: " & TEXT('THEO DÕI MIDWIFE TẠI NHÀ'!I19, "0.0%") & " | " & 'THEO DÕI MIDWIFE TẠI NHÀ'!J19 & " NU (" & TEXT('THEO DÕI MIDWIFE TẠI NHÀ'!K19, "0.0%") & ")" -> CR tư vấn: 0.0% | 0 NU (0.0%) | J8: ="Tỷ lệ đơn/đăng ký: " & TEXT('DATA THAI KỲ & CONVERT'!M20, "0.0%") & " | Co-data: " & TEXT('DATA THAI KỲ & CONVERT'!K20, "0.0%") & "" -> Tỷ lệ đơn/đăng ký: 0.0% | Co-data: 0.0% | M8: ="Cơ sở đã chấp thuận" -> Cơ sở đã chấp thuận
A10: ⚡ BÀN PHÍM ĐIỀU HƯỚNG NHANH TỚI 16 TUẦN CHIẾN DỊCH (CLICK ĐỂ ĐẾN CHI TIẾT TUẦN)
A11: ▶ W01 (15/09) | B11: ▶ W02 (22/09) | C11: ▶ W03 (29/09) | D11: ▶ W04 (06/10) | E11: ▶ W05 (13/10) | G11: ▶ W06 (20/10) | I11: ▶ W07 (27/10) | K11: ▶ W08 (03/11)
A12: ▶ W09 (10/11) | B12: ▶ W10 (17/11) | C12: ▶ W11 (24/11) | D12: ▶ W12 (01/12) | E12: ▶ W13 (08/12) | G12: ▶ W14 (15/12) | I12: ▶ W15 (22/12) | K12: ▶ W16 (29/12)
A13: TUẦN | B13: KHOẢNG THỜI GIAN | C13: TARGET DATA | D13: ACTUAL DATA | E13: % ĐẠT DATA | F13: TARGET NU | G13: ACTUAL NU | H13: % ĐẠT NU | I13: TỶ LỆ CR | J13: LỊCH HẸN BV | K13: BV DUYỆT SK | L13: LỚP ONLINE | M13: TRẠNG THÁI TUẦN
A14: W01 | B14: 15/09 - 21/09 | C14: 626 | D14: 120 | E14: =IF(C14>0, D14/C14, 0) -> 0.19169329 | F14: 0 | G14: =IF('W01 (15-21.09)'!G5="",0,'W01 (15-21.09)'!G5) -> 44 | H14: =IF(F14>0, G14/F14, 0) -> 0 | I14: =IF(D14>0, G14/D14, 0) -> 0.36666667 | J14: =COUNTA('W01 (15-21.09)'!B11:B25) -> 13 | K14: =COUNTIF('W01 (15-21.09)'!H11:H25, "Đã chấp thuận") -> 11 | L14: =COUNTA('W01 (15-21.09)'!C28:C35) -> 0 | M14: =IF(D14>=C14, "🟢 Hoàn thành KPI", IF(D14>0, "🟡 Đang bám sát", IF(J14>0, "🔵 Đã hẹn BV", "⚪ Chưa triển khai"))) -> 🟡 Đang bám sát
A15: W02 | B15: 22/09 - 28/09 | C15: 626 | D15: 400 | E15: =IF(C15>0, D15/C15, 0) -> 0.63897764 | F15: 215 | G15: 110 | H15: =IF(F15>0, G15/F15, 0) -> 0.51162791 | I15: =IF(D15>0, G15/D15, 0) -> 0.275 | J15: =COUNTA('W02 (22-28.09)'!B11:B25) -> 1 | K15: =COUNTIF('W02 (22-28.09)'!H11:H25, "Đã chấp thuận") -> 1 | L15: =COUNTA('W02 (22-28.09)'!C33:C40) -> 1 | M15: =IF(D15>=C15, "🟢 Hoàn thành KPI", IF(D15>0, "🟡 Đang bám sát", IF(J15>0, "🔵 Đã hẹn BV", "⚪ Chưa triển khai"))) -> 🟡 Đang bám sát
A16: W03 | B16: 29/09 - 05/10 | C16: 626 | D16: 629 | E16: =IF(C16>0, D16/C16, 0) -> 1.0047923 | F16: 272 | G16: 168 | H16: =IF(F16>0, G16/F16, 0) -> 0.61764706 | I16: =IF(D16>0, G16/D16, 0) -> 0.26709062 | J16: =COUNTA('W03 (29-05.10)'!B11:B25) -> 1 | K16: =COUNTIF('W03 (29-05.10)'!H11:H25, "Đã chấp thuận") -> 0 | L16: =COUNTA('W03 (29-05.10)'!C31:C38) -> 2 | M16: =IF(D16>=C16, "🟢 Hoàn thành KPI", IF(D16>0, "🟡 Đang bám sát", IF(J16>0, "🔵 Đã hẹn BV", "⚪ Chưa triển khai"))) -> 🟢 Hoàn thành KPI
A17: W04 | B17: 06/10 - 12/10 | C17: 626 | D17: =IF('W04 (06-12.10)'!D5="",0,'W04 (06-12.10)'!D5) -> 0 | E17: =IF(C17>0, D17/C17, 0) -> 0 | F17: 272 | G17: =IF('W04 (06-12.10)'!G5="",0,'W04 (06-12.10)'!G5) -> 0 | H17: =IF(F17>0, G17/F17, 0) -> 0 | I17: =IF(D17>0, G17/D17, 0) -> 0 | J17: =COUNTA('W04 (06-12.10)'!B11:B25) -> 2 | K17: =COUNTIF('W04 (06-12.10)'!H11:H25, "Đã chấp thuận") -> 0 | L17: =COUNTA('W04 (06-12.10)'!C31:C38) -> 1 | M17: =IF(D17>=C17, "🟢 Hoàn thành KPI", IF(D17>0, "🟡 Đang bám sát", IF(J17>0, "🔵 Đã hẹn BV", "⚪ Chưa triển khai"))) -> 🔵 Đã hẹn BV
A18: W05 | B18: 13/10 - 19/10 | C18: 626 | D18: =IF('W05 (13-19.10)'!D5="",0,'W05 (13-19.10)'!D5) -> 0 | E18: =IF(C18>0, D18/C18, 0) -> 0 | F18: 272 | G18: =IF('W05 (13-19.10)'!G5="",0,'W05 (13-19.10)'!G5) -> 0 | H18: =IF(F18>0, G18/F18, 0) -> 0 | I18: =IF(D18>0, G18/D18, 0) -> 0 | J18: =COUNTA('W05 (13-19.10)'!B11:B25) -> 3 | K18: =COUNTIF('W05 (13-19.10)'!H11:H25, "Đã chấp thuận") -> 0 | L18: =COUNTA('W05 (13-19.10)'!C31:C38) -> 1 | M18: =IF(D18>=C18, "🟢 Hoàn thành KPI", IF(D18>0, "🟡 Đang bám sát", IF(J18>0, "🔵 Đã hẹn BV", "⚪ Chưa triển khai"))) -> 🔵 Đã hẹn BV
A19: W06 | B19: 20/10 - 26/10 | C19: 626 | D19: =IF('W06 (20-26.10)'!D5="",0,'W06 (20-26.10)'!D5) -> 0 | E19: =IF(C19>0, D19/C19, 0) -> 0 | F19: 272 | G19: =IF('W06 (20-26.10)'!G5="",0,'W06 (20-26.10)'!G5) -> 0 | H19: =IF(F19>0, G19/F19, 0) -> 0 | I19: =IF(D19>0, G19/D19, 0) -> 0 | J19: =COUNTA('W06 (20-26.10)'!B11:B25) -> 14 | K19: =COUNTIF('W06 (20-26.10)'!H11:H25, "Đã chấp thuận") -> 11 | L19: =COUNTA('W06 (20-26.10)'!C31:C38) -> 1 | M19: =IF(D19>=C19, "🟢 Hoàn thành KPI", IF(D19>0, "🟡 Đang bám sát", IF(J19>0, "🔵 Đã hẹn BV", "⚪ Chưa triển khai"))) -> 🔵 Đã hẹn BV
A20: W07 | B20: 27/10 - 02/11 | C20: 626 | D20: =IF('W07 (27-02.11)'!D5="",0,'W07 (27-02.11)'!D5) -> 0 | E20: =IF(C20>0, D20/C20, 0) -> 0 | F20: 272 | G20: =IF('W07 (27-02.11)'!G5="",0,'W07 (27-02.11)'!G5) -> 0 | H20: =IF(F20>0, G20/F20, 0) -> 0 | I20: =IF(D20>0, G20/D20, 0) -> 0 | J20: =COUNTA('W07 (27-02.11)'!B11:B25) -> 1 | K20: =COUNTIF('W07 (27-02.11)'!H11:H25, "Đã chấp thuận") -> 0 | L20: =COUNTA('W07 (27-02.11)'!C31:C38) -> 1 | M20: =IF(D20>=C20, "🟢 Hoàn thành KPI", IF(D20>0, "🟡 Đang bám sát", IF(J20>0, "🔵 Đã hẹn BV", "⚪ Chưa triển khai"))) -> 🔵 Đã hẹn BV
A21: W08 | B21: 03/11 - 09/11 | C21: 626 | D21: =IF('W08 (03-09.11)'!D5="",0,'W08 (03-09.11)'!D5) -> 0 | E21: =IF(C21>0, D21/C21, 0) -> 0 | F21: 157 | G21: =IF('W08 (03-09.11)'!G5="",0,'W08 (03-09.11)'!G5) -> 0 | H21: =IF(F21>0, G21/F21, 0) -> 0 | I21: =IF(D21>0, G21/D21, 0) -> 0 | J21: =COUNTA('W08 (03-09.11)'!B11:B25) -> 0 | K21: =COUNTIF('W08 (03-09.11)'!H11:H25, "Đã chấp thuận") -> 0 | L21: =COUNTA('W08 (03-09.11)'!C31:C38) -> 0 | M21: =IF(D21>=C21, "🟢 Hoàn thành KPI", IF(D21>0, "🟡 Đang bám sát", IF(J21>0, "🔵 Đã hẹn BV", "⚪ Chưa triển khai"))) -> ⚪ Chưa triển khai
A22: W09 | B22: 10/11 - 16/11 | C22: 626 | D22: =IF('W09 (10-16.11)'!D5="",0,'W09 (10-16.11)'!D5) -> 0 | E22: =IF(C22>0, D22/C22, 0) -> 0 | F22: 157 | G22: =IF('W09 (10-16.11)'!G5="",0,'W09 (10-16.11)'!G5) -> 0 | H22: =IF(F22>0, G22/F22, 0) -> 0 | I22: =IF(D22>0, G22/D22, 0) -> 0 | J22: =COUNTA('W09 (10-16.11)'!B11:B25) -> 0 | K22: =COUNTIF('W09 (10-16.11)'!H11:H25, "Đã chấp thuận") -> 0 | L22: =COUNTA('W09 (10-16.11)'!C31:C38) -> 0 | M22: =IF(D22>=C22, "🟢 Hoàn thành KPI", IF(D22>0, "🟡 Đang bám sát", IF(J22>0, "🔵 Đã hẹn BV", "⚪ Chưa triển khai"))) -> ⚪ Chưa triển khai
A23: W10 | B23: 17/11 - 23/11 | C23: 626 | D23: =IF('W10 (17-23.11)'!D5="",0,'W10 (17-23.11)'!D5) -> 0 | E23: =IF(C23>0, D23/C23, 0) -> 0 | F23: 157 | G23: =IF('W10 (17-23.11)'!G5="",0,'W10 (17-23.11)'!G5) -> 0 | H23: =IF(F23>0, G23/F23, 0) -> 0 | I23: =IF(D23>0, G23/D23, 0) -> 0 | J23: =COUNTA('W10 (17-23.11)'!B11:B25) -> 0 | K23: =COUNTIF('W10 (17-23.11)'!H11:H25, "Đã chấp thuận") -> 0 | L23: =COUNTA('W10 (17-23.11)'!C31:C38) -> 0 | M23: =IF(D23>=C23, "🟢 Hoàn thành KPI", IF(D23>0, "🟡 Đang bám sát", IF(J23>0, "🔵 Đã hẹn BV", "⚪ Chưa triển khai"))) -> ⚪ Chưa triển khai
A24: W11 | B24: 24/11 - 30/11 | C24: 626 | D24: =IF('W11 (24-30.11)'!D5="",0,'W11 (24-30.11)'!D5) -> 0 | E24: =IF(C24>0, D24/C24, 0) -> 0 | F24: 157 | G24: =IF('W11 (24-30.11)'!G5="",0,'W11 (24-30.11)'!G5) -> 0 | H24: =IF(F24>0, G24/F24, 0) -> 0 | I24: =IF(D24>0, G24/D24, 0) -> 0 | J24: =COUNTA('W11 (24-30.11)'!B11:B25) -> 0 | K24: =COUNTIF('W11 (24-30.11)'!H11:H25, "Đã chấp thuận") -> 0 | L24: =COUNTA('W11 (24-30.11)'!C31:C38) -> 0 | M24: =IF(D24>=C24, "🟢 Hoàn thành KPI", IF(D24>0, "🟡 Đang bám sát", IF(J24>0, "🔵 Đã hẹn BV", "⚪ Chưa triển khai"))) -> ⚪ Chưa triển khai
A25: W12 | B25: 01/12 - 07/12 | C25: 626 | D25: =IF('W12 (01-07.12)'!D5="",0,'W12 (01-07.12)'!D5) -> 0 | E25: =IF(C25>0, D25/C25, 0) -> 0 | F25: 157 | G25: =IF('W12 (01-07.12)'!G5="",0,'W12 (01-07.12)'!G5) -> 0 | H25: =IF(F25>0, G25/F25, 0) -> 0 | I25: =IF(D25>0, G25/D25, 0) -> 0 | J25: =COUNTA('W12 (01-07.12)'!B11:B25) -> 0 | K25: =COUNTIF('W12 (01-07.12)'!H11:H25, "Đã chấp thuận") -> 0 | L25: =COUNTA('W12 (01-07.12)'!C31:C38) -> 0 | M25: =IF(D25>=C25, "🟢 Hoàn thành KPI", IF(D25>0, "🟡 Đang bám sát", IF(J25>0, "🔵 Đã hẹn BV", "⚪ Chưa triển khai"))) -> ⚪ Chưa triển khai
A26: W13 | B26: 08/12 - 14/12 | C26: 626 | D26: =IF('W13 (08-14.12)'!D5="",0,'W13 (08-14.12)'!D5) -> 0 | E26: =IF(C26>0, D26/C26, 0) -> 0 | F26: 157 | G26: =IF('W13 (08-14.12)'!G5="",0,'W13 (08-14.12)'!G5) -> 0 | H26: =IF(F26>0, G26/F26, 0) -> 0 | I26: =IF(D26>0, G26/D26, 0) -> 0 | J26: =COUNTA('W13 (08-14.12)'!B11:B25) -> 0 | K26: =COUNTIF('W13 (08-14.12)'!H11:H25, "Đã chấp thuận") -> 0 | L26: =COUNTA('W13 (08-14.12)'!C31:C38) -> 0 | M26: =IF(D26>=C26, "🟢 Hoàn thành KPI", IF(D26>0, "🟡 Đang bám sát", IF(J26>0, "🔵 Đã hẹn BV", "⚪ Chưa triển khai"))) -> ⚪ Chưa triển khai
A27: W14 | B27: 15/12 - 21/12 | C27: 626 | D27: =IF('W14 (15-21.12)'!D5="",0,'W14 (15-21.12)'!D5) -> 0 | E27: =IF(C27>0, D27/C27, 0) -> 0 | F27: 157 | G27: =IF('W14 (15-21.12)'!G5="",0,'W14 (15-21.12)'!G5) -> 0 | H27: =IF(F27>0, G27/F27, 0) -> 0 | I27: =IF(D27>0, G27/D27, 0) -> 0 | J27: =COUNTA('W14 (15-21.12)'!B11:B25) -> 0 | K27: =COUNTIF('W14 (15-21.12)'!H11:H25, "Đã chấp thuận") -> 0 | L27: =COUNTA('W14 (15-21.12)'!C31:C38) -> 0 | M27: =IF(D27>=C27, "🟢 Hoàn thành KPI", IF(D27>0, "🟡 Đang bám sát", IF(J27>0, "🔵 Đã hẹn BV", "⚪ Chưa triển khai"))) -> ⚪ Chưa triển khai
A28: W15 | B28: 22/12 - 28/12 | C28: 626 | D28: =IF('W15 (22-28.12)'!D5="",0,'W15 (22-28.12)'!D5) -> 0 | E28: =IF(C28>0, D28/C28, 0) -> 0 | F28: 157 | G28: =IF('W15 (22-28.12)'!G5="",0,'W15 (22-28.12)'!G5) -> 0 | H28: =IF(F28>0, G28/F28, 0) -> 0 | I28: =IF(D28>0, G28/D28, 0) -> 0 | J28: =COUNTA('W15 (22-28.12)'!B11:B25) -> 0 | K28: =COUNTIF('W15 (22-28.12)'!H11:H25, "Đã chấp thuận") -> 0 | L28: =COUNTA('W15 (22-28.12)'!C31:C38) -> 0 | M28: =IF(D28>=C28, "🟢 Hoàn thành KPI", IF(D28>0, "🟡 Đang bám sát", IF(J28>0, "🔵 Đã hẹn BV", "⚪ Chưa triển khai"))) -> ⚪ Chưa triển khai
A29: W16 | B29: 29/12 - 04/01 | C29: 620 | D29: =IF('W16 (29-04.01)'!D5="",0,'W16 (29-04.01)'!D5) -> 0 | E29: =IF(C29>0, D29/C29, 0) -> 0 | F29: 162 | G29: =IF('W16 (29-04.01)'!G5="",0,'W16 (29-04.01)'!G5) -> 0 | H29: =IF(F29>0, G29/F29, 0) -> 0 | I29: =IF(D29>0, G29/D29, 0) -> 0 | J29: =COUNTA('W16 (29-04.01)'!B11:B25) -> 0 | K29: =COUNTIF('W16 (29-04.01)'!H11:H25, "Đã chấp thuận") -> 0 | L29: =COUNTA('W16 (29-04.01)'!C31:C38) -> 0 | M29: =IF(D29>=C29, "🟢 Hoàn thành KPI", IF(D29>0, "🟡 Đang bám sát", IF(J29>0, "🔵 Đã hẹn BV", "⚪ Chưa triển khai"))) -> ⚪ Chưa triển khai
A30: TỔNG CỘNG | B30: 16 TUẦN | C30: =SUM(C14:C29) -> 10010 | D30: 1212 | E30: =IF(C30>0, D30/C30, 0) -> 0.12107892 | F30: =SUM(F14:F29) -> 2993 | G30: 322 | H30: =IF(F30>0, G30/F30, 0) -> 0.10758436 | I30: =IF(D30>0, G30/D30, 0) -> 0.26567657 | J30: =SUM(J14:J29) -> 35 | K30: =SUM(K14:K29) -> 23 | L30: =SUM(L14:L29) -> 7 | M30: =IF(D30>=C30, "🏆 ĐẠT TARGET", "⚡ TIẾP TỤC BÁM ĐÍCH") -> ⚡ TIẾP TỤC BÁM ĐÍCH
A32: 🏥 BẢNG TỔNG HỢP TIẾN TRÌNH LỊCH HẸN & PHÊ DUYỆT SỰ KIỆN BỆNH VIỆN (PHÂN THEO THÁNG 9 - 12)
A33: * Tự động đồng bộ 100% từ 16 Tab tuần • Phân nhóm theo 4 tháng chiến dịch • Tự động ẩn ngày trống (không hiển thị 00/01/1900)
A34: 🗓️ THÁNG 09/2026 (W01 - W02) | D34: 🗓️ THÁNG 10/2026 (W03 - W07) | G34: 🗓️ THÁNG 11/2026 (W08 - W11) | J34: 🗓️ THÁNG 12/2026 - 01/2027 (W12 - W16)
A35: ="Đã chốt: " & (COUNTIFS('W01 (15-21.09)'!H11:H25, "Đã chấp thuận", 'W01 (15-21.09)'!I11:I25, "<>") + COUNTIFS('W02 (22-28.09)'!H11:H25, "Đã chấp thuận", 'W02 (22-28.09)'!I11:I25, "<>")) & " sự kiện BV" -> Đã chốt: 4 sự kiện BV | D35: ="Đã chốt: " & (COUNTIFS('W03 (29-05.10)'!H11:H25, "Đã chấp thuận", 'W03 (29-05.10)'!I11:I25, "<>") + COUNTIFS('W04 (06-12.10)'!H11:H25, "Đã chấp thuận", 'W04 (06-12.10)'!I11:I25, "<>") + COUNTIFS('W05 (13-19.10)'!H11:H25, "Đã chấp thuận", 'W05 (13-19.10)'!I11:I25, "<>") + COUNTIFS('W06 (20-26.10)'!H11:H25, "Đã chấp thuận", 'W06 (20-26.10)'!I11:I25, "<>") + COUNTIFS('W07 (27-02.11)'!H11:H25, "Đã chấp thuận", 'W07 (27-02.11)'!I11:I25, "<>")) & " sự kiện BV" -> Đã chốt: 11 sự kiện BV | G35: ="Đã chốt: " & (COUNTIFS('W08 (03-09.11)'!H11:H25, "Đã chấp thuận", 'W08 (03-09.11)'!I11:I25, "<>") + COUNTIFS('W09 (10-16.11)'!H11:H25, "Đã chấp thuận", 'W09 (10-16.11)'!I11:I25, "<>") + COUNTIFS('W10 (17-23.11)'!H11:H25, "Đã chấp thuận", 'W10 (17-23.11)'!I11:I25, "<>") + COUNTIFS('W11 (24-30.11)'!H11:H25, "Đã chấp thuận", 'W11 (24-30.11)'!I11:I25, "<>")) & " sự kiện BV" -> Đã chốt: 0 sự kiện BV | J35: ="Đã chốt: " & (COUNTIFS('W12 (01-07.12)'!H11:H25, "Đã chấp thuận", 'W12 (01-07.12)'!I11:I25, "<>") + COUNTIFS('W13 (08-14.12)'!H11:H25, "Đã chấp thuận", 'W13 (08-14.12)'!I11:I25, "<>") + COUNTIFS('W14 (15-21.12)'!H11:H25, "Đã chấp thuận", 'W14 (15-21.12)'!I11:I25, "<>") + COUNTIFS('W15 (22-28.12)'!H11:H25, "Đã chấp thuận", 'W15 (22-28.12)'!I11:I25, "<>") + COUNTIFS('W16 (29-04.01)'!H11:H25, "Đã chấp thuận", 'W16 (29-04.01)'!I11:I25, "<>")) & " sự kiện BV" -> Đã chốt: 0 sự kiện BV
A36: ="Quy mô: " & TEXT(SUM('W01 (15-21.09)'!J11:J25) + SUM('W02 (22-28.09)'!J11:J25), "#,##0") & " Mẹ tiếp cận" -> Quy mô: 2,430 Mẹ tiếp cận | D36: ="Quy mô: " & TEXT(SUM('W03 (29-05.10)'!J11:J25) + SUM('W04 (06-12.10)'!J11:J25) + SUM('W05 (13-19.10)'!J11:J25) + SUM('W06 (20-26.10)'!J11:J25) + SUM('W07 (27-02.11)'!J11:J25), "#,##0") & " Mẹ tiếp cận" -> Quy mô: 990 Mẹ tiếp cận | G36: ="Quy mô: " & TEXT(SUM('W08 (03-09.11)'!J11:J25) + SUM('W09 (10-16.11)'!J11:J25) + SUM('W10 (17-23.11)'!J11:J25) + SUM('W11 (24-30.11)'!J11:J25), "#,##0") & " Mẹ tiếp cận" -> Quy mô: 0 Mẹ tiếp cận | J36: ="Quy mô: " & TEXT(SUM('W12 (01-07.12)'!J11:J25) + SUM('W13 (08-14.12)'!J11:J25) + SUM('W14 (15-21.12)'!J11:J25) + SUM('W15 (22-28.12)'!J11:J25) + SUM('W16 (29-04.01)'!J11:J25), "#,##0") & " Mẹ tiếp cận" -> Quy mô: 0 Mẹ tiếp cận
A37: 🟢 Đang triển khai (5 SK chốt ngày) | D37: 🟢 11 BV chốt lịch (W06) | G37: ⚪ Kế hoạch mở rộng W08-W11 | J37: ⚪ Kế hoạch về đích W12-W16
A39: STT | B39: TÊN BỆNH VIỆN / CƠ SỞ Y TẾ | C39: KHU VỰC / TỈNH | D39: TUẦN | E39: NGƯỜI LIÊN HỆ BV | F39: PIC PHỤ TRÁCH | G39: NGÀY GIỜ HẸN GẶP | H39: TÌNH TRẠNG HẸN | I39: CHẤP THUẬN TỔ CHỨC SK | J39: NGÀY TỔ CHỨC SỰ KIỆN | K39: QUY MÔ DỰ KIẾN | L39: LIÊN KẾT TUẦN | M39: GHI CHÚ / TIẾN ĐỘ VẬN HÀNH
A40: 🌟 THÁNG 09/2026: GIAI ĐOẠN KHỞI ĐỘNG & MỞ RỘNG ĐỐI TÁC (W01 - W02: 15/09 - 28/09)
A41: =IF(B41="","",COUNTA($B$41:B41)) -> 1 | B41: =IF('W01 (15-21.09)'!B11="","",'W01 (15-21.09)'!B11) -> Bệnh viện Âu Cơ | C41: =IF('W01 (15-21.09)'!B11="","",'W01 (15-21.09)'!C11) -> Đồng Nai | D41: =IF('W01 (15-21.09)'!B11="","","W01") -> W01 | E41: =IF('W01 (15-21.09)'!B11="","",'W01 (15-21.09)'!D11) | F41: =IF('W01 (15-21.09)'!B11="","",'W01 (15-21.09)'!E11) | G41: =IF('W01 (15-21.09)'!B11="","",IF(OR('W01 (15-21.09)'!F11="",'W01 (15-21.09)'!F11=0),"",'W01 (15-21.09)'!F11)) -> 46275 | H41: =IF('W01 (15-21.09)'!B11="","",'W01 (15-21.09)'!G11) -> Đã gặp | I41: =IF('W01 (15-21.09)'!B11="","",'W01 (15-21.09)'!H11) -> Đã chấp thuận | J41: =IF('W01 (15-21.09)'!B11="","",IF(OR('W01 (15-21.09)'!I11="",'W01 (15-21.09)'!I11=0),"",'W01 (15-21.09)'!I11)) -> 46291 | K41: =IF('W01 (15-21.09)'!B11="","",IF(OR('W01 (15-21.09)'!J11="",'W01 (15-21.09)'!J11=0),"",'W01 (15-21.09)'!J11)) -> 90 | L41: =IF('W01 (15-21.09)'!B11="","","Chi tiết ➔") -> Chi tiết ➔ | M41: =IF('W01 (15-21.09)'!B11="","",'W01 (15-21.09)'!K11) -> 50
A42: =IF(B42="","",COUNTA($B$41:B42)) -> 2 | B42: =IF('W01 (15-21.09)'!B12="","",'W01 (15-21.09)'!B12) -> Bệnh viện Xuyên Á | C42: =IF('W01 (15-21.09)'!B12="","",'W01 (15-21.09)'!C12) -> Củ Chi | D42: =IF('W01 (15-21.09)'!B12="","","W01") -> W01 | E42: =IF('W01 (15-21.09)'!B12="","",'W01 (15-21.09)'!D12) | F42: =IF('W01 (15-21.09)'!B12="","",'W01 (15-21.09)'!E12) | G42: =IF('W01 (15-21.09)'!B12="","",IF(OR('W01 (15-21.09)'!F12="",'W01 (15-21.09)'!F12=0),"",'W01 (15-21.09)'!F12)) -> 46275 | H42: =IF('W01 (15-21.09)'!B12="","",'W01 (15-21.09)'!G12) -> Đã gặp | I42: =IF('W01 (15-21.09)'!B12="","",'W01 (15-21.09)'!H12) -> Đã chấp thuận | J42: =IF('W01 (15-21.09)'!B12="","",IF(OR('W01 (15-21.09)'!I12="",'W01 (15-21.09)'!I12=0),"",'W01 (15-21.09)'!I12)) | K42: =IF('W01 (15-21.09)'!B12="","",IF(OR('W01 (15-21.09)'!J12="",'W01 (15-21.09)'!J12=0),"",'W01 (15-21.09)'!J12)) -> 90 | L42: =IF('W01 (15-21.09)'!B12="","","Chi tiết ➔") -> Chi tiết ➔ | M42: =IF('W01 (15-21.09)'!B12="","",'W01 (15-21.09)'!K12) -> 40
A43: =IF(B43="","",COUNTA($B$41:B43)) -> 3 | B43: =IF('W01 (15-21.09)'!B13="","",'W01 (15-21.09)'!B13) -> Bệnh Viện Hoàn Mỹ Thủ Đức | C43: =IF('W01 (15-21.09)'!B13="","",'W01 (15-21.09)'!C13) -> Thủ Đức | D43: =IF('W01 (15-21.09)'!B13="","","W01") -> W01 | E43: =IF('W01 (15-21.09)'!B13="","",'W01 (15-21.09)'!D13) | F43: =IF('W01 (15-21.09)'!B13="","",'W01 (15-21.09)'!E13) | G43: =IF('W01 (15-21.09)'!B13="","",IF(OR('W01 (15-21.09)'!F13="",'W01 (15-21.09)'!F13=0),"",'W01 (15-21.09)'!F13)) -> 46281 | H43: =IF('W01 (15-21.09)'!B13="","",'W01 (15-21.09)'!G13) -> Đã gặp | I43: =IF('W01 (15-21.09)'!B13="","",'W01 (15-21.09)'!H13) -> Đã chấp thuận | J43: =IF('W01 (15-21.09)'!B13="","",IF(OR('W01 (15-21.09)'!I13="",'W01 (15-21.09)'!I13=0),"",'W01 (15-21.09)'!I13)) | K43: =IF('W01 (15-21.09)'!B13="","",IF(OR('W01 (15-21.09)'!J13="",'W01 (15-21.09)'!J13=0),"",'W01 (15-21.09)'!J13)) -> 90 | L43: =IF('W01 (15-21.09)'!B13="","","Chi tiết ➔") -> Chi tiết ➔ | M43: =IF('W01 (15-21.09)'!B13="","",'W01 (15-21.09)'!K13)
A44: =IF(B44="","",COUNTA($B$41:B44)) -> 4 | B44: =IF('W01 (15-21.09)'!B14="","",'W01 (15-21.09)'!B14) -> BV Hoàn Mỹ Bình Dương | C44: =IF('W01 (15-21.09)'!B14="","",'W01 (15-21.09)'!C14) -> Bình Dương | D44: =IF('W01 (15-21.09)'!B14="","","W01") -> W01 | E44: =IF('W01 (15-21.09)'!B14="","",'W01 (15-21.09)'!D14) | F44: =IF('W01 (15-21.09)'!B14="","",'W01 (15-21.09)'!E14) | G44: =IF('W01 (15-21.09)'!B14="","",IF(OR('W01 (15-21.09)'!F14="",'W01 (15-21.09)'!F14=0),"",'W01 (15-21.09)'!F14)) -> 46281 | H44: =IF('W01 (15-21.09)'!B14="","",'W01 (15-21.09)'!G14) -> Đã gặp | I44: =IF('W01 (15-21.09)'!B14="","",'W01 (15-21.09)'!H14) -> Đã chấp thuận | J44: =IF('W01 (15-21.09)'!B14="","",IF(OR('W01 (15-21.09)'!I14="",'W01 (15-21.09)'!I14=0),"",'W01 (15-21.09)'!I14)) | K44: =IF('W01 (15-21.09)'!B14="","",IF(OR('W01 (15-21.09)'!J14="",'W01 (15-21.09)'!J14=0),"",'W01 (15-21.09)'!J14)) -> 90 | L44: =IF('W01 (15-21.09)'!B14="","","Chi tiết ➔") -> Chi tiết ➔ | M44: =IF('W01 (15-21.09)'!B14="","",'W01 (15-21.09)'!K14)
...

Sheet _SETTINGS
A1: DANH MỤC BỆNH VIỆN | B1: TÌNH TRẠNG CUỘC HẸN | C1: TÌNH TRẠNG CHẤP THUẬN | D1: ĐƠN VỊ DIỄN GIẢ | E1: NỀN TẢNG ONLINE | F1: TRẠNG THÁI LỚP | G1: TRẠNG THÁI ACTION | H1: ĐƠN VỊ ACTION | I1: GIAI ĐOẠN THAI KỲ & ĐỘ TUỔI BÉ | J1: NỮ HỘ SINH CHUYÊN NGHIỆP (MIDWIFE) | K1: GÓI COMBO SẢN PHẨM DANONE | L1: KÊNH CHUYỂN ĐỔI
A2: Bệnh viện Âu Cơ | B2: Đã gặp | C2: Đã chấp thuận | D2: Danone - Aptamil | E2: Zoom Cloud Meetings | F2: Đã hoàn thành | G2: 🟢 Đã hoàn thành | H2: Danone - Aptamil | I2: 1. Mang thai 3 tháng đầu (Tuần 1 - 12) | J2: NHS. Nguyễn Thị Lan (TP.HCM - Q7, Nhà Bè) | K2: Combo Tân Sinh (2 lon 800g + Gối chống trào) | L2: Tại sự kiện Hội thảo BV
A3: Bệnh viện Xuyên Á | B3: Đang chờ | C3: Đang chờ phản hồi | D3: Zmoms | E3: Facebook Fanpage Live | F3: Đã lên lịch | G3: 🟡 Đang xử lý | H3: Zmoms | I3: 2. Mang thai 3 tháng giữa (Tuần 13 - 27) | J3: NHS. Trần Mai Hương (TP.HCM - Thủ Đức, Bình Thạnh) | K3: Combo Đề Kháng Vàng (3 lon 800g + Bình giữ nhiệt Elmich) | L3: Nữ hộ sinh tư vấn tại nhà
A4: Bệnh Viện Hoàn Mỹ Thủ Đức | B4: Dời lịch | C4: Từ chối | D4: Bệnh viện / Bác sĩ mời | E4: TikTok Live | F4: Hoãn / Dời lịch | G4: 🔴 Chậm tiến độ | H4: Cả 2 bên phối hợp | I4: 3. Mang thai 3 tháng cuối (Tuần 28 - 40) | J4: NHS. Lê Thu Trang (Bình Dương - Dĩ An, Thuận An) | K4: Combo Ăn Dặm Chuẩn (2 lon 800g + Bộ thìa bát ăn dặm) | L4: Lớp học Online / Webinar Zmoms
A5: BV Hoàn Mỹ Bình Dương | B5: Đã hủy | D5: Đối tác MBI | E5: Google Meet | F5: Đã hủy | G5: ⚪ Chưa thực hiện | H5: Đối tác Bệnh viện | I5: 4. Bé 0 - 6 tháng tuổi (Sơ sinh) | J5: NHS. Phạm Hồng Hạnh (Đồng Nai - Biên Hòa, Long Thành) | K5: Combo Khám Phá Toàn Diện (4 lon 800g + Xe chòi chân cao cấp) | L5: Tại cơ sở Spa đối tác
A6: Singmark Dong Nai | D6: Khác | E6: Khác | H6: Khác | I6: 5. Bé 6 - 12 tháng tuổi (Ăn dặm) | J6: NHS. Vũ Minh Anh (Cần Thơ - Ninh Kiều, Cái Răng) | K6: Combo Dinh Dưỡng Mẹ & Bé (Sữa bầu + Sữa bé sơ sinh) | L6: Kênh Tiêm chủng đối tác
A7: SIH | I7: 6. Bé 12 - 24 tháng tuổi (Tập đi) | J7: NHS. Đỗ Thị Hoàng Yến (Hà Nội - Đống Đa, Cầu Giấy) | L7: CSKH & Telesale Zmoms
A8: Hoàn My Ke Mei Kai | I8: 7. Bé > 24 tháng tuổi (Phát triển)
A9: Spa Thanh Lan
A10: NatuQueen Spa
A11: Bệnh viện Hoàn Mỹ Đà nẵng
A12: Bệnh viện Hồng Ngọc
A13: Phòng khám 43 Nguyễn Khang
A14: Bệnh viện Sản Nhi Quốc tế Hải Phòng
A15: Bệnh viện Tâm Phúc Hải Phòng
A16: Bệnh viện Việt Tiệp Hải Phòng
A17: Bệnh viện Quốc tế Green Hải Phòng
A18: BV ĐK Quốc tế Vạn Phúc
A19: BV Hoàn Mỹ Cửu Long
A20: Bệnh viện ĐH Y Dược Cần Thơ
... A27: Đối tác Y tế khác

Sheet DATA THAI KỲ & CONVERT
A1: DANH MỤC THEO DÕI DATA THAI KỲ, PHỄU CHUYỂN ĐỔI & ĐỘ TUỔI CỦA BÉ – CHIẾN DỊCH DANONE x ZMOMS
A2: HỆ THỐNG QUẢN LÝ DỮ LIỆU MẸ BẦU & SAU SINH • THEO DÕI CO-DATA (FOLLOW ZMOMS & APTACLUB) • ĐO LƯỜNG TỶ LỆ CHUYỂN ĐỔI NEW USER (NU COMBO)
A3: Tự động phân nhóm 7 giai đoạn thai kỳ & độ tuổi của bé • Đo lường tỷ lệ phát sinh đơn hàng thành công trên tổng số mẹ đăng ký • Đồng bộ số liệu thời gian thực
A4: ⬅ VỀ DASHBOARD TỔNG QUAN | E4: 👩‍⚕️ THEO DÕI HOẠT ĐỘNG NỮ HỘ SINH TƯ VẤN TẠI NHÀ | L4: 📊 BẢNG PHÂN TÍCH PHỄU CHUYỂN ĐỔI THAI KỲ (XEM BÊN DƯỚI) | Q4: 📋 CƠ SỞ DỮ LIỆU 100 MẸ CHI TIẾT (XEM DÒNG 25 TRỞ ĐI)
A5: 📋 TỔNG SỐ MẸ ĐĂNG KÝ | D5: 📱 MẸ FOLLOW ZMOMS | G5: 💙 MẸ ĐÔNG Ý CHIA SẺ TT APTACLUB | J5: ⭐ CO-DATA (CẢ 2 NỀN TẢNG) | M5: 🛒 MẸ PHÁT SINH ĐƠN (NU) | P5: 🎯 TỶ LỆ CHUYỂN ĐỔI ĐƠN HÀNG
A6: 1212 | D6: 1212 | G6: 1096 | J6: 1212 | M6: 320 | P6: =M6/J6 -> 0.2640264
A8: ="100% Data tiếp cận chiến dịch" -> 100% Data tiếp cận chiến dịch | D8: ="Tỷ lệ: " & TEXT(COUNTIF(M26:M125, "Có")/COUNTA(B26:B125), "0.0%") -> #DIV/0! | G8: ="Tỷ lệ: " & TEXT(COUNTIF(N26:N125, "Có")/COUNTA(B26:B125), "0.0%") -> #DIV/0! | J8: ="Tỷ lệ: " & TEXT(COUNTIF(O26:O125, "Đạt Co-data")/COUNTA(B26:B125), "0.0%") -> #DIV/0! | M8: ="Định nghĩa: Người mua Combo" -> Định nghĩa: Người mua Combo | P8: ="CR trên Co-data: " & TEXT(COUNTIF(P26:P125, "Có")/COUNTIF(O26:O125, "Đạt Co-data"), "0.0%") -> #DIV/0!
A10: 📊 PHẦN 1: BẢNG TỔNG HỢP PHỄU CHUYỂN ĐỔI THEO GIAI ĐOẠN THAI KỲ VÀ ĐỘ TUỔI CỦA BÉ (COHORT ANALYSIS)
A11: * Thống kê 100% tự động bằng công thức Excel từ cơ sở dữ liệu mẹ bầu & sau sinh • Đo lường tỷ lệ phát sinh đơn hàng thành công (NU Combo)
A12: STT | B12: GIAI ĐOẠN THAI KỲ & ĐỘ TUỔI BÉ | C12: ĐỐI TƯỢNG | D12: SỐ MẸ TIẾP CẬN | E12: TỶ TRỌNG (%) | F12: FOLLOW ZMOMS | G12: % FOLLOW ZMOMS | H12: FOLLOW APTACLUB | I12: % FOLLOW APTA | J12: ĐẠT CO-DATA | K12: % CO-DATA | L12: MẸ MUA COMBO (NU) | M12: TỶ LỆ ĐƠN / ĐĂNG KÝ | N12: TỶ LỆ ĐƠN / CO-DATA | O12: COMBO SẢN PHẨM KHUYẾN NGHỊ DANONE APTAMIL | R12: HÀNH ĐỘNG TIẾP CẬN & CHĂM SÓC KHUYẾN NGHỊ CỦA CHIẾN DỊCH
A13: 1 | B13: 1. Mang thai 3 tháng đầu (Tuần 1 - 12) | C13: Mẹ Bầu | D13: 0 | E13: =IF($D$20>0, D13/$D$20, 0) -> 0 | F13: 0 | G13: =IF(D13>0, F13/D13, 0) -> 0 | H13: 0 | I13: =IF(D13>0, H13/D13, 0) -> 0 | J13: 0 | K13: =IF(D13>0, J13/D13, 0) -> 0 | L13: 0 | M13: =IF(D13>0, L13/D13, 0) -> 0 | N13: =IF(J13>0, L13/J13, 0) -> 0 | R13: Mời tham gia Webinar thai kỳ, tặng cẩm nang giảm ốm nghén và tư vấn vi chất.
A14: 2 | B14: 2. Mang thai 3 tháng giữa (Tuần 13 - 27) | C14: Mẹ Bầu | D14: =COUNTIF(L$26:L$125, "2. Mang thai 3 tháng giữa (Tuần 13 - 27)") -> 0 | E14: =IF($D$20>0, D14/$D$20, 0) -> 0 | F14: =COUNTIFS(L$26:L$125, "2. Mang thai 3 tháng giữa (Tuần 13 - 27)", M$26:M$125, "Có") -> 0 | G14: =IF(D14>0, F14/D14, 0) -> 0 | H14: =COUNTIFS(L$26:L$125, "2. Mang thai 3 tháng giữa (Tuần 13 - 27)", N$26:N$125, "Có") -> 0 | I14: =IF(D14>0, H14/D14, 0) -> 0 | J14: =COUNTIFS(L$26:L$125, "2. Mang thai 3 tháng giữa (Tuần 13 - 27)", O$26:O$125, "Đạt Co-data") -> 0 | K14: =IF(D14>0, J14/D14, 0) -> 0 | L14: =COUNTIFS(L$26:L$125, "2. Mang thai 3 tháng giữa (Tuần 13 - 27)", P$26:P$125, "Có") -> 0 | M14: =IF(D14>0, L14/D14, 0) -> 0 | N14: =IF(J14>0, L14/J14, 0) -> 0 | R14: Kích hoạt tư vấn dinh dưỡng phát triển xương & giác quan, tương tác Zalo Zmoms.
A15: 3 | B15: 3. Mang thai 3 tháng cuối (Tuần 28 - 40) | C15: Mẹ Bầu | D15: =COUNTIF(L$26:L$125, "3. Mang thai 3 tháng cuối (Tuần 28 - 40)") -> 0 | E15: =IF($D$20>0, D15/$D$20, 0) -> 0 | F15: =COUNTIFS(L$26:L$125, "3. Mang thai 3 tháng cuối (Tuần 28 - 40)", M$26:M$125, "Có") -> 0 | G15: =IF(D15>0, F15/D15, 0) -> 0 | H15: =COUNTIFS(L$26:L$125, "3. Mang thai 3 tháng cuối (Tuần 28 - 40)", N$26:N$125, "Có") -> 0 | I15: =IF(D15>0, H15/D15, 0) -> 0 | J15: =COUNTIFS(L$26:L$125, "3. Mang thai 3 tháng cuối (Tuần 28 - 40)", O$26:O$125, "Đạt Co-data") -> 0 | K15: =IF(D15>0, J15/D15, 0) -> 0 | L15: =COUNTIFS(L$26:L$125, "3. Mang thai 3 tháng cuối (Tuần 28 - 40)", P$26:P$125, "Có") -> 0 | M15: =IF(D15>0, L15/D15, 0) -> 0 | N15: =IF(J15>0, L15/J15, 0) -> 0 | R15: Target trọng điểm chốt đơn trước sinh; đặt lịch Nữ hộ sinh đến nhà tư vấn chuẩn bị sinh.
A16: 4 | B16: 4. Bé 0 - 6 tháng tuổi (Sơ sinh) | C16: Mẹ Sau Sinh | D16: =COUNTIF(L$26:L$125, "4. Bé 0 - 6 tháng tuổi (Sơ sinh)") -> 0 | E16: =IF($D$20>0, D16/$D$20, 0) -> 0 | F16: =COUNTIFS(L$26:L$125, "4. Bé 0 - 6 tháng tuổi (Sơ sinh)", M$26:M$125, "Có") -> 0 | G16: =IF(D16>0, F16/D16, 0) -> 0 | H16: =COUNTIFS(L$26:L$125, "4. Bé 0 - 6 tháng tuổi (Sơ sinh)", N$26:N$125, "Có") -> 0 | I16: =IF(D16>0, H16/D16, 0) -> 0 | J16: =COUNTIFS(L$26:L$125, "4. Bé 0 - 6 tháng tuổi (Sơ sinh)", O$26:O$125, "Đạt Co-data") -> 0 | K16: =IF(D16>0, J16/D16, 0) -> 0 | L16: =COUNTIFS(L$26:L$125, "4. Bé 0 - 6 tháng tuổi (Sơ sinh)", P$26:P$125, "Có") -> 0 | M16: =IF(D16>0, L16/D16, 0) -> 0 | N16: =IF(J16>0, L16/J16, 0) -> 0 | R16: Midwife đến nhà hỗ trợ kích sữa, tắm bé, tư vấn giải pháp Aptamil Step 1 khi thiếu sữa.
A17: 5 | B17: 5. Bé 6 - 12 tháng tuổi (Ăn dặm) | C17: Mẹ Sau Sinh | D17: =COUNTIF(L$26:L$125, "5. Bé 6 - 12 tháng tuổi (Ăn dặm)") -> 0 | E17: =IF($D$20>0, D17/$D$20, 0) -> 0 | F17: =COUNTIFS(L$26:L$125, "5. Bé 6 - 12 tháng tuổi (Ăn dặm)", M$26:M$125, "Có") -> 0 | G17: =IF(D17>0, F17/D17, 0) -> 0 | H17: =COUNTIFS(L$26:L$125, "5. Bé 6 - 12 tháng tuổi (Ăn dặm)", N$26:N$125, "Có") -> 0 | I17: =IF(D17>0, H17/D17, 0) -> 0 | J17: =COUNTIFS(L$26:L$125, "5. Bé 6 - 12 tháng tuổi (Ăn dặm)", O$26:O$125, "Đạt Co-data") -> 0 | K17: =IF(D17>0, J17/D17, 0) -> 0 | L17: =COUNTIFS(L$26:L$125, "5. Bé 6 - 12 tháng tuổi (Ăn dặm)", P$26:P$125, "Có") -> 0 | M17: =IF(D17>0, L17/D17, 0) -> 0 | N17: =IF(J17>0, L17/J17, 0) -> 0 | R17: Tư vấn thực đơn ăn dặm, bổ sung hệ dưỡng chất Synbiotic bảo vệ tiêu hóa bé.
A18: 6 | B18: 6. Bé 12 - 24 tháng tuổi (Tập đi) | C18: Mẹ Sau Sinh | D18: =COUNTIF(L$26:L$125, "6. Bé 12 - 24 tháng tuổi (Tập đi)") -> 0 | E18: =IF($D$20>0, D18/$D$20, 0) -> 0 | F18: =COUNTIFS(L$26:L$125, "6. Bé 12 - 24 tháng tuổi (Tập đi)", M$26:M$125, "Có") -> 0 | G18: =IF(D18>0, F18/D18, 0) -> 0 | H18: =COUNTIFS(L$26:L$125, "6. Bé 12 - 24 tháng tuổi (Tập đi)", N$26:N$125, "Có") -> 0 | I18: =IF(D18>0, H18/D18, 0) -> 0 | J18: =COUNTIFS(L$26:L$125, "6. Bé 12 - 24 tháng tuổi (Tập đi)", O$26:O$125, "Đạt Co-data") -> 0 | K18: =IF(D18>0, J18/D18, 0) -> 0 | L18: =COUNTIFS(L$26:L$125, "6. Bé 12 - 24 tháng tuổi (Tập đi)", P$26:P$125, "Có") -> 0 | M18: =IF(D18>0, L18/D18, 0) -> 0 | N18: =IF(J18>0, L18/J18, 0) -> 0 | R18: Chương trình tích điểm đổi quà Aptaclub, nhắc lịch tiêm chủng và bổ sung dinh dưỡng.
A19: 7 | B19: 7. Bé > 24 tháng tuổi (Phát triển) | C19: Mẹ Sau Sinh | D19: =COUNTIF(L$26:L$125, "7. Bé > 24 tháng tuổi (Phát triển)") -> 0 | E19: =IF($D$20>0, D19/$D$20, 0) -> 0 | F19: =COUNTIFS(L$26:L$125, "7. Bé > 24 tháng tuổi (Phát triển)", M$26:M$125, "Có") -> 0 | G19: =IF(D19>0, F19/D19, 0) -> 0 | H19: =COUNTIFS(L$26:L$125, "7. Bé > 24 tháng tuổi (Phát triển)", N$26:N$125, "Có") -> 0 | I19: =IF(D19>0, H19/D19, 0) -> 0 | J19: =COUNTIFS(L$26:L$125, "7. Bé > 24 tháng tuổi (Phát triển)", O$26:O$125, "Đạt Co-data") -> 0 | K19: =IF(D19>0, J19/D19, 0) -> 0 | L19: =COUNTIFS(L$26:L$125, "7. Bé > 24 tháng tuổi (Phát triển)", P$26:P$125, "Có") -> 0 | M19: =IF(D19>0, L19/D19, 0) -> 0 | N19: =IF(J19>0, L19/J19, 0) -> 0 | R19: Duy trì gắn kết tệp khách hàng trung thành, giới thiệu dòng sản phẩm mở rộng của Danone.
A20: TỔNG | B20: TỔNG CỘNG 7 GIAI ĐOẠN | C20: TOÀN CHIẾN DỊCH | D20: =SUM(D13:D19) -> 0 | E20: =IF(D20>0, 1, 0) -> 0 | F20: =SUM(F13:F19) -> 0 | G20: =IF(D20>0, F20/D20, 0) -> 0 | H20: =SUM(H13:H19) -> 0 | I20: =IF(D20>0, H20/D20, 0) -> 0 | J20: =SUM(J13:J19) -> 0 | K20: =IF(D20>0, J20/D20, 0) -> 0 | L20: =SUM(L13:L19) -> 0 | M20: =IF(D20>0, L20/D20, 0) -> 0 | N20: =IF(J20>0, L20/J20, 0) -> 0 | O20: DANH MỤC TRỌNG ĐIỂM APTAMIL | R20: HÀNH ĐỘNG TỔNG HỢP: TỐI ƯU HÓA PHỄU CHUYỂN ĐỔI TOÀN DIỆN
A22: 📋 PHẦN 2: CƠ SỞ DỮ LIỆU CHI TIẾT DANH SÁCH MẸ BẦU & SAU SINH (INDIVIDUAL PROSPECT & CUSTOMER DATABASE)
A23: * Dữ liệu mẫu chuẩn 100 Khách hàng thực tế qua các kênh Bệnh viện, Nữ hộ sinh tại nhà, Spa, Tiêm chủng & Webinar • Tự động tính Giai đoạn & NU
A25: STT | B25: MÃ KH | C25: HỌ VÀ TÊN MẸ | D25: SỐ ĐIỆN THOẠI | E25: KHU VỰC / TỈNH THÀNH | F25: NGUỒN DATA / KÊNH TIẾP CẬN | G25: TUẦN TIẾP CẬN | H25: TÌNH TRẠNG | I25: NGÀY DỰ SINH / SINH BÉ | J25: TUẦN THAI | K25: THÁNG TUỔI | L25: GIAI ĐOẠN THAI KỲ & ĐỘ TUỔI BÉ (TỰ ĐỘNG) | M25: FOLLOW ZMOMS | N25: FOLLOW APTACLUB | O25: TRẠNG THÁI CO-DATA | P25: ĐƠN HÀNG THÀNH CÔNG | Q25: GÓI COMBO SẢN PHẨM ĐÃ MUA | R25: ĐỊNH DANH NEW USER (NU) | S25: KÊNH CHUYỂN ĐỔI | T25: MIDWIFE / PIC PHỤ TRÁCH | U25: GHI CHÚ CHUYÊN MÔN
M26: Có | N26: Có | O26: TRUE
M27: Có | N27: Có | O27: TRUE
M28: Có | N28: Có | O28: TRUE
M29: Có | N29: Có | O29: TRUE
M30: Có | N30: Có | O30: TRUE
M31: Có | N31: Có | O31: TRUE
M32: Có | N32: Có | O32: TRUE
M33: Có | N33: Có | O33: TRUE
M34: Có | N34: Có | O34: TRUE
M35: Có | N35: Có | O35: TRUE
M36: Có | N36: Có | O36: TRUE
M37: Có | N37: Có | O37: FALSE
... M298: Có | N298: Có | O298: TRUE

Sheet THEO DÕI MIDWIFE TẠI NHÀ
A1: THEO DÕI HOẠT ĐỘNG ĐỘI NGŨ NỮ HỘ SINH CHUYÊN NGHIỆP (MIDWIFE PROFESSIONALS TƯ VẤN TẠI NHÀ)
A2: DỰ ÁN HỢP TÁC DANONE x ZMOMS • TƯ VẤN 1-ON-1 TẬN NHÀ MẸ BẦU & SAU SINH • ĐO LƯỜNG TỶ LỆ CHUYỂN ĐỔI VÀ TỶ LỆ NEW USER (NU COMBO)
A3: Đồng bộ năng suất từng Nữ hộ sinh theo địa bàn phụ trách • Đánh giá tỷ lệ chuyển đổi từ tư vấn chuyên môn và tỷ lệ chốt New User mua combo dinh dưỡng
A4: ⬅ VỀ DASHBOARD TỔNG QUAN | D4: 🤰 XEM TAB DỮ LIỆU THAI KỲ & COHORT | H4: 📊 BẢNG TỔNG HỢP HIỆU SUẤT NỮ HỘ SINH (BÊN DƯỚI) | K4: 📝 NHẬT KÝ CHI TIẾT TỪNG CA TƯ VẤN TẠI NHÀ (DÒNG 24 TRỞ ĐI)
A5: 👩‍⚕️ NỮ HỘ SINH HOẠT ĐỘNG | C5: 🏠 CA TƯ VẤN HOÀN THÀNH | F5: ⚡ TỶ LỆ CHUYỂN ĐỔI TỪ NHS | I5: 🛒 NEW USERS TỪ NHS (NU COMBO) | L5: 🎯 TỶ LỆ NU CỦA NỮ HỘ SINH
F6: =IF(SUM(G13:G18)>0, SUM(H13:H18)/SUM(G13:G18), 0) -> 0 | I6: =SUM(J13:J18) -> 0 | L6: =IF(SUM(G13:G18)>0, SUM(J13:J18)/SUM(G13:G18), 0) -> 0
A8: ="Đội ngũ nòng cốt chuyên môn" -> Đội ngũ nòng cốt chuyên môn | C8: ="Đạt: " & TEXT(SUM(G13:G18)/SUM(F13:F18), "0.0%") & " trên lịch hẹn" -> #DIV/0! | F8: ="Số mẹ quan tâm giải pháp / Tổng ca" -> Số mẹ quan tâm giải pháp / Tổng ca | I8: ="Định nghĩa: Người mua combo Danone" -> Định nghĩa: Người mua combo Danone | L8: ="Tỷ lệ NU combo / Số ca tư vấn" -> Tỷ lệ NU combo / Số ca tư vấn
A10: 📊 PHẦN 1: BẢNG TỔNG HỢP HIỆU SUẤT ĐỘI NGŨ NỮ HỘ SINH CHUYÊN NGHIỆP
A11: * Đánh giá trực tiếp hiệu quả tư vấn tại nhà của từng Nữ hộ sinh • Tỷ lệ chuyển đổi mẹ quan tâm & Tỷ lệ chốt New User mua Combo (NU)
A12: STT | B12: MÃ NHS | C12: HỌ VÀ TÊN NỮ HỘ SINH | D12: TRÌNH ĐỘ CHUYÊN MÔN | E12: KHU VỰC PHỤ TRÁCH | F12: LỊCH ĐẶT HẸN | G12: CA HOÀN THÀNH | H12: MẸ CHUYỂN ĐỔI | I12: TỶ LỆ CHUYỂN ĐỔI (%) | J12: NU COMBO CHỐT | K12: TỶ LỆ NU (%) | L12: DOANH SỐ COMBO (VNĐ) | M12: ĐÁNH GIÁ | N12: GHI CHÚ CHUYÊN MÔN & ĐÁNH GIÁ
A13: 1
A14: 2
A15: 3
A16: 4
A17: 5
A18: 6
A19: TỔNG | B19: TOÀN ĐỘI NGŨ | C19: 6 NỮ HỘ SINH | D19: CHUYÊN NGHIỆP | E19: TOÀN CHIẾN DỊCH | F19: =SUM(F13:F18) -> 0 | G19: =SUM(G13:G18) -> 0 | H19: =SUM(H13:H18) -> 0 | I19: =IF(G19>0, H19/G19, 0) -> 0 | J19: =SUM(J13:J18) -> 0 | K19: =IF(G19>0, J19/G19, 0) -> 0 | L19: =SUM(L13:L18) -> 0 | M19: =AVERAGE(M13:M18) -> #DIV/0! | N19: HIỆU SUẤT CHUYỂN ĐỔI XUẤT SẮC – KÊNH TRỌNG TÂM CỦA DANONE
A21: 📝 PHẦN 2: NHẬT KÝ CHI TIẾT TỪNG CA TƯ VẤN TẠI NHÀ CỦA NỮ HỘ SINH
A22: * Ghi nhận kết quả tư vấn thực tế tại nhà mẹ • Theo dõi tỷ lệ chuyển đổi giải pháp dinh dưỡng và tình trạng mua Combo New User
A23: STT | B23: MÃ CA TƯ VẤN | C23: TUẦN | D23: NGÀY TƯ VẤN | E23: MÃ KHÁCH HÀNG | F23: HỌ VÀ TÊN MẸ | G23: ĐỊA CHỈ NHÀ MẸ / KHU VỰC | H23: GIAI ĐOẠN / TUỔI BÉ | I23: NỮ HỘ SINH PHỤ TRÁCH | J23: NỘI DUNG TƯ VẤN CHUYÊN MÔN | K23: KẾT QUẢ TƯ VẤN | L23: MUA COMBO (NU)? | M23: GÓI COMBO ĐÃ MUA | N23: ĐÁNH GIÁ CSAT
A24: 1 | B24: VISIT-001
A25: 2 | B25: VISIT-002
A26: 3 | B26: VISIT-003
A27: 4 | B27: VISIT-004
A28: 5 | B28: VISIT-005
A29: 6 | B29: VISIT-006
A30: 7 | B30: VISIT-007
A31: 8 | B31: VISIT-008
A32: 9 | B32: VISIT-009
A33: 10 | B33: VISIT-010

Sheet W01 (15-21.09)
A1: BÁO CÁO CHI TIẾT VẬN HÀNH – TUẦN 01 (15/09 - 21/09) | P1: ⬅ VỀ DASHBOARD TỔNG QUAN
A2: Dự án Hợp tác Danone x Zmoms • Phân bổ chỉ tiêu tuần: 626 Data xác thực | 157 New Users (NU Combo)
B4: 🎯 CHỈ TIÊU & TIẾN ĐỘ LEAD CO-DATA TUẦN | F4: 🛒 CHỈ TIÊU & CHUYỂN ĐỔI NU COMBO TUẦN | J4: ⚡ TỶ LỆ CHUYỂN ĐỔI (CR) | M4: 💰 DOANH SỐ COMBO TẠM TÍNH | P4: 📊 ĐÁNH GIÁ VẬN HÀNH TUẦN
B5: Target: | C5: 626 | D5: 85 | E5: =IF(C5>0, D5/C5, 0) -> 0.13578275 | F5: 157 | G5: 44 | H5: Tỷ lệ đạt: | I5: =IF(F5>0, G5/F5, 0) -> 0.28025478 | J5: =IF(D5>0, G5/D5, 0) -> 0.51764706 | M5: =G5*1300000 -> 57200000 | P5: =IF(D5>=C5, "🟢 Hoàn thành kế hoạch", IF(D5>0, "🟡 Đang bám sát tiến độ", "⚪ Đang cập nhật dữ liệu")) -> 🟡 Đang bám sát tiến độ
A9: 🏥 PHẦN 1: QUẢN LÝ LỊCH HẸN, TIẾN ĐỘ ĐỐI TÁC BỆNH VIỆN & CHUYỂN ĐỔI CO-DATA / NU TRONG TUẦN
A10: STT | B10: TÊN BỆNH VIỆN / CƠ SỞ Y TẾ | C10: TỈNH / TP | D10: NGƯỜI LIÊN HỆ BV | E10: PIC PHỤ TRÁCH | F10: NGÀY GIỜ HẸN LÀM VIỆC | G10: TÌNH TRẠNG CUỘC HẸN | H10: CHẤP THUẬN TỔ CHỨC SK | I10: NGÀY SỰ KIỆN | J10: QUY MÔ TIẾP CẬN | K10: TARGET CO-DATA | L10: ACTUAL CO-DATA | M10: % ĐẠT CO-DATA | N10: TARGET NU (COMBO) | O10: ACTUAL NU (COMBO) | P10: % ĐẠT NU | Q10: TỶ LỆ CR (% NU/LEAD) | R10: GHI CHÚ / HÀNH ĐỘNG TIẾP THEO
A11: 1 | B11: Bệnh viện Âu Cơ | C11: Đồng Nai | F11: 46275 | G11: Đã gặp | H11: Đã chấp thuận | I11: 46291 | J11: 90 | K11: 50 | M11: =IF(K11="","",IF(K11>0,L11/K11,0)) -> 0 | P11: =IF(N11="","",IF(N11>0,O11/N11,0)) | Q11: =IF(L11="","",IF(L11>0,O11/L11,0))
A12: 2 | B12: Bệnh viện Xuyên Á | C12: Củ Chi | F12: 46275 | G12: Đã gặp | H12: Đã chấp thuận | J12: 90 | K12: 40 | M12: =IF(K12="","",IF(K12>0,L12/K12,0)) -> 0 | P12: =IF(N12="","",IF(N12>0,O12/N12,0)) | Q12: =IF(L12="","",IF(L12>0,O12/L12,0))
A13: 3 | B13: Bệnh Viện Hoàn Mỹ Thủ Đức | C13: Thủ Đức | F13: 46281 | G13: Đã gặp | H13: Đã chấp thuận | J13: 90 | M13: =IF(K13="","",IF(K13>0,L13/K13,0)) | P13: =IF(N13="","",IF(N13>0,O13/N13,0)) | Q13: =IF(L13="","",IF(L13>0,O13/L13,0))
A14: 4 | B14: BV Hoàn Mỹ Bình Dương | C14: Bình Dương | F14: 46281 | G14: Đã gặp | H14: Đã chấp thuận | J14: 90 | M14: =IF(K14="","",IF(K14>0,L14/K14,0)) | P14: =IF(N14="","",IF(N14>0,O14/N14,0)) | Q14: =IF(L14="","",IF(L14>0,O14/L14,0))
A15: 5 | B15: Singmark Dong Nai | C15: Dong Nai | F15: 46281 | G15: Đã gặp | H15: Đã chấp thuận | I15: 46291 | J15: 90 | K15: 30 | M15: =IF(K15="","",IF(K15>0,L15/K15,0)) -> 0 | P15: =IF(N15="","",IF(N15>0,O15/N15,0)) | Q15: =IF(L15="","",IF(L15>0,O15/L15,0))
A16: 6 | B16: Hoàn My Ke Mei Kai | C16: Binh Duong | F16: 46280 | G16: Đã gặp | H16: Đã chấp thuận | I16: 46292 | J16: 90 | K16: 20 | M16: =IF(K16="","",IF(K16>0,L16/K16,0)) -> 0 | P16: =IF(N16="","",IF(N16>0,O16/N16,0)) | Q16: =IF(L16="","",IF(L16>0,O16/L16,0))
A17: 7 | B17: Becamex Bình Duong | C17: Bình Dương | F17: 46287 | G17: Đã gặp | H17: Đã chấp thuận | J17: 90 | M17: =IF(K17="","",IF(K17>0,L17/K17,0)) | P17: =IF(N17="","",IF(N17>0,O17/N17,0)) | Q17: =IF(L17="","",IF(L17>0,O17/L17,0)) | R17: Chờ lịch tháng 10
A18: 8 | B18: Bệnh viện Hạnh Phúc | C18: Bình Dương | F18: 46280 | G18: Đã gặp | H18: Đã chấp thuận | J18: 90 | M18: =IF(K18="","",IF(K18>0,L18/K18,0)) | P18: =IF(N18="","",IF(N18>0,O18/N18,0)) | Q18: =IF(L18="","",IF(L18>0,O18/L18,0)) | R18: Chờ lịch tháng 10
A19: 9 | B19: Bệnh Viện Y Học Hồng Bàng | C19: HCMC | F19: 46287 | G19: Đã gặp | H19: Đã chấp thuận | J19: 90 | M19: =IF(K19="","",IF(K19>0,L19/K19,0)) | P19: =IF(N19="","",IF(N19>0,O19/N19,0)) | Q19: =IF(L19="","",IF(L19>0,O19/L19,0)) | R19: Chờ lịch tháng 10
A20: 10 | B20: Bệnh viện Sun Phú Quốc | C20: Hà Nội | F20: 46283 | G20: Đã gặp | H20: Đã chấp thuận | J20: 90 | M20: =IF(K20="","",IF(K20>0,L20/K20,0)) | P20: =IF(N20="","",IF(N20>0,O20/N20,0)) | Q20: =IF(L20="","",IF(L20>0,O20/L20,0)) | R20: Chờ lịch tháng 10
A21: 11 | B21: Bệnh viện Columbia | C21: Hà Nội | F21: 46283 | G21: Đã gặp | H21: Đã chấp thuận | I21: 46291 | J21: 90 | M21: =IF(K21="","",IF(K21>0,L21/K21,0)) | P21: =IF(N21="","",IF(N21>0,O21/N21,0)) | Q21: =IF(L21="","",IF(L21>0,O21/L21,0)) | R21: Chờ lịch tháng 10
A22: 12 | B22: Bệnh viện ĐH Y Dược Cần Thơ | C22: Cần Thơ | F22: 46288 | G22: Đã gặp | H22: Đang chờ phản hồi | J22: 90 | M22: =IF(K22="","",IF(K22>0,L22/K22,0)) | P22: =IF(N22="","",IF(N22>0,O22/N22,0)) | Q22: =IF(L22="","",IF(L22>0,O22/L22,0)) | R22: Đang chờ phản hồi BV
A23: 13 | B23: Bệnh viện Sản Nhi Long An | C23: Hà Nội | F23: 46288 | G23: Đã gặp | H23: Đang chờ phản hồi | I23: 46292 | J23: 90 | M23: =IF(K23="","",IF(K23>0,L23/K23,0)) | P23: =IF(N23="","",IF(N23>0,O23/N23,0)) | Q23: =IF(L23="","",IF(L23>0,O23/L23,0)) | R23: Đang chờ phản hồi BV
A24: TỔNG CỘNG SỰ KIỆN BV / ĐỐI TÁC W01: | J24: =SUM(J11:J23) -> 1170 | K24: =SUM(K11:K23) -> 140 | L24: =SUM(L11:L23) -> 0 | M24: =IF(K24>0, L24/K24, 0) -> 0 | N24: =SUM(N11:N23) -> 0 | O24: =SUM(O11:O23) -> 0 | P24: =IF(N24>0, O24/N24, 0) -> 0 | Q24: =IF(L24>0, O24/L24, 0) -> 0 | R24: Hoàn thành vượt chỉ tiêu tuần
A26: 💻 PHẦN 2: LỊCH TRÌNH LỚP HỌC ONLINE / WEBINAR THAI KỲ TRONG TUẦN
A27: STT | B27: NGÀY & KHUNG GIỜ | C27: CHUYÊN ĐỀ ĐÀO TẠO THAI KỲ | D27: NỀN TẢNG | E27: DIỄN GIẢ / PIC | F27: ĐƠN VỊ CÔNG TÁC | G27: MẸ ĐĂNG KÝ | H27: MẸ THAM DỰ THỰC TẾ | I27: TÌNH TRẠNG BUỔI HỌC | J27: LINK RECORD / PHÒNG | K27: GHI CHÚ / ĐÁNH GIÁ CHẤT LƯỢNG & THEO DÕI SAU LỚP HỌC
A28: 1
A29: 2
A30: 3
A31: 4
A32: 5
A33: 6
A34: 7
A35: 8
A36: TỔNG SỐ LƯỢNG MẸ THAM GIA LỚP ONLINE TRONG TUẦN: | G36: =SUM(G28:G35) -> 0 | H36: =SUM(H28:H35) -> 0 | I36: Lượt mẹ tham gia thực tế trên hệ thống
A38: 📝 PHẦN 3: NHẬT KÝ VẬN HÀNH & HÀNH ĐỘNG CẦN DANONE / ZMOMS PHỐI HỢP XỬ LÝ
A39: STT | B39: NỘI DUNG VƯỚNG MẮC / ĐỀ XUẤT | D39: ĐƠN VỊ | E39: PIC | F39: HẠN CHÓT | G39: TRẠNG THÁI | H39: KẾT QUẢ / GHI CHÚ TIẾN ĐỘ & HÀNH ĐỘNG TIẾP THEO
A40: 1
A41: 2
A42: 3
A43: 4

Sheet W02 (22-28.09)
A1: BÁO CÁO CHI TIẾT VẬN HÀNH – TUẦN 02 (22/09 - 28/09) | P1: ⬅ VỀ DASHBOARD TỔNG QUAN
A2: Dự án Hợp tác Danone x Zmoms • Phân bổ chỉ tiêu tuần: 626 Data xác thực | 157 New Users (NU Combo)
B4: 🎯 CHỈ TIÊU & TIẾN ĐỘ LEAD CO-DATA TUẦN | F4: 🛒 CHỈ TIÊU & CHUYỂN ĐỔI NU COMBO TUẦN | J4: ⚡ TỶ LỆ CHUYỂN ĐỔI (CR) | M4: 💰 DOANH SỐ COMBO TẠM TÍNH | P4: 📊 ĐÁNH GIÁ VẬN HÀNH TUẦN
B5: Target: | C5: 626 | D5: 244 | E5: =IF(C5>0, D5/C5, 0) -> 0.38977636 | F5: 216 | G5: 110 | H5: Tỷ lệ đạt: | I5: =IF(F5>0, G5/F5, 0) -> 0.50925926 | J5: =IF(D5>0, G5/D5, 0) -> 0.45081967 | M5: =G5*1300000 -> 143000000 | P5: =IF(D5>=C5, "🟢 Hoàn thành kế hoạch", IF(D5>0, "🟡 Đang bám sát tiến độ", "⚪ Đang cập nhật dữ liệu")) -> 🟡 Đang bám sát tiến độ
A9: 🏥 PHẦN 1: QUẢN LÝ LỊCH HẸN, TIẾN ĐỘ ĐỐI TÁC BỆNH VIỆN & CHUYỂN ĐỔI CO-DATA / NU TRONG TUẦN
A10: STT | B10: TÊN BỆNH VIỆN / CƠ SỞ Y TẾ | C10: TỈNH / TP | D10: NGƯỜI LIÊN HỆ BV | E10: PIC PHỤ TRÁCH | F10: NGÀY GIỜ HẸN LÀM VIỆC | G10: TÌNH TRẠNG CUỘC HẸN | H10: CHẤP THUẬN TỔ CHỨC SK | I10: NGÀY SỰ KIỆN | J10: QUY MÔ TIẾP CẬN | K10: TARGET CO-DATA | L10: ACTUAL CO-DATA | M10: % ĐẠT CO-DATA | N10: TARGET NU (COMBO) | O10: ACTUAL NU (COMBO) | P10: % ĐẠT NU | Q10: TỶ LỆ CR (% NU/LEAD) | R10: GHI CHÚ / HÀNH ĐỘNG TIẾP THEO
A11: 1 | B11: Bệnh viện Âu Cơ (Lớp tư vấn VIP) | C11: Đồng Nai | G11: Đã gặp | H11: Đã chấp thuận | J11: 90 | K11: 90 | M11: =IF(K11="","",IF(K11>0,L11/K11,0)) -> 0 | P11: =IF(N11="","",IF(N11>0,O11/N11,0)) | Q11: =IF(L11="","",IF(L11>0,O11/L11,0))
A12: 2
A13: 3 | M13: =IF(K13="","",IF(K13>0,L13/K13,0)) | P13: =IF(N13="","",IF(N13>0,O13/N13,0)) | Q13: =IF(L13="","",IF(L13>0,O13/L13,0))
A14: 4 | M14: =IF(K14="","",IF(K14>0,L14/K14,0)) | P14: =IF(N14="","",IF(N14>0,O14/N14,0)) | Q14: =IF(L14="","",IF(L14>0,O14/L14,0))
A15: 5 | M15: =IF(K15="","",IF(K15>0,L15/K15,0)) | P15: =IF(N15="","",IF(N15>0,O15/N15,0)) | Q15: =IF(L15="","",IF(L15>0,O15/L15,0))
A16: 6 | M16: =IF(K16="","",IF(K16>0,L16/K16,0)) | P16: =IF(N16="","",IF(N16>0,O16/N16,0)) | Q16: =IF(L16="","",IF(L16>0,O16/L16,0))
A17: 7 | M17: =IF(K17="","",IF(K17>0,L17/K17,0)) | P17: =IF(N17="","",IF(N17>0,O17/N17,0)) | Q17: =IF(L17="","",IF(L17>0,O17/L17,0))
A18: 8 | M18: =IF(K18="","",IF(K18>0,L18/K18,0)) | P18: =IF(N18="","",IF(N18>0,O18/N18,0)) | Q18: =IF(L18="","",IF(L18>0,O18/L18,0))
A19: 9 | M19: =IF(K19="","",IF(K19>0,L19/K19,0)) | P19: =IF(N19="","",IF(N19>0,O19/N19,0)) | Q19: =IF(L19="","",IF(L19>0,O19/L19,0))
A20: 10 | M20: =IF(K20="","",IF(K20>0,L20/K20,0)) | P20: =IF(N20="","",IF(N20>0,O20/N20,0)) | Q20: =IF(L20="","",IF(L20>0,O20/L20,0))
A21: 11 | M21: =IF(K21="","",IF(K21>0,L21/K21,0)) | P21: =IF(N21="","",IF(N21>0,O21/N21,0)) | Q21: =IF(L21="","",IF(L21>0,O21/L21,0))
A22: 12 | M22: =IF(K22="","",IF(K22>0,L22/K22,0)) | P22: =IF(N22="","",IF(N22>0,O22/N22,0)) | Q22: =IF(L22="","",IF(L22>0,O22/L22,0))
A23: 13 | M23: =IF(K23="","",IF(K23>0,L23/K23,0)) | P23: =IF(N23="","",IF(N23>0,O23/N23,0)) | Q23: =IF(L23="","",IF(L23>0,O23/L23,0))
A24: 14 | M24: =IF(K24="","",IF(K24>0,L24/K24,0)) | P24: =IF(N24="","",IF(N24>0,O24/N24,0)) | Q24: =IF(L24="","",IF(L24>0,O24/L24,0))
... A27: 17 | M27: =IF(K27="","",IF(K27>0,L27/K27,0)) | P27: =IF(N27="","",IF(N27>0,O27/N27,0)) | Q27: =IF(L27="","",IF(L27>0,O27/L27,0))
A29: TỔNG CỘNG SỰ KIỆN BV / ĐỐI TÁC W02: | J29: =SUM(J11:J27) -> 90 | K29: =SUM(K11:K27) -> 90 | L29: =SUM(L11:L27) -> 0 | M29: =IF(K29>0, L29/K29, 0) -> 0 | N29: =SUM(N11:N27) -> 0 | O29: =SUM(O11:O27) -> 0 | P29: =IF(N29>0, O29/N29, 0) -> 0 | Q29: =IF(L29>0, O29/L29, 0) -> 0 | R29: Tiếp tục đẩy mạnh các sự kiện Spa & BV
A31: 💻 PHẦN 2: LỊCH TRÌNH LỚP HỌC ONLINE / WEBINAR THAI KỲ TRONG TUẦN
A32: STT | B32: NGÀY & KHUNG GIỜ | C32: CHUYÊN ĐỀ ĐÀO TẠO THAI KỲ | D32: NỀN TẢNG | E32: DIỄN GIẢ / PIC | F32: ĐƠN VỊ CÔNG TÁC | G32: MẸ ĐĂNG KÝ | H32: MẸ THAM DỰ THỰC TẾ | I32: TÌNH TRẠNG BUỔI HỌC | J32: LINK RECORD / PHÒNG | K32: GHI CHÚ / ĐÁNH GIÁ CHẤT LƯỢNG & THEO DÕI SAU LỚP HỌC
A33: 1 | B33: 46290 | C33: Sữa Mẹ o Không Áp Lực | D33: Zoom Cloud Meetings | E33: BS Thu
A34: 2
A35: 3
A36: 4
A37: 5
A38: 6
A39: 7
A40: 8
A41: TỔNG SỐ LƯỢNG MẸ THAM GIA LỚP ONLINE TRONG TUẦN: | G41: =SUM(G33:G40) -> 0 | H41: =SUM(H33:H40) -> 0 | I41: Lượt mẹ tham gia thực tế trên hệ thống
A43: 📝 PHẦN 3: NHẬT KÝ VẬN HÀNH & HÀNH ĐỘNG CẦN DANONE / ZMOMS PHỐI HỢP XỬ LÝ
A44: STT | B44: NỘI DUNG VƯỚNG MẮC / ĐỀ XUẤT | D44: ĐƠN VỊ | E44: PIC | F44: HẠN CHÓT | G44: TRẠNG THÁI | H44: KẾT QUẢ / GHI CHÚ TIẾN ĐỘ & HÀNH ĐỘNG TIẾP THEO
A45: 1
A46: 2
A47: 3
A48: 4

Sheet W03 (29-05.10)
A1: BÁO CÁO CHI TIẾT VẬN HÀNH – TUẦN 03 (29/09 - 05/10) | P1: ⬅ VỀ DASHBOARD TỔNG QUAN
A2: Dự án Hợp tác Danone x Zmoms • Phân bổ chỉ tiêu tuần: 626 Data xác thực | 157 New Users (NU Combo)
B4: 🎯 CHỈ TIÊU & TIẾN ĐỘ LEAD CO-DATA TUẦN | F4: 🛒 CHỈ TIÊU & CHUYỂN ĐỔI NU COMBO TUẦN | J4: ⚡ TỶ LỆ CHUYỂN ĐỔI (CR) | M4: 💰 DOANH SỐ COMBO TẠM TÍNH | P4: 📊 ĐÁNH GIÁ VẬN HÀNH TUẦN
B5: Target: | C5: 626 | D5: 135 | E5: =IF(C5>0, D5/C5, 0) -> 0.21565495 | F5: 272 | G5: 27 | H5: Tỷ lệ đạt: | I5: =IF(F5>0, G5/F5, 0) -> 0.099264706 | J5: =IF(D5>0, G5/D5, 0) -> 0.2 | M5: =G5*1300000 -> 35100000 | P5: =IF(D5>=C5, "🟢 Hoàn thành kế hoạch", IF(D5>0, "🟡 Đang bám sát tiến độ", "⚪ Đang cập nhật dữ liệu")) -> 🟡 Đang bám sát tiến độ
A9: 🏥 PHẦN 1: QUẢN LÝ LỊCH HẸN, TIẾN ĐỘ ĐỐI TÁC BỆNH VIỆN & CHUYỂN ĐỔI CO-DATA / NU TRONG TUẦN
A10: STT | B10: TÊN BỆNH VIỆN / CƠ SỞ Y TẾ | C10: TỈNH / TP | D10: NGƯỜI LIÊN HỆ BV | E10: PIC PHỤ TRÁCH | F10: NGÀY GIỜ HẸN LÀM VIỆC | G10: TÌNH TRẠNG CUỘC HẸN | H10: CHẤP THUẬN TỔ CHỨC SK | I10: NGÀY SỰ KIỆN | J10: QUY MÔ TIẾP CẬN | K10: TARGET CO-DATA | L10: ACTUAL CO-DATA | M10: % ĐẠT CO-DATA | N10: TARGET NU (COMBO) | O10: ACTUAL NU (COMBO) | P10: % ĐẠT NU | Q10: TỶ LỆ CR (% NU/LEAD) | R10: GHI CHÚ / HÀNH ĐỘNG TIẾP THEO
A11: 1 | B11: Bệnh viện Hạnh Phúc | C11: HCMC | I11: 46298 | M11: =IF(K11="","",IF(K11>0,L11/K11,0)) | P11: =IF(N11="","",IF(N11>0,O11/N11,0)) | Q11: =IF(L11="","",IF(L11>0,O11/L11,0))
A12: 2 | M12: =IF(K12="","",IF(K12>0,L12/K12,0)) | P12: =IF(N12="","",IF(N12>0,O12/N12,0)) | Q12: =IF(L12="","",IF(L12>0,O12/L12,0))
A13: 3 | M13: =IF(K13="","",IF(K13>0,L13/K13,0)) | P13: =IF(N13="","",IF(N13>0,O13/N13,0)) | Q13: =IF(L13="","",IF(L13>0,O13/L13,0))
A14: 4 | M14: =IF(K14="","",IF(K14>0,L14/K14,0)) | P14: =IF(N14="","",IF(N14>0,O14/N14,0)) | Q14: =IF(L14="","",IF(L14>0,O14/L14,0))
A15: 5 | M15: =IF(K15="","",IF(K15>0,L15/K15,0)) | P15: =IF(N15="","",IF(N15>0,O15/N15,0)) | Q15: =IF(L15="","",IF(L15>0,O15/L15,0))
A16: 6 | M16: =IF(K16="","",IF(K16>0,L16/K16,0)) | P16: =IF(N16="","",IF(N16>0,O16/N16,0)) | Q16: =IF(L16="","",IF(L16>0,O16/L16,0))
A17: 7 | M17: =IF(K17="","",IF(K17>0,L17/K17,0)) | P17: =IF(N17="","",IF(N17>0,O17/N17,0)) | Q17: =IF(L17="","",IF(L17>0,O17/L17,0))
A18: 8 | M18: =IF(K18="","",IF(K18>0,L18/K18,0)) | P18: =IF(N18="","",IF(N18>0,O18/N18,0)) | Q18: =IF(L18="","",IF(L18>0,O18/L18,0))
A19: 9 | M19: =IF(K19="","",IF(K19>0,L19/K19,0)) | P19: =IF(N19="","",IF(N19>0,O19/N19,0)) | Q19: =IF(L19="","",IF(L19>0,O19/L19,0))
A20: 10 | M20: =IF(K20="","",IF(K20>0,L20/K20,0)) | P20: =IF(N20="","",IF(N20>0,O20/N20,0)) | Q20: =IF(L20="","",IF(L20>0,O20/L20,0))
A21: 11 | M21: =IF(K21="","",IF(K21>0,L21/K21,0)) | P21: =IF(N21="","",IF(N21>0,O21/N21,0)) | Q21: =IF(L21="","",IF(L21>0,O21/L21,0))
A22: 12 | M22: =IF(K22="","",IF(K22>0,L22/K22,0)) | P22: =IF(N22="","",IF(N22>0,O22/N22,0)) | Q22: =IF(L22="","",IF(L22>0,O22/L22,0))
A23: 13 | M23: =IF(K23="","",IF(K23>0,L23/K23,0)) | P23: =IF(N23="","",IF(N23>0,O23/N23,0)) | Q23: =IF(L23="","",IF(L23>0,O23/L23,0))
... A25: 15 | M25: =IF(K25="","",IF(K25>0,L25/K25,0)) | P25: =IF(N25="","",IF(N25>0,O25/N25,0)) | Q25: =IF(L25="","",IF(L25>0,O25/L25,0))
M26: =IF(K26="","",IF(K26>0,L26/K26,0)) | P26: =IF(N26="","",IF(N26>0,O26/N26,0)) | Q26: =IF(L26="","",IF(L26>0,O26/L26,0))
A27: TỔNG CỘNG SỰ KIỆN BV / ĐỐI TÁC W03: | J27: =SUM(J11:J26) -> 0 | K27: =SUM(K11:K26) -> 0 | L27: =SUM(L11:L26) -> 0 | M27: =IF(K27>0, L27/K27, 0) -> 0 | N27: =SUM(N11:N26) -> 0 | O27: =SUM(O11:O26) -> 0 | P27: =IF(N27>0, O27/N27, 0) -> 0 | Q27: =IF(L27>0, O27/L27, 0) -> 0 | R27: Tự động đồng bộ sang Dashboard
A29: 💻 PHẦN 2: LỊCH TRÌNH LỚP HỌC ONLINE / WEBINAR THAI KỲ TRONG TUẦN
A30: STT | B30: NGÀY & KHUNG GIỜ | C30: CHUYÊN ĐỀ ĐÀO TẠO THAI KỲ | D30: NỀN TẢNG | E30: DIỄN GIẢ / PIC | F30: ĐƠN VỊ CÔNG TÁC | G30: MẸ ĐĂNG KÝ | H30: MẸ THAM DỰ THỰC TẾ | I30: TÌNH TRẠNG BUỔI HỌC | J30: LINK RECORD / PHÒNG | K30: GHI CHÚ / ĐÁNH GIÁ CHẤT LƯỢNG & THEO DÕI SAU LỚP HỌC
A31: 1 | B31: 30/09 & 11.00-12.00 | C31: Sinh Lý Cơ thể - Cơ chế sữa mẹ | D31: Zoom Cloud Meetings | E31: Bs Thai | F31: Bệnh viện / Bác sĩ mời
A32: 2 | B32: 02/10 & 20.00-21.00 | C32: Kỹ Thuật cho con bú & | D32: Zoom Cloud Meetings | E32: Bs Thu | F32: Bệnh viện / Bác sĩ mời
A33: 3
A34: 4
A35: 5
A36: 6
A37: 7
A38: 8
A39: TỔNG SỐ LƯỢNG MẸ THAM GIA LỚP ONLINE TRONG TUẦN: | G39: =SUM(G31:G38) -> 0 | H39: =SUM(H31:H38) -> 0 | I39: Lượt mẹ tham gia thực tế trên hệ thống
A41: 📝 PHẦN 3: NHẬT KÝ VẬN HÀNH & HÀNH ĐỘNG CẦN DANONE / ZMOMS PHỐI HỢP XỬ LÝ
A42: STT | B42: NỘI DUNG VƯỚNG MẮC / ĐỀ XUẤT | D42: ĐƠN VỊ | E42: PIC | F42: HẠN CHÓT | G42: TRẠNG THÁI | H42: KẾT QUẢ / GHI CHÚ TIẾN ĐỘ & HÀNH ĐỘNG TIẾP THEO
A43: 1
A44: 2
A45: 3
A46: 4

Sheet W04 (06-12.10)
A1: BÁO CÁO CHI TIẾT VẬN HÀNH – TUẦN 04 (06/10 - 12/10) | P1: ⬅ VỀ DASHBOARD TỔNG QUAN
A2: Dự án Hợp tác Danone x Zmoms • Phân bổ chỉ tiêu tuần: 626 Data xác thực | 157 New Users (NU Combo)
B4: 🎯 CHỈ TIÊU & TIẾN ĐỘ LEAD CO-DATA TUẦN | F4: 🛒 CHỈ TIÊU & CHUYỂN ĐỔI NU COMBO TUẦN | J4: ⚡ TỶ LỆ CHUYỂN ĐỔI (CR) | M4: 💰 DOANH SỐ COMBO TẠM TÍNH | P4: 📊 ĐÁNH GIÁ VẬN HÀNH TUẦN
B5: Target: | C5: 626 | D5: =IF(L27>0, L27, "") | E5: =IF(C5>0, D5/C5, 0) -> 0 | F5: 272 | G5: =IF(O27>0, O27, "") | H5: Tỷ lệ đạt: | I5: =IF(F5>0, G5/F5, 0) -> 0 | J5: =IF(D5>0, G5/D5, 0) -> #DIV/0! | M5: =G5*1300000 -> 0 | P5: =IF(D5>=C5, "🟢 Hoàn thành kế hoạch", IF(D5>0, "🟡 Đang bám sát tiến độ", "⚪ Đang cập nhật dữ liệu")) -> 🟢 Hoàn thành kế hoạch
A9: 🏥 PHẦN 1: QUẢN LÝ LỊCH HẸN, TIẾN ĐỘ ĐỐI TÁC BỆNH VIỆN & CHUYỂN ĐỔI CO-DATA / NU TRONG TUẦN
A10: STT | B10: TÊN BỆNH VIỆN / CƠ SỞ Y TẾ | C10: TỈNH / TP | D10: NGƯỜI LIÊN HỆ BV | E10: PIC PHỤ TRÁCH | F10: NGÀY GIỜ HẸN LÀM VIỆC | G10: TÌNH TRẠNG CUỘC HẸN | H10: CHẤP THUẬN TỔ CHỨC SK | I10: NGÀY SỰ KIỆN | J10: QUY MÔ TIẾP CẬN | K10: TARGET CO-DATA | L10: ACTUAL CO-DATA | M10: % ĐẠT CO-DATA | N10: TARGET NU (COMBO) | O10: ACTUAL NU (COMBO) | P10: % ĐẠT NU | Q10: TỶ LỆ CR (% NU/LEAD) | R10: GHI CHÚ / HÀNH ĐỘNG TIẾP THEO
A11: 1 | B11: Bệnh viện Hoàn Mỹ | C11: HCMC | I11: 46305 | M11: =IF(K11="","",IF(K11>0,L11/K11,0)) | P11: =IF(N11="","",IF(N11>0,O11/N11,0)) | Q11: =IF(L11="","",IF(L11>0,O11/L11,0))
A12: 2 | B12: Bệnh VIện Hoàn Mỹ Bình Dương | C12: HCMC | I12: 46307 | M12: =IF(K12="","",IF(K12>0,L12/K12,0)) | P12: =IF(N12="","",IF(N12>0,O12/N12,0)) | Q12: =IF(L12="","",IF(L12>0,O12/L12,0))
A13: 3 | M13: =IF(K13="","",IF(K13>0,L13/K13,0)) | P13: =IF(N13="","",IF(N13>0,O13/N13,0)) | Q13: =IF(L13="","",IF(L13>0,O13/L13,0))
A14: 4 | M14: =IF(K14="","",IF(K14>0,L14/K14,0)) | P14: =IF(N14="","",IF(N14>0,O14/N14,0)) | Q14: =IF(L14="","",IF(L14>0,O14/L14,0))
A15: 5 | M15: =IF(K15="","",IF(K15>0,L15/K15,0)) | P15: =IF(N15="","",IF(N15>0,O15/N15,0)) | Q15: =IF(L15="","",IF(L15>0,O15/L15,0))
A16: 6 | M16: =IF(K16="","",IF(K16>0,L16/K16,0)) | P16: =IF(N16="","",IF(N16>0,O16/N16,0)) | Q16: =IF(L16="","",IF(L16>0,O16/L16,0))
A17: 7 | M17: =IF(K17="","",IF(K17>0,L17/K17,0)) | P17: =IF(N17="","",IF(N17>0,O17/N17,0)) | Q17: =IF(L17="","",IF(L17>0,O17/L17,0))
A18: 8 | M18: =IF(K18="","",IF(K18>0,L18/K18,0)) | P18: =IF(N18="","",IF(N18>0,O18/N18,0)) | Q18: =IF(L18="","",IF(L18>0,O18/L18,0))
A19: 9 | M19: =IF(K19="","",IF(K19>0,L19/K19,0)) | P19: =IF(N19="","",IF(N19>0,O19/N19,0)) | Q19: =IF(L19="","",IF(L19>0,O19/L19,0))
A20: 10 | M20: =IF(K20="","",IF(K20>0,L20/K20,0)) | P20: =IF(N20="","",IF(N20>0,O20/N20,0)) | Q20: =IF(L20="","",IF(L20>0,O20/L20,0))
A21: 11 | M21: =IF(K21="","",IF(K21>0,L21/K21,0)) | P21: =IF(N21="","",IF(N21>0,O21/N21,0)) | Q21: =IF(L21="","",IF(L21>0,O21/L21,0))
A22: 12 | M22: =IF(K22="","",IF(K22>0,L22/K22,0)) | P22: =IF(N22="","",IF(N22>0,O22/N22,0)) | Q22: =IF(L22="","",IF(L22>0,O22/L22,0))
A23: 13 | M23: =IF(K23="","",IF(K23>0,L23/K23,0)) | P23: =IF(N23="","",IF(N23>0,O23/N23,0)) | Q23: =IF(L23="","",IF(L23>0,O23/L23,0))
A24: 14 | M24: =IF(K24="","",IF(K24>0,L24/K24,0)) | P24: =IF(N24="","",IF(N24>0,O24/N24,0)) | Q24: =IF(L24="","",IF(L24>0,O24/L24,0))
A25: 15 | M25: =IF(K25="","",IF(K25>0,L25/K25,0)) | P25: =IF(N25="","",IF(N25>0,O25/N25,0)) | Q25: =IF(L25="","",IF(L25>0,O25/L25,0))
M26: =IF(K26="","",IF(K26>0,L26/K26,0)) | P26: =IF(N26="","",IF(N26>0,O26/N26,0)) | Q26: =IF(L26="","",IF(L26>0,O26/L26,0))
A27: TỔNG CỘNG SỰ KIỆN BV / ĐỐI TÁC W04: | J27: =SUM(J11:J26) -> 0 | K27: =SUM(K11:K26) -> 0 | L27: =SUM(L11:L26) -> 0 | M27: =IF(K27>0, L27/K27, 0) -> 0 | N27: =SUM(N11:N26) -> 0 | O27: =SUM(O11:O26) -> 0 | P27: =IF(N27>0, O27/N27, 0) -> 0 | Q27: =IF(L27>0, O27/L27, 0) -> 0 | R27: Tự động đồng bộ sang Dashboard
A29: 💻 PHẦN 2: LỊCH TRÌNH LỚP HỌC ONLINE / WEBINAR THAI KỲ TRONG TUẦN
A30: STT | B30: NGÀY & KHUNG GIỜ | C30: CHUYÊN ĐỀ ĐÀO TẠO THAI KỲ | D30: NỀN TẢNG | E30: DIỄN GIẢ / PIC | F30: ĐƠN VỊ CÔNG TÁC | G30: MẸ ĐĂNG KÝ | H30: MẸ THAM DỰ THỰC TẾ | I30: TÌNH TRẠNG BUỔI HỌC | J30: LINK RECORD / PHÒNG | K30: GHI CHÚ / ĐÁNH GIÁ CHẤT LƯỢNG & THEO DÕI SAU LỚP HỌC
A31: 1 | B31: 07/10 & 11.00-12.00 | C31: Sự Cố tuyến Vú & Xử lý y khoa tại nhà | D31: Zoom Cloud Meetings | E31: Bs Thai | F31: Bệnh viện / Bác sĩ mời
A32: 2
A33: 3
A34: 4
A35: 5
A36: 6
A37: 7
A38: 8
A39: TỔNG SỐ LƯỢNG MẸ THAM GIA LỚP ONLINE TRONG TUẦN: | G39: =SUM(G31:G38) -> 0 | H39: =SUM(H31:H38) -> 0 | I39: Lượt mẹ tham gia thực tế trên hệ thống
A41: 📝 PHẦN 3: NHẬT KÝ VẬN HÀNH & HÀNH ĐỘNG CẦN DANONE / ZMOMS PHỐI HỢP XỬ LÝ
A42: STT | B42: NỘI DUNG VƯỚNG MẮC / ĐỀ XUẤT | D42: ĐƠN VỊ | E42: PIC | F42: HẠN CHÓT | G42: TRẠNG THÁI | H42: KẾT QUẢ / GHI CHÚ TIẾN ĐỘ & HÀNH ĐỘNG TIẾP THEO
A43: 1
A44: 2
A45: 3
A46: 4

Sheet W05 (13-19.10)
A1: BÁO CÁO CHI TIẾT VẬN HÀNH – TUẦN 05 (13/10 - 19/10) | P1: ⬅ VỀ DASHBOARD TỔNG QUAN
A2: Dự án Hợp tác Danone x Zmoms • Phân bổ chỉ tiêu tuần: 626 Data xác thực | 157 New Users (NU Combo)
B4: 🎯 CHỈ TIÊU & TIẾN ĐỘ LEAD CO-DATA TUẦN | F4: 🛒 CHỈ TIÊU & CHUYỂN ĐỔI NU COMBO TUẦN | J4: ⚡ TỶ LỆ CHUYỂN ĐỔI (CR) | M4: 💰 DOANH SỐ COMBO TẠM TÍNH | P4: 📊 ĐÁNH GIÁ VẬN HÀNH TUẦN
B5: Target: | C5: 626 | D5: =IF(L27>0, L27, "") | E5: =IF(C5>0, D5/C5, 0) -> 0 | F5: 272 | G5: =IF(O27>0, O27, "") | H5: Tỷ lệ đạt: | I5: =IF(F5>0, G5/F5, 0) -> 0 | J5: =IF(D5>0, G5/D5, 0) -> #DIV/0! | M5: =G5*1300000 -> 0 | P5: =IF(D5>=C5, "🟢 Hoàn thành kế hoạch", IF(D5>0, "🟡 Đang bám sát tiến độ", "⚪ Đang cập nhật dữ liệu")) -> 🟢 Hoàn thành kế hoạch
A9: 🏥 PHẦN 1: QUẢN LÝ LỊCH HẸN, TIẾN ĐỘ ĐỐI TÁC BỆNH VIỆN & CHUYỂN ĐỔI CO-DATA / NU TRONG TUẦN
A10: STT | B10: TÊN BỆNH VIỆN / CƠ SỞ Y TẾ | C10: TỈNH / TP | D10: NGƯỜI LIÊN HỆ BV | E10: PIC PHỤ TRÁCH | F10: NGÀY GIỜ HẸN LÀM VIỆC | G10: TÌNH TRẠNG CUỘC HẸN | H10: CHẤP THUẬN TỔ CHỨC SK | I10: NGÀY SỰ KIỆN | J10: QUY MÔ TIẾP CẬN | K10: TARGET CO-DATA | L10: ACTUAL CO-DATA | M10: % ĐẠT CO-DATA | N10: TARGET NU (COMBO) | O10: ACTUAL NU (COMBO) | P10: % ĐẠT NU | Q10: TỶ LỆ CR (% NU/LEAD) | R10: GHI CHÚ / HÀNH ĐỘNG TIẾP THEO
A11: 1 | B11: Phòng khám 315 | C11: HCMC | I11: 16/10 | M11: =IF(K11="","",IF(K11>0,L11/K11,0)) | P11: =IF(N11="","",IF(N11>0,O11/N11,0)) | Q11: =IF(L11="","",IF(L11>0,O11/L11,0))
A12: 2 | B12: Bệnh viện Xuyên Á | C12: HCMC | I12: 17/10 | M12: =IF(K12="","",IF(K12>0,L12/K12,0)) | P12: =IF(N12="","",IF(N12>0,O12/N12,0)) | Q12: =IF(L12="","",IF(L12>0,O12/L12,0))
A13: 3 | B13: Phòng khám 315 | C13: HCMC | I13: 18/10 | M13: =IF(K13="","",IF(K13>0,L13/K13,0)) | P13: =IF(N13="","",IF(N13>0,O13/N13,0)) | Q13: =IF(L13="","",IF(L13>0,O13/L13,0))
A14: 4 | M14: =IF(K14="","",IF(K14>0,L14/K14,0)) | P14: =IF(N14="","",IF(N14>0,O14/N14,0)) | Q14: =IF(L14="","",IF(L14>0,O14/L14,0))
A15: 5 | M15: =IF(K15="","",IF(K15>0,L15/K15,0)) | P15: =IF(N15="","",IF(N15>0,O15/N15,0)) | Q15: =IF(L15="","",IF(L15>0,O15/L15,0))
A16: 6 | M16: =IF(K16="","",IF(K16>0,L16/K16,0)) | P16: =IF(N16="","",IF(N16>0,O16/N16,0)) | Q16: =IF(L16="","",IF(L16>0,O16/L16,0))
A17: 7 | M17: =IF(K17="","",IF(K17>0,L17/K17,0)) | P17: =IF(N17="","",IF(N17>0,O17/N17,0)) | Q17: =IF(L17="","",IF(L17>0,O17/L17,0))
A18: 8 | M18: =IF(K18="","",IF(K18>0,L18/K18,0)) | P18: =IF(N18="","",IF(N18>0,O18/N18,0)) | Q18: =IF(L18="","",IF(L18>0,O18/L18,0))
A19: 9 | M19: =IF(K19="","",IF(K19>0,L19/K19,0)) | P19: =IF(N19="","",IF(N19>0,O19/N19,0)) | Q19: =IF(L19="","",IF(L19>0,O19/L19,0))
A20: 10 | M20: =IF(K20="","",IF(K20>0,L20/K20,0)) | P20: =IF(N20="","",IF(N20>0,O20/N20,0)) | Q20: =IF(L20="","",IF(L20>0,O20/L20,0))
A21: 11 | M21: =IF(K21="","",IF(K21>0,L21/K21,0)) | P21: =IF(N21="","",IF(N21>0,O21/N21,0)) | Q21: =IF(L21="","",IF(L21>0,O21/L21,0))
A22: 12 | M22: =IF(K22="","",IF(K22>0,L22/K22,0)) | P22: =IF(N22="","",IF(N22>0,O22/N22,0)) | Q22: =IF(L22="","",IF(L22>0,O22/L22,0))
A23: 13 | M23: =IF(K23="","",IF(K23>0,L23/K23,0)) | P23: =IF(N23="","",IF(N23>0,O23/N23,0)) | Q23: =IF(L23="","",IF(L23>0,O23/L23,0))
A24: 14 | M24: =IF(K24="","",IF(K24>0,L24/K24,0)) | P24: =IF(N24="","",IF(N24>0,O24/N24,0)) | Q24: =IF(L24="","",IF(L24>0,O24/L24,0))
A25: 15 | M25: =IF(K25="","",IF(K25>0,L25/K25,0)) | P25: =IF(N25="","",IF(N25>0,O25/N25,0)) | Q25: =IF(L25="","",IF(L25>0,O25/L25,0))
M26: =IF(K26="","",IF(K26>0,L26/K26,0)) | P26: =IF(N26="","",IF(N26>0,O26/N26,0)) | Q26: =IF(L26="","",IF(L26>0,O26/L26,0))
A27: TỔNG CỘNG SỰ KIỆN BV / ĐỐI TÁC W05: | J27: =SUM(J11:J26) -> 0 | K27: =SUM(K11:K26) -> 0 | L27: =SUM(L11:L26) -> 0 | M27: =IF(K27>0, L27/K27, 0) -> 0 | N27: =SUM(N11:N26) -> 0 | O27: =SUM(O11:O26) -> 0 | P27: =IF(N27>0, O27/N27, 0) -> 0 | Q27: =IF(L27>0, O27/L27, 0) -> 0 | R27: Tự động đồng bộ sang Dashboard
A29: 💻 PHẦN 2: LỊCH TRÌNH LỚP HỌC ONLINE / WEBINAR THAI KỲ TRONG TUẦN
A30: STT | B30: NGÀY & KHUNG GIỜ | C30: CHUYÊN ĐỀ ĐÀO TẠO THAI KỲ | D30: NỀN TẢNG | E30: DIỄN GIẢ / PIC | F30: ĐƠN VỊ CÔNG TÁC | G30: MẸ ĐĂNG KÝ | H30: MẸ THAM DỰ THỰC TẾ | I30: TÌNH TRẠNG BUỔI HỌC | J30: LINK RECORD / PHÒNG | K30: GHI CHÚ / ĐÁNH GIÁ CHẤT LƯỢNG & THEO DÕI SAU LỚP HỌC
A31: 1 | B31: 16/10 & 20.00-21.00 | C31: Tâm lý học sữa mẹ - Hội chứng áp lực tinh thần | D31: Zoom Cloud Meetings | E31: Bs Thu | F31: Bệnh viện / Bác sĩ mời
A32: 2
A33: 3
A34: 4
A35: 5
A36: 6
A37: 7
A38: 8
A39: TỔNG SỐ LƯỢNG MẸ THAM GIA LỚP ONLINE TRONG TUẦN: | G39: =SUM(G31:G38) -> 0 | H39: =SUM(H31:H38) -> 0 | I39: Lượt mẹ tham gia thực tế trên hệ thống
A41: 📝 PHẦN 3: NHẬT KÝ VẬN HÀNH & HÀNH ĐỘNG CẦN DANONE / ZMOMS PHỐI HỢP XỬ LÝ
A42: STT | B42: NỘI DUNG VƯỚNG MẮC / ĐỀ XUẤT | D42: ĐƠN VỊ | E42: PIC | F42: HẠN CHÓT | G42: TRẠNG THÁI | H42: KẾT QUẢ / GHI CHÚ TIẾN ĐỘ & HÀNH ĐỘNG TIẾP THEO
A43: 1
A44: 2
A45: 3
A46: 4

Sheet W06 (20-26.10)
A1: BÁO CÁO CHI TIẾT VẬN HÀNH – TUẦN 06 (20/10 - 26/10) | P1: ⬅ VỀ DASHBOARD TỔNG QUAN
A2: Dự án Hợp tác Danone x Zmoms • Phân bổ chỉ tiêu tuần: 626 Data xác thực | 157 New Users (NU Combo)
B4: 🎯 CHỈ TIÊU & TIẾN ĐỘ LEAD CO-DATA TUẦN | F4: 🛒 CHỈ TIÊU & CHUYỂN ĐỔI NU COMBO TUẦN | J4: ⚡ TỶ LỆ CHUYỂN ĐỔI (CR) | M4: 💰 DOANH SỐ COMBO TẠM TÍNH | P4: 📊 ĐÁNH GIÁ VẬN HÀNH TUẦN
B5: Target: | C5: 626 | D5: =IF(L27>0, L27, "") | E5: =IF(C5>0, D5/C5, 0) -> 0 | F5: 272 | G5: =IF(O27>0, O27, "") | H5: Tỷ lệ đạt: | I5: =IF(F5>0, G5/F5, 0) -> 0 | J5: =IF(D5>0, G5/D5, 0) -> #DIV/0! | M5: =G5*1300000 -> 0 | P5: =IF(D5>=C5, "🟢 Hoàn thành kế hoạch", IF(D5>0, "🟡 Đang bám sát tiến độ", "⚪ Đang cập nhật dữ liệu")) -> 🟢 Hoàn thành kế hoạch
A9: 🏥 PHẦN 1: QUẢN LÝ LỊCH HẸN, TIẾN ĐỘ ĐỐI TÁC BỆNH VIỆN & CHUYỂN ĐỔI CO-DATA / NU TRONG TUẦN
A10: STT | B10: TÊN BỆNH VIỆN / CƠ SỞ Y TẾ | C10: TỈNH / TP | D10: NGƯỜI LIÊN HỆ BV | E10: PIC PHỤ TRÁCH | F10: NGÀY GIỜ HẸN LÀM VIỆC | G10: TÌNH TRẠNG CUỘC HẸN | H10: CHẤP THUẬN TỔ CHỨC SK | I10: NGÀY SỰ KIỆN | J10: QUY MÔ TIẾP CẬN | K10: TARGET CO-DATA | L10: ACTUAL CO-DATA | M10: % ĐẠT CO-DATA | N10: TARGET NU (COMBO) | O10: ACTUAL NU (COMBO) | P10: % ĐẠT NU | Q10: TỶ LỆ CR (% NU/LEAD) | R10: GHI CHÚ / HÀNH ĐỘNG TIẾP THEO
A11: 1 | B11: Bệnh viện Âu Cơ | C11: Đồng Nai | F11: 46275 | G11: Đã gặp | H11: Đã chấp thuận | I11: 46319 | J11: 90 | K11: Thêm lớp riêng của IPD8 | P11: =IF(N11="","",IF(N11>0,O11/N11,0)) | Q11: =IF(L11="","",IF(L11>0,O11/L11,0))
A12: 2 | B12: Bệnh viện Xuyên Á | C12: Củ Chi | F12: 46275 | G12: Đã gặp | H12: Đã chấp thuận | I12: 46319 | J12: 90 | K12: Thêm lớp riêng của IPD8 | P12: =IF(N12="","",IF(N12>0,O12/N12,0)) | Q12: =IF(L12="","",IF(L12>0,O12/L12,0))
